Workbook

Sheet 抖音大号维护标准
A1: 【MCN事业部】抖音大号维护标准
A2: 目标星图播放中位数 = 下阶段报价 ÷ 目标CPM 200 × 1000 × 1.5 维护顺序： 1、冲榜项目/发布后急需上量/抖加无法过审，优先采用千川无视版进行维护 2、除以上情况外，应当优先采用抖加维护，正常情况下仅适用抖加采买播放量，互动量通过HKJ补齐 达到目标中位数并形成至少3条满30天样本后，下月执行涨价；平台预期CPM暂时没变化也不立即降价。
A3: 账号 | B3: 8月植入报价 | C3: 8月定制报价 | D3: 预期播放量 | E3: 预期CPM | F3: 星图中位数 （30天） | G3: 9月植入报价 （定制价格*70%） | H3: 9月定制报价 | I3: 涨价比例 | J3: 目标 柱状图播放量 （定制CPM30） | K3: 目标 星图中位数 （30天） | L3: 抖加费用 （CPM17） | M3: 抖加费用 （CPM20） | N3: 柱状图播放量缺口 | O3: 千川费用 （CPM5.5） | P3: HKJ互动 | Q3: 总维护成本 | R3: 7折+数据维护后 集团毛利 | S3: 集团毛利率 | T3: 部门毛利 | U3: 部门毛利率
A4: 花无缺 | B4: 14800 | C4: 16600 | D4: 57000 | E4: =B4/D4*1000 -> 259.64912 | F4: 69000 | G4: 14800 | H4: 16600 | I4: =(H4-C4)/C4 -> 0 | J4: =(H4*80%)*1000/30 -> 442666.67 | K4: =H4/200*1000*1.5 -> 124500 | L4: =K4*17/1000 -> 2116.5 | M4: =K4*20/1000 -> 2490 | N4: =J4-K4 -> 318166.67 | O4: =(N4/1000)*5.5 -> 1749.9167 | P4: =30*18+200*0.8+300*0.2+200*0.1 -> 780 | Q4: =M4+O4+P4 -> 5019.9167 | R4: =(H4*70%)-Q4 -> 6600.0833 | S4: =R4/H4 -> 0.39759538 | T4: =R4*0.65 -> 4290.0542 | U4: =T4/H4 -> 0.258437
A5: 最游话说 | B5: 11900 | C5: 14300 | D5: 32000 | E5: =B5/D5*1000 -> 371.875 | F5: 54000 | G5: =H5*0.7 -> 12600 | H5: 18000 | I5: =(H5-C5)/C5 -> 0.25874126 | J5: =(H5*80%)*1000/30 -> 480000 | K5: =H5/200*1000*1.5 -> 135000 | L5: =K5*17/1000 -> 2295 | M5: =K5*20/1000 -> 2700 | N5: =J5-K5 -> 345000 | O5: =(N5/1000)*5.5 -> 1897.5 | P5: =20*18+200*0.8+300*0.2+200*0.1 -> 600 | Q5: =M5+O5+P5 -> 5197.5 | R5: =(H5*70%)-Q5 -> 7402.5 | S5: =R5/H5 -> 0.41125 | T5: =R5*0.65 -> 4811.625 | U5: =T5/H5 -> 0.2673125
A6: 报告砖家 | B6: 14250 | C6: 17100 | D6: 261000 | E6: =B6/D6*1000 -> 54.597701 | F6: 189000 | G6: =H6*0.7 -> 14000 | H6: 20000 | I6: =(H6-C6)/C6 -> 0.16959064 | J6: =(H6*80%)*1000/30 -> 533333.33 | K6: =H6/200*1000*1.5 -> 150000 | L6: =K6*17/1000 -> 2550 | M6: =K6*20/1000 -> 3000 | N6: =J6-K6 -> 383333.33 | O6: =(N6/1000)*5.5 -> 2108.3333 | P6: =30*18+200*0.8+300*0.2+200*0.1 -> 780 | Q6: =M6+O6+P6 -> 5888.3333 | R6: =(H6*70%)-Q6 -> 8111.6667 | S6: =R6/H6 -> 0.40558333 | T6: =R6*0.65 -> 5272.5833 | U6: =T6/H6 -> 0.26362917
A7: 策划克星阿强 | B7: 8000 | C7: 10000 | D7: 35000 | E7: =B7/D7*1000 -> 228.57143 | F7: 84000 | G7: =H7*0.7 -> 8400 | H7: 12000 | I7: =(H7-C7)/C7 -> 0.2 | J7: =(H7*80%)*1000/30 -> 320000 | K7: =H7/200*1000*1.5 -> 90000 | L7: =K7*17/1000 -> 1530 | M7: =K7*20/1000 -> 1800 | N7: =J7-K7 -> 230000 | O7: =(N7/1000)*5.5 -> 1265 | P7: =15*18+200*0.8+300*0.2+200*0.1 -> 510 | Q7: =M7+O7+P7 -> 3575 | R7: =(H7*70%)-Q7 -> 4825 | S7: =R7/H7 -> 0.40208333 | T7: =R7*0.65 -> 3136.25 | U7: =T7/H7 -> 0.26135417
A8: 天机妹 | B8: 15000 | C8: 18000 | D8: 13000 | E8: =B8/D8*1000 -> 1153.8462 | F8: 84000 | G8: =H8*0.7 -> 14000 | H8: 20000 | I8: =(H8-C8)/C8 -> 0.11111111 | J8: =(H8*80%)*1000/30 -> 533333.33 | K8: =H8/200*1000*1.5 -> 150000 | L8: =K8*17/1000 -> 2550 | M8: =K8*20/1000 -> 3000 | N8: =J8-K8 -> 383333.33 | O8: =(N8/1000)*5.5 -> 2108.3333 | P8: =30*18+200*0.8+300*0.2+200*0.1 -> 780 | Q8: =M8+O8+P8 -> 5888.3333 | R8: =(H8*70%)-Q8 -> 8111.6667 | S8: =R8/H8 -> 0.40558333 | T8: =R8*0.65 -> 5272.5833 | U8: =T8/H8 -> 0.26362917
A9: 木游话说 | B9: 10000 | C9: 12000 | D9: 26000 | E9: =B9/D9*1000 -> 384.61538 | F9: 70000 | G9: =H9*0.7 -> 10500 | H9: 15000 | I9: =(H9-C9)/C9 -> 0.25 | J9: =(H9*80%)*1000/30 -> 400000 | K9: =H9/200*1000*1.5 -> 112500 | L9: =K9*17/1000 -> 1912.5 | M9: =K9*20/1000 -> 2250 | N9: =J9-K9 -> 287500 | O9: =(N9/1000)*5.5 -> 1581.25 | P9: =20*18+200*0.8+300*0.2+200*0.1 -> 600 | Q9: =M9+O9+P9 -> 4431.25 | R9: =(H9*70%)-Q9 -> 6068.75 | S9: =R9/H9 -> 0.40458333 | T9: =R9*0.65 -> 3944.6875 | U9: =T9/H9 -> 0.26297917
A10: 麦冬冬 | B10: 8000 | C10: 10000 | D10: 26000 | E10: =B10/D10*1000 -> 307.69231 | F10: 97000 | G10: 8000 | H10: 10000 | I10: =(H10-C10)/C10 -> 0 | J10: =(H10*80%)*1000/30 -> 266666.67 | K10: =H10/200*1000*1.5 -> 75000 | L10: =K10*17/1000 -> 1275 | M10: =K10*20/1000 -> 1500 | N10: =J10-K10 -> 191666.67 | O10: =(N10/1000)*5.5 -> 1054.1667 | P10: =15*18+200*0.8+300*0.2+200*0.1 -> 510 | Q10: =M10+O10+P10 -> 3064.1667 | R10: =(H10*70%)-Q10 -> 3935.8333 | S10: =R10/H10 -> 0.39358333 | T10: =R10*0.65 -> 2558.2917 | U10: =T10/H10 -> 0.25582917
A15: 【MCN事业部】抖音小号维护标准
A16: 私单按询单表私单价格，不额外折扣；平台单按各账号定制刊例报价×70% 播放目标沿用大号模板：定制基准×80%÷30×1000。按完整目标预留千川费用，不将星图中位数当成已实现播放扣减。
A17: 账号 | B17: 负责人 | C17: 定制 刊例价 | D17: 私单 报价 | E17: 涨价定制 刊例价 | F17: 涨价私单 报价 | G17: 订单 类型 | H17: 成交价 | I17: 目标播放量 （次） | J17: 千川版本 | K17: 千川 费用 | L17: 点赞 | M17: 评论 | N17: 收藏 | O17: 转发 | P17: 互动 费用 | Q17: 总维护 成本 | R17: 维护费 占成交价 | S17: 集团 毛利 | T17: 集团毛利率 （占折前报价） | U17: 部门 毛利 | V17: 部门毛利率 （占折前报价） | W17: 备注 | X17: 主页链接
A18: 薛定谔的机 | B18: 薛荐轩 | C18: 10500 | D18: =C18*0.6 -> 6300 | E18: / | F18: / | G18: 私单 | H18: =(D18)*(1) -> 6300 | I18: =ROUNDUP(C18*维护参数!$B$11/维护参数!$B$12*1000,0) -> 280000 | J18: 普通千川 | K18: =(MAX(维护参数!$B$4,ROUNDUP(I18/10000,0)))*(维护参数!$B$2) -> 588 | L18: =ROUNDUP(C18*维护参数!$B$16/维护参数!$B$15/1000,0)*1000 -> 21000 | M18: =ROUNDUP(C18*维护参数!$B$17/维护参数!$B$15/10,0)*10 -> 210 | N18: =ROUNDUP(C18*维护参数!$B$18/维护参数!$B$15/10,0)*10 -> 210 | O18: =ROUNDUP(C18*维护参数!$B$19/维护参数!$B$15/10,0)*10 -> 320 | P18: =L18/1000*维护参数!$B$6+M18*维护参数!$B$7+N18*维护参数!$B$8+O18*维护参数!$B$9 -> 1513 | Q18: =SUM(K18,P18) -> 2101 | R18: =Q18/H18 -> 0.33349206 | S18: =H18-Q18 -> 4199 | T18: =S18/(C18) -> 0.39990476 | U18: =S18*维护参数!$B$20 -> 2729.35 | V18: =U18/(C18) -> 0.2599381 | W18: 真人 | X18: https://v.douyin.com/dcP3cOC30h4/
G19: 平台单 | H19: =(C18)*(维护参数!$B$10) -> 7350 | J19: 千川无视版 | K19: =(MAX(维护参数!$B$5,ROUNDUP(I18/10000,0)))*(维护参数!$B$3) -> 1540 | Q19: =SUM(K19,P18) -> 3053 | R19: =Q19/H19 -> 0.41537415 | S19: =H19-Q19 -> 4297 | T19: =S19/(C18) -> 0.4092381 | U19: =S19*维护参数!$B$20 -> 2793.05 | V19: =U19/(C18) -> 0.26600476
A20: 花满楼 | B20: 陈健伊 | C20: 11700 | D20: =C20*0.6 -> 7020 | E20: / | F20: / | G20: 私单 | H20: =(D20)*(1) -> 7020 | I20: =ROUNDUP(C20*维护参数!$B$11/维护参数!$B$12*1000,0) -> 312000 | J20: 普通千川 | K20: =(MAX(维护参数!$B$4,ROUNDUP(I20/10000,0)))*(维护参数!$B$2) -> 672 | L20: =ROUNDUP(C20*维护参数!$B$16/维护参数!$B$15/1000,0)*1000 -> 24000 | M20: =ROUNDUP(C20*维护参数!$B$17/维护参数!$B$15/10,0)*10 -> 240 | N20: =ROUNDUP(C20*维护参数!$B$18/维护参数!$B$15/10,0)*10 -> 240 | O20: =ROUNDUP(C20*维护参数!$B$19/维护参数!$B$15/10,0)*10 -> 360 | P20: =L20/1000*维护参数!$B$6+M20*维护参数!$B$7+N20*维护参数!$B$8+O20*维护参数!$B$9 -> 1728 | Q20: =SUM(K20,P20) -> 2400 | R20: =Q20/H20 -> 0.34188034 | S20: =H20-Q20 -> 4620 | T20: =S20/(C20) -> 0.39487179 | U20: =S20*维护参数!$B$20 -> 3003 | V20: =U20/(C20) -> 0.25666667 | W20: 建议降价 | X20: https://v.douyin.com/SAEJqgoPkrY/
G21: 平台单 | H21: =(C20)*(维护参数!$B$10) -> 8190 | J21: 千川无视版 | K21: =(MAX(维护参数!$B$5,ROUNDUP(I20/10000,0)))*(维护参数!$B$3) -> 1760 | Q21: =SUM(K21,P20) -> 3488 | R21: =Q21/H21 -> 0.42588523 | S21: =H21-Q21 -> 4702 | T21: =S21/(C20) -> 0.40188034 | U21: =S21*维护参数!$B$20 -> 3056.3 | V21: =U21/(C20) -> 0.26122222
A22: 麦小雯 | B22: 陈健伊 | C22: 6000 | D22: =C22*0.6 -> 3600 | E22: 9000 | F22: =E22*0.6 -> 5400 | G22: 私单 | H22: =(D22)*(1) -> 3600 | I22: =ROUNDUP(C22*维护参数!$B$11/维护参数!$B$12*1000,0) -> 160000 | J22: 普通千川 | K22: =(MAX(维护参数!$B$4,ROUNDUP(I22/10000,0)))*(维护参数!$B$2) -> 336 | L22: =ROUNDUP(C22*维护参数!$B$16/维护参数!$B$15/1000,0)*1000 -> 12000 | M22: =ROUNDUP(C22*维护参数!$B$17/维护参数!$B$15/10,0)*10 -> 120 | N22: =ROUNDUP(C22*维护参数!$B$18/维护参数!$B$15/10,0)*10 -> 120 | O22: =ROUNDUP(C22*维护参数!$B$19/维护参数!$B$15/10,0)*10 -> 180 | P22: =L22/1000*维护参数!$B$6+M22*维护参数!$B$7+N22*维护参数!$B$8+O22*维护参数!$B$9 -> 864 | Q22: =SUM(K22,P22) -> 1200 | R22: =Q22/H22 -> 0.33333333 | S22: =H22-Q22 -> 2400 | T22: =S22/(C22) -> 0.4 | U22: =S22*维护参数!$B$20 -> 1560 | V22: =U22/(C22) -> 0.26 | X22: https://v.douyin.com/DcH2brXPgvc/
G23: 平台单 | H23: =(C22)*(维护参数!$B$10) -> 4200 | J23: 千川无视版 | K23: =(MAX(维护参数!$B$5,ROUNDUP(I22/10000,0)))*(维护参数!$B$3) -> 880 | Q23: =SUM(K23,P22) -> 1744 | R23: =Q23/H23 -> 0.4152381 | S23: =H23-Q23 -> 2456 | T23: =S23/(C22) -> 0.40933333 | U23: =S23*维护参数!$B$20 -> 1596.4 | V23: =U23/(C22) -> 0.26606667
A24: 葵仔不想肝 | B24: 刘登魁 | C24: 6250 | D24: =C24*0.6 -> 3750 | E24: 7000 | F24: =E24*0.6 -> 4200 | G24: 私单 | H24: =(D24)*(1) -> 3750 | I24: =ROUNDUP(C24*维护参数!$B$11/维护参数!$B$12*1000,0) -> 166667 | J24: 普通千川 | K24: =(MAX(维护参数!$B$4,ROUNDUP(I24/10000,0)))*(维护参数!$B$2) -> 357 | L24: =ROUNDUP(C24*维护参数!$B$16/维护参数!$B$15/1000,0)*1000 -> 13000 | M24: =ROUNDUP(C24*维护参数!$B$17/维护参数!$B$15/10,0)*10 -> 130 | N24: =ROUNDUP(C24*维护参数!$B$18/维护参数!$B$15/10,0)*10 -> 130 | O24: =ROUNDUP(C24*维护参数!$B$19/维护参数!$B$15/10,0)*10 -> 190 | P24: =L24/1000*维护参数!$B$6+M24*维护参数!$B$7+N24*维护参数!$B$8+O24*维护参数!$B$9 -> 935 | Q24: =SUM(K24,P24) -> 1292 | R24: =Q24/H24 -> 0.34453333 | S24: =H24-Q24 -> 2458 | T24: =S24/(C24) -> 0.39328 | U24: =S24*维护参数!$B$20 -> 1597.7 | V24: =U24/(C24) -> 0.255632 | X24: https://v.douyin.com/38Scd6JrG_s/
G25: 平台单 | H25: =(C24)*(维护参数!$B$10) -> 4375 | J25: 千川无视版 | K25: =(MAX(维护参数!$B$5,ROUNDUP(I24/10000,0)))*(维护参数!$B$3) -> 935 | Q25: =SUM(K25,P24) -> 1870 | R25: =Q25/H25 -> 0.42742857 | S25: =H25-Q25 -> 2505 | T25: =S25/(C24) -> 0.4008 | U25: =S25*维护参数!$B$20 -> 1628.25 | V25: =U25/(C24) -> 0.26052
A26: 游热娃子 | B26: 杨鸿霆 | C26: 8750 | D26: =C26*0.6 -> 5250 | E26: 10000 | F26: =E26*0.6 -> 6000 | G26: 私单 | H26: =(D26)*(1) -> 5250 | I26: =ROUNDUP(C26*维护参数!$B$11/维护参数!$B$12*1000,0) -> 233334 | J26: 普通千川 | K26: =(MAX(维护参数!$B$4,ROUNDUP(I26/10000,0)))*(维护参数!$B$2) -> 504 | L26: =ROUNDUP(C26*维护参数!$B$16/维护参数!$B$15/1000,0)*1000 -> 18000 | M26: =ROUNDUP(C26*维护参数!$B$17/维护参数!$B$15/10,0)*10 -> 180 | N26: =ROUNDUP(C26*维护参数!$B$18/维护参数!$B$15/10,0)*10 -> 180 | O26: =ROUNDUP(C26*维护参数!$B$19/维护参数!$B$15/10,0)*10 -> 270 | P26: =L26/1000*维护参数!$B$6+M26*维护参数!$B$7+N26*维护参数!$B$8+O26*维护参数!$B$9 -> 1296 | Q26: =SUM(K26,P26) -> 1800 | R26: =Q26/H26 -> 0.34285714 | S26: =H26-Q26 -> 3450 | T26: =S26/(C26) -> 0.39428571 | U26: =S26*维护参数!$B$20 -> 2242.5 | V26: =U26/(C26) -> 0.25628571 | W26: 数据好 | X26: https://v.douyin.com/JmcvjVd/
G27: 平台单 | H27: =(C26)*(维护参数!$B$10) -> 6125 | J27: 千川无视版 | K27: =(MAX(维护参数!$B$5,ROUNDUP(I26/10000,0)))*(维护参数!$B$3) -> 1320 | Q27: =SUM(K27,P26) -> 2616 | R27: =Q27/H27 -> 0.42710204 | S27: =H27-Q27 -> 3509 | T27: =S27/(C26) -> 0.40102857 | U27: =S27*维护参数!$B$20 -> 2280.85 | V27: =U27/(C26) -> 0.26066857
A28: 游小妹 | B28: 杨鸿霆 | C28: 6000 | D28: =C28*0.6 -> 3600 | E28: 8000 | F28: =E28*0.6 -> 4800 | G28: 私单 | H28: =(D28)*(1) -> 3600 | I28: =ROUNDUP(C28*维护参数!$B$11/维护参数!$B$12*1000,0) -> 160000 | J28: 普通千川 | K28: =(MAX(维护参数!$B$4,ROUNDUP(I28/10000,0)))*(维护参数!$B$2) -> 336 | L28: =ROUNDUP(C28*维护参数!$B$16/维护参数!$B$15/1000,0)*1000 -> 12000 | M28: =ROUNDUP(C28*维护参数!$B$17/维护参数!$B$15/10,0)*10 -> 120 | N28: =ROUNDUP(C28*维护参数!$B$18/维护参数!$B$15/10,0)*10 -> 120 | O28: =ROUNDUP(C28*维护参数!$B$19/维护参数!$B$15/10,0)*10 -> 180 | P28: =L28/1000*维护参数!$B$6+M28*维护参数!$B$7+N28*维护参数!$B$8+O28*维护参数!$B$9 -> 864 | Q28: =SUM(K28,P28) -> 1200 | R28: =Q28/H28 -> 0.33333333 | S28: =H28-Q28 -> 2400 | T28: =S28/(C28) -> 0.4 | U28: =S28*维护参数!$B$20 -> 1560 | V28: =U28/(C28) -> 0.26 | X28: https://v.douyin.com/JmcXQpY/
G29: 平台单 | H29: =(C28)*(维护参数!$B$10) -> 4200 | J29: 千川无视版 | K29: =(MAX(维护参数!$B$5,ROUNDUP(I28/10000,0)))*(维护参数!$B$3) -> 880 | Q29: =SUM(K29,P28) -> 1744 | R29: =Q29/H29 -> 0.4152381 | S29: =H29-Q29 -> 2456 | T29: =S29/(C28) -> 0.40933333 | U29: =S29*维护参数!$B$20 -> 1596.4 | V29: =U29/(C28) -> 0.26606667
A30: 灵梦小师妹 | B30: 林宇辰 | C30: 6000 | D30: =C30*0.6 -> 3600 | E30: / | F30: / | G30: 私单 | H30: =(D30)*(1) -> 3600 | I30: =ROUNDUP(C30*维护参数!$B$11/维护参数!$B$12*1000,0) -> 160000 | J30: 普通千川 | K30: =(MAX(维护参数!$B$4,ROUNDUP(I30/10000,0)))*(维护参数!$B$2) -> 336 | L30: =ROUNDUP(C30*维护参数!$B$16/维护参数!$B$15/1000,0)*1000 -> 12000 | M30: =ROUNDUP(C30*维护参数!$B$17/维护参数!$B$15/10,0)*10 -> 120 | N30: =ROUNDUP(C30*维护参数!$B$18/维护参数!$B$15/10,0)*10 -> 120 | O30: =ROUNDUP(C30*维护参数!$B$19/维护参数!$B$15/10,0)*10 -> 180 | P30: =L30/1000*维护参数!$B$6+M30*维护参数!$B$7+N30*维护参数!$B$8+O30*维护参数!$B$9 -> 864 | Q30: =SUM(K30,P30) -> 1200 | R30: =Q30/H30 -> 0.33333333 | S30: =H30-Q30 -> 2400 | T30: =S30/(C30) -> 0.4 | U30: =S30*维护参数!$B$20 -> 1560 | V30: =U30/(C30) -> 0.26 | W30: 王者 | X30: https://www.douyin.com/user/MS4wLjABAAAAJfqON1LDmWBPlUXvQ-iwZ6AZLbLuIj72uGiFUuot89k
G31: 平台单 | H31: =(C30)*(维护参数!$B$10) -> 4200 | J31: 千川无视版 | K31: =(MAX(维护参数!$B$5,ROUNDUP(I30/10000,0)))*(维护参数!$B$3) -> 880 | Q31: =SUM(K31,P30) -> 1744 | R31: =Q31/H31 -> 0.4152381 | S31: =H31-Q31 -> 2456 | T31: =S31/(C30) -> 0.40933333 | U31: =S31*维护参数!$B$20 -> 1596.4 | V31: =U31/(C30) -> 0.26606667
A32: 超玩教授 | B32: 商光涵 | C32: 6000 | D32: =C32*0.6 -> 3600 | E32: 8000 | F32: =E32*0.6 -> 4800 | G32: 私单 | H32: =(D32)*(1) -> 3600 | I32: =ROUNDUP(C32*维护参数!$B$11/维护参数!$B$12*1000,0) -> 160000 | J32: 普通千川 | K32: =(MAX(维护参数!$B$4,ROUNDUP(I32/10000,0)))*(维护参数!$B$2) -> 336 | L32: =ROUNDUP(C32*维护参数!$B$16/维护参数!$B$15/1000,0)*1000 -> 12000 | M32: =ROUNDUP(C32*维护参数!$B$17/维护参数!$B$15/10,0)*10 -> 120 | N32: =ROUNDUP(C32*维护参数!$B$18/维护参数!$B$15/10,0)*10 -> 120 | O32: =ROUNDUP(C32*维护参数!$B$19/维护参数!$B$15/10,0)*10 -> 180 | P32: =L32/1000*维护参数!$B$6+M32*维护参数!$B$7+N32*维护参数!$B$8+O32*维护参数!$B$9 -> 864 | Q32: =SUM(K32,P32) -> 1200 | R32: =Q32/H32 -> 0.33333333 | S32: =H32-Q32 -> 2400 | T32: =S32/(C32) -> 0.4 | U32: =S32*维护参数!$B$20 -> 1560 | V32: =U32/(C32) -> 0.26 | W32: 需改封面+隐藏 | X32: https://v.douyin.com/JJ3p572/
G33: 平台单 | H33: =(C32)*(维护参数!$B$10) -> 4200 | J33: 千川无视版 | K33: =(MAX(维护参数!$B$5,ROUNDUP(I32/10000,0)))*(维护参数!$B$3) -> 880 | Q33: =SUM(K33,P32) -> 1744 | R33: =Q33/H33 -> 0.4152381 | S33: =H33-Q33 -> 2456 | T33: =S33/(C32) -> 0.40933333 | U33: =S33*维护参数!$B$20 -> 1596.4 | V33: =U33/(C32) -> 0.26606667
A34: lee小强 | B34: 商光涵 | C34: 4800 | D34: =C34*0.6 -> 2880 | E34: 6000 | F34: =E34*0.6 -> 3600 | G34: 私单 | H34: =(D34)*(1) -> 2880 | I34: =ROUNDUP(C34*维护参数!$B$11/维护参数!$B$12*1000,0) -> 128000 | J34: 普通千川 | K34: =(MAX(维护参数!$B$4,ROUNDUP(I34/10000,0)))*(维护参数!$B$2) -> 273 | L34: =ROUNDUP(C34*维护参数!$B$16/维护参数!$B$15/1000,0)*1000 -> 10000 | M34: =ROUNDUP(C34*维护参数!$B$17/维护参数!$B$15/10,0)*10 -> 100 | N34: =ROUNDUP(C34*维护参数!$B$18/维护参数!$B$15/10,0)*10 -> 100 | O34: =ROUNDUP(C34*维护参数!$B$19/维护参数!$B$15/10,0)*10 -> 150 | P34: =L34/1000*维护参数!$B$6+M34*维护参数!$B$7+N34*维护参数!$B$8+O34*维护参数!$B$9 -> 720 | Q34: =SUM(K34,P34) -> 993 | R34: =Q34/H34 -> 0.34479167 | S34: =H34-Q34 -> 1887 | T34: =S34/(C34) -> 0.393125 | U34: =S34*维护参数!$B$20 -> 1226.55 | V34: =U34/(C34) -> 0.25553125 | X34: https://v.douyin.com/ihb6eF8j/
G35: 平台单 | H35: =(C34)*(维护参数!$B$10) -> 3360 | J35: 千川无视版 | K35: =(MAX(维护参数!$B$5,ROUNDUP(I34/10000,0)))*(维护参数!$B$3) -> 715 | Q35: =SUM(K35,P34) -> 1435 | R35: =Q35/H35 -> 0.42708333 | S35: =H35-Q35 -> 1925 | T35: =S35/(C34) -> 0.40104167 | U35: =S35*维护参数!$B$20 -> 1251.25 | V35: =U35/(C34) -> 0.26067708
A36: 不玩就分手 | B36: 刘登魁 | C36: 3500 | D36: =C36*0.6 -> 2100 | E36: 4500 | F36: =E36*0.6 -> 2700 | G36: 私单 | H36: =(D36)*(1) -> 2100 | I36: =ROUNDUP(C36*维护参数!$B$11/维护参数!$B$12*1000,0) -> 93334 | J36: 普通千川 | K36: =(MAX(维护参数!$B$4,ROUNDUP(I36/10000,0)))*(维护参数!$B$2) -> 210 | L36: =ROUNDUP(C36*维护参数!$B$16/维护参数!$B$15/1000,0)*1000 -> 7000 | M36: =ROUNDUP(C36*维护参数!$B$17/维护参数!$B$15/10,0)*10 -> 70 | N36: =ROUNDUP(C36*维护参数!$B$18/维护参数!$B$15/10,0)*10 -> 70 | O36: =ROUNDUP(C36*维护参数!$B$19/维护参数!$B$15/10,0)*10 -> 110 | P36: =L36/1000*维护参数!$B$6+M36*维护参数!$B$7+N36*维护参数!$B$8+O36*维护参数!$B$9 -> 505 | Q36: =SUM(K36,P36) -> 715 | R36: =Q36/H36 -> 0.34047619 | S36: =H36-Q36 -> 1385 | T36: =S36/(C36) -> 0.39571429 | U36: =S36*维护参数!$B$20 -> 900.25 | V36: =U36/(C36) -> 0.25721429 | W36: 王者 | X36: https://v.douyin.com/jTKED_9fV4A/
G37: 平台单 | H37: =(C36)*(维护参数!$B$10) -> 2450 | J37: 千川无视版 | K37: =(MAX(维护参数!$B$5,ROUNDUP(I36/10000,0)))*(维护参数!$B$3) -> 550 | Q37: =SUM(K37,P36) -> 1055 | R37: =Q37/H37 -> 0.43061224 | S37: =H37-Q37 -> 1395 | T37: =S37/(C36) -> 0.39857143 | U37: =S37*维护参数!$B$20 -> 906.75 | V37: =U37/(C36) -> 0.25907143
A38: 游梗要说 | B38: 罗晓棋 | C38: 7800 | D38: =C38*0.6 -> 4680 | E38: / | F38: / | G38: 私单 | H38: =(D38)*(1) -> 4680 | I38: =ROUNDUP(C38*维护参数!$B$11/维护参数!$B$12*1000,0) -> 208000 | J38: 普通千川 | K38: =(MAX(维护参数!$B$4,ROUNDUP(I38/10000,0)))*(维护参数!$B$2) -> 441 | L38: =ROUNDUP(C38*维护参数!$B$16/维护参数!$B$15/1000,0)*1000 -> 16000 | M38: =ROUNDUP(C38*维护参数!$B$17/维护参数!$B$15/10,0)*10 -> 160 | N38: =ROUNDUP(C38*维护参数!$B$18/维护参数!$B$15/10,0)*10 -> 160 | O38: =ROUNDUP(C38*维护参数!$B$19/维护参数!$B$15/10,0)*10 -> 240 | P38: =L38/1000*维护参数!$B$6+M38*维护参数!$B$7+N38*维护参数!$B$8+O38*维护参数!$B$9 -> 1152 | Q38: =SUM(K38,P38) -> 1593 | R38: =Q38/H38 -> 0.34038462 | S38: =H38-Q38 -> 3087 | T38: =S38/(C38) -> 0.39576923 | U38: =S38*维护参数!$B$20 -> 2006.55 | V38: =U38/(C38) -> 0.25725 | X38: https://www.douyin.com/user/MS4wLjABAAAAbRgpD5qO5M7mlI-ALMWDbsqjwiSeFC1WxNPKVgjsSCbFam1N0thGyVDw-PfRjICt
G39: 平台单 | H39: =(C38)*(维护参数!$B$10) -> 5460 | J39: 千川无视版 | K39: =(MAX(维护参数!$B$5,ROUNDUP(I38/10000,0)))*(维护参数!$B$3) -> 1155 | Q39: =SUM(K39,P38) -> 2307 | R39: =Q39/H39 -> 0.42252747 | S39: =H39-Q39 -> 3153 | T39: =S39/(C38) -> 0.40423077 | U39: =S39*维护参数!$B$20 -> 2049.45 | V39: =U39/(C38) -> 0.26275
A40: 中二探长 | B40: 陈泓睿 | C40: 3750 | D40: =C40*0.6 -> 2250 | E40: 5000 | F40: =E40*0.6 -> 3000 | G40: 私单 | H40: =(D40)*(1) -> 2250 | I40: =ROUNDUP(C40*维护参数!$B$11/维护参数!$B$12*1000,0) -> 100000 | J40: 普通千川 | K40: =(MAX(维护参数!$B$4,ROUNDUP(I40/10000,0)))*(维护参数!$B$2) -> 210 | L40: =ROUNDUP(C40*维护参数!$B$16/维护参数!$B$15/1000,0)*1000 -> 8000 | M40: =ROUNDUP(C40*维护参数!$B$17/维护参数!$B$15/10,0)*10 -> 80 | N40: =ROUNDUP(C40*维护参数!$B$18/维护参数!$B$15/10,0)*10 -> 80 | O40: =ROUNDUP(C40*维护参数!$B$19/维护参数!$B$15/10,0)*10 -> 120 | P40: =L40/1000*维护参数!$B$6+M40*维护参数!$B$7+N40*维护参数!$B$8+O40*维护参数!$B$9 -> 576 | Q40: =SUM(K40,P40) -> 786 | R40: =Q40/H40 -> 0.34933333 | S40: =H40-Q40 -> 1464 | T40: =S40/(C40) -> 0.3904 | U40: =S40*维护参数!$B$20 -> 951.6 | V40: =U40/(C40) -> 0.25376 | W40: 王者 | X40: https://v.douyin.com/mFA-j2xaAJY/
G41: 平台单 | H41: =(C40)*(维护参数!$B$10) -> 2625 | J41: 千川无视版 | K41: =(MAX(维护参数!$B$5,ROUNDUP(I40/10000,0)))*(维护参数!$B$3) -> 550 | Q41: =SUM(K41,P40) -> 1126 | R41: =Q41/H41 -> 0.42895238 | S41: =H41-Q41 -> 1499 | T41: =S41/(C40) -> 0.39973333 | U41: =S41*维护参数!$B$20 -> 974.35 | V41: =U41/(C40) -> 0.25982667
A42: 嘿小虎 | B42: 陈泓睿 | C42: 3000 | D42: =C42*0.6 -> 1800 | E42: 5000 | F42: =E42*0.6 -> 3000 | G42: 私单 | H42: =(D42)*(1) -> 1800 | I42: =ROUNDUP(C42*维护参数!$B$11/维护参数!$B$12*1000,0) -> 80000 | J42: 普通千川 | K42: =(MAX(维护参数!$B$4,ROUNDUP(I42/10000,0)))*(维护参数!$B$2) -> 210 | L42: =ROUNDUP(C42*维护参数!$B$16/维护参数!$B$15/1000,0)*1000 -> 6000 | M42: =ROUNDUP(C42*维护参数!$B$17/维护参数!$B$15/10,0)*10 -> 60 | N42: =ROUNDUP(C42*维护参数!$B$18/维护参数!$B$15/10,0)*10 -> 60 | O42: =ROUNDUP(C42*维护参数!$B$19/维护参数!$B$15/10,0)*10 -> 90 | P42: =L42/1000*维护参数!$B$6+M42*维护参数!$B$7+N42*维护参数!$B$8+O42*维护参数!$B$9 -> 432 | Q42: =SUM(K42,P42) -> 642 | R42: =Q42/H42 -> 0.35666667 | S42: =H42-Q42 -> 1158 | T42: =S42/(C42) -> 0.386 | U42: =S42*维护参数!$B$20 -> 752.7 | V42: =U42/(C42) -> 0.2509 | W42: 逆水寒-之前 需改封面+隐藏 | X42: https://v.douyin.com/lIhi6TchbPw/
G43: 平台单 | H43: =(C42)*(维护参数!$B$10) -> 2100 | J43: 千川无视版 | K43: =(MAX(维护参数!$B$5,ROUNDUP(I42/10000,0)))*(维护参数!$B$3) -> 440 | Q43: =SUM(K43,P42) -> 872 | R43: =Q43/H43 -> 0.4152381 | S43: =H43-Q43 -> 1228 | T43: =S43/(C42) -> 0.40933333 | U43: =S43*维护参数!$B$20 -> 798.2 | V43: =U43/(C42) -> 0.26606667
A44: 有事找学姐 | B44: 林宇辰 | C44: 7150 | D44: =C44*0.6 -> 4290 | E44: / | F44: / | G44: 私单 | H44: =(D44)*(1) -> 4290 | I44: =ROUNDUP(C44*维护参数!$B$11/维护参数!$B$12*1000,0) -> 190667 | J44: 普通千川 | K44: =(MAX(维护参数!$B$4,ROUNDUP(I44/10000,0)))*(维护参数!$B$2) -> 420 | L44: =ROUNDUP(C44*维护参数!$B$16/维护参数!$B$15/1000,0)*1000 -> 15000 | M44: =ROUNDUP(C44*维护参数!$B$17/维护参数!$B$15/10,0)*10 -> 150 | N44: =ROUNDUP(C44*维护参数!$B$18/维护参数!$B$15/10,0)*10 -> 150 | O44: =ROUNDUP(C44*维护参数!$B$19/维护参数!$B$15/10,0)*10 -> 220 | P44: =L44/1000*维护参数!$B$6+M44*维护参数!$B$7+N44*维护参数!$B$8+O44*维护参数!$B$9 -> 1079 | Q44: =SUM(K44,P44) -> 1499 | R44: =Q44/H44 -> 0.34941725 | S44: =H44-Q44 -> 2791 | T44: =S44/(C44) -> 0.39034965 | U44: =S44*维护参数!$B$20 -> 1814.15 | V44: =U44/(C44) -> 0.25372727 | W44: 王者 | X44: https://v.douyin.com/ettSTTldPIc/
...

Sheet 抖音小号维护标准
A1: 【内容事业部】抖音游戏类小号维护标准
A2: 私单按询单表私单价格，不额外折扣；平台单按各账号定制刊例报价×70% 播放目标沿用大号模板：定制基准×80%÷30×1000。按完整目标预留千川费用，不将星图中位数当成已实现播放扣减。
A9: 账号 | B9: 负责人 | C9: 备注 | D9: 定制 刊例价 | E9: 私单 报价 | F9: 涨价定制 刊例价 | G9: 涨价私单 报价 | H9: 订单 类型 | I9: 成交价 | J9: 目标播放量 （次） | K9: 千川版本 | L9: 千川 费用 | M9: 点赞 | N9: 评论 | O9: 收藏 | P9: 转发 | Q9: 互动 费用 | R9: 总维护 成本 | S9: 维护费 占成交价 | T9: 集团 毛利 | U9: 集团毛利率 （占折前报价） | V9: 部门 毛利 | W9: 部门毛利率 （占折前报价） | X9: 备注 | Y9: 主页链接
A10: 薛定谔的机 | B10: 薛荐轩 | D10: 10500 | E10: =D10*0.6 -> 6300 | F10: / | G10: / | H10: 私单 | I10: =(E10)*(1) -> 6300 | J10: =ROUNDUP(D10*维护参数!$B$11/维护参数!$B$12*1000,0) -> 280000 | K10: 普通千川 | L10: =(MAX(维护参数!$B$4,ROUNDUP(J10/10000,0)))*(维护参数!$B$2) -> 588 | M10: =ROUNDUP(D10*维护参数!$B$16/维护参数!$B$15/1000,0)*1000 -> 21000 | N10: =ROUNDUP(D10*维护参数!$B$17/维护参数!$B$15/10,0)*10 -> 210 | O10: =ROUNDUP(D10*维护参数!$B$18/维护参数!$B$15/10,0)*10 -> 210 | P10: =ROUNDUP(D10*维护参数!$B$19/维护参数!$B$15/10,0)*10 -> 320 | Q10: =M10/1000*维护参数!$B$6+N10*维护参数!$B$7+O10*维护参数!$B$8+P10*维护参数!$B$9 -> 1513 | R10: =SUM(L10,Q10) -> 2101 | S10: =R10/I10 -> 0.33349206 | T10: =I10-R10 -> 4199 | U10: =T10/(D10) -> 0.39990476 | V10: =T10*维护参数!$B$20 -> 2729.35 | W10: =V10/(D10) -> 0.2599381 | X10: 真人 | Y10: https://v.douyin.com/dcP3cOC30h4/
H11: 平台单 | I11: =(D10)*(维护参数!$B$10) -> 7350 | K11: 千川无视版 | L11: =(MAX(维护参数!$B$5,ROUNDUP(J10/10000,0)))*(维护参数!$B$3) -> 1540 | R11: =SUM(L11,Q10) -> 3053 | S11: =R11/I11 -> 0.41537415 | T11: =I11-R11 -> 4297 | U11: =T11/(D10) -> 0.4092381 | V11: =T11*维护参数!$B$20 -> 2793.05 | W11: =V11/(D10) -> 0.26600476
A12: 花满楼 | B12: 陈健伊 | D12: 11700 | E12: =D12*0.6 -> 7020 | F12: / | G12: / | H12: 私单 | I12: =(E12)*(1) -> 7020 | J12: =ROUNDUP(D12*维护参数!$B$11/维护参数!$B$12*1000,0) -> 312000 | K12: 普通千川 | L12: =(MAX(维护参数!$B$4,ROUNDUP(J12/10000,0)))*(维护参数!$B$2) -> 672 | M12: =ROUNDUP(D12*维护参数!$B$16/维护参数!$B$15/1000,0)*1000 -> 24000 | N12: =ROUNDUP(D12*维护参数!$B$17/维护参数!$B$15/10,0)*10 -> 240 | O12: =ROUNDUP(D12*维护参数!$B$18/维护参数!$B$15/10,0)*10 -> 240 | P12: =ROUNDUP(D12*维护参数!$B$19/维护参数!$B$15/10,0)*10 -> 360 | Q12: =M12/1000*维护参数!$B$6+N12*维护参数!$B$7+O12*维护参数!$B$8+P12*维护参数!$B$9 -> 1728 | R12: =SUM(L12,Q12) -> 2400 | S12: =R12/I12 -> 0.34188034 | T12: =I12-R12 -> 4620 | U12: =T12/(D12) -> 0.39487179 | V12: =T12*维护参数!$B$20 -> 3003 | W12: =V12/(D12) -> 0.25666667 | X12: 建议降价 | Y12: https://v.douyin.com/SAEJqgoPkrY/
H13: 平台单 | I13: =(D12)*(维护参数!$B$10) -> 8190 | K13: 千川无视版 | L13: =(MAX(维护参数!$B$5,ROUNDUP(J12/10000,0)))*(维护参数!$B$3) -> 1760 | R13: =SUM(L13,Q12) -> 3488 | S13: =R13/I13 -> 0.42588523 | T13: =I13-R13 -> 4702 | U13: =T13/(D12) -> 0.40188034 | V13: =T13*维护参数!$B$20 -> 3056.3 | W13: =V13/(D12) -> 0.26122222
A14: 麦小雯 | B14: 陈健伊 | D14: 6000 | E14: =D14*0.6 -> 3600 | F14: 9000 | G14: =F14*0.6 -> 5400 | H14: 私单 | I14: =(E14)*(1) -> 3600 | J14: =ROUNDUP(D14*维护参数!$B$11/维护参数!$B$12*1000,0) -> 160000 | K14: 普通千川 | L14: =(MAX(维护参数!$B$4,ROUNDUP(J14/10000,0)))*(维护参数!$B$2) -> 336 | M14: =ROUNDUP(D14*维护参数!$B$16/维护参数!$B$15/1000,0)*1000 -> 12000 | N14: =ROUNDUP(D14*维护参数!$B$17/维护参数!$B$15/10,0)*10 -> 120 | O14: =ROUNDUP(D14*维护参数!$B$18/维护参数!$B$15/10,0)*10 -> 120 | P14: =ROUNDUP(D14*维护参数!$B$19/维护参数!$B$15/10,0)*10 -> 180 | Q14: =M14/1000*维护参数!$B$6+N14*维护参数!$B$7+O14*维护参数!$B$8+P14*维护参数!$B$9 -> 864 | R14: =SUM(L14,Q14) -> 1200 | S14: =R14/I14 -> 0.33333333 | T14: =I14-R14 -> 2400 | U14: =T14/(D14) -> 0.4 | V14: =T14*维护参数!$B$20 -> 1560 | W14: =V14/(D14) -> 0.26 | Y14: https://v.douyin.com/DcH2brXPgvc/
H15: 平台单 | I15: =(D14)*(维护参数!$B$10) -> 4200 | K15: 千川无视版 | L15: =(MAX(维护参数!$B$5,ROUNDUP(J14/10000,0)))*(维护参数!$B$3) -> 880 | R15: =SUM(L15,Q14) -> 1744 | S15: =R15/I15 -> 0.4152381 | T15: =I15-R15 -> 2456 | U15: =T15/(D14) -> 0.40933333 | V15: =T15*维护参数!$B$20 -> 1596.4 | W15: =V15/(D14) -> 0.26606667
A16: 葵仔不想肝 | B16: 刘登魁 | D16: 6250 | E16: =D16*0.6 -> 3750 | F16: 7000 | G16: =F16*0.6 -> 4200 | H16: 私单 | I16: =(E16)*(1) -> 3750 | J16: =ROUNDUP(D16*维护参数!$B$11/维护参数!$B$12*1000,0) -> 166667 | K16: 普通千川 | L16: =(MAX(维护参数!$B$4,ROUNDUP(J16/10000,0)))*(维护参数!$B$2) -> 357 | M16: =ROUNDUP(D16*维护参数!$B$16/维护参数!$B$15/1000,0)*1000 -> 13000 | N16: =ROUNDUP(D16*维护参数!$B$17/维护参数!$B$15/10,0)*10 -> 130 | O16: =ROUNDUP(D16*维护参数!$B$18/维护参数!$B$15/10,0)*10 -> 130 | P16: =ROUNDUP(D16*维护参数!$B$19/维护参数!$B$15/10,0)*10 -> 190 | Q16: =M16/1000*维护参数!$B$6+N16*维护参数!$B$7+O16*维护参数!$B$8+P16*维护参数!$B$9 -> 935 | R16: =SUM(L16,Q16) -> 1292 | S16: =R16/I16 -> 0.34453333 | T16: =I16-R16 -> 2458 | U16: =T16/(D16) -> 0.39328 | V16: =T16*维护参数!$B$20 -> 1597.7 | W16: =V16/(D16) -> 0.255632 | Y16: https://v.douyin.com/38Scd6JrG_s/
H17: 平台单 | I17: =(D16)*(维护参数!$B$10) -> 4375 | K17: 千川无视版 | L17: =(MAX(维护参数!$B$5,ROUNDUP(J16/10000,0)))*(维护参数!$B$3) -> 935 | R17: =SUM(L17,Q16) -> 1870 | S17: =R17/I17 -> 0.42742857 | T17: =I17-R17 -> 2505 | U17: =T17/(D16) -> 0.4008 | V17: =T17*维护参数!$B$20 -> 1628.25 | W17: =V17/(D16) -> 0.26052
A18: 游热娃子 | B18: 杨鸿霆 | D18: 8750 | E18: =D18*0.6 -> 5250 | F18: 10000 | G18: =F18*0.6 -> 6000 | H18: 私单 | I18: =(E18)*(1) -> 5250 | J18: =ROUNDUP(D18*维护参数!$B$11/维护参数!$B$12*1000,0) -> 233334 | K18: 普通千川 | L18: =(MAX(维护参数!$B$4,ROUNDUP(J18/10000,0)))*(维护参数!$B$2) -> 504 | M18: =ROUNDUP(D18*维护参数!$B$16/维护参数!$B$15/1000,0)*1000 -> 18000 | N18: =ROUNDUP(D18*维护参数!$B$17/维护参数!$B$15/10,0)*10 -> 180 | O18: =ROUNDUP(D18*维护参数!$B$18/维护参数!$B$15/10,0)*10 -> 180 | P18: =ROUNDUP(D18*维护参数!$B$19/维护参数!$B$15/10,0)*10 -> 270 | Q18: =M18/1000*维护参数!$B$6+N18*维护参数!$B$7+O18*维护参数!$B$8+P18*维护参数!$B$9 -> 1296 | R18: =SUM(L18,Q18) -> 1800 | S18: =R18/I18 -> 0.34285714 | T18: =I18-R18 -> 3450 | U18: =T18/(D18) -> 0.39428571 | V18: =T18*维护参数!$B$20 -> 2242.5 | W18: =V18/(D18) -> 0.25628571 | X18: 数据好 | Y18: https://v.douyin.com/JmcvjVd/
H19: 平台单 | I19: =(D18)*(维护参数!$B$10) -> 6125 | K19: 千川无视版 | L19: =(MAX(维护参数!$B$5,ROUNDUP(J18/10000,0)))*(维护参数!$B$3) -> 1320 | R19: =SUM(L19,Q18) -> 2616 | S19: =R19/I19 -> 0.42710204 | T19: =I19-R19 -> 3509 | U19: =T19/(D18) -> 0.40102857 | V19: =T19*维护参数!$B$20 -> 2280.85 | W19: =V19/(D18) -> 0.26066857
A20: 游小妹 | B20: 杨鸿霆 | D20: 6000 | E20: =D20*0.6 -> 3600 | F20: 8000 | G20: =F20*0.6 -> 4800 | H20: 私单 | I20: =(E20)*(1) -> 3600 | J20: =ROUNDUP(D20*维护参数!$B$11/维护参数!$B$12*1000,0) -> 160000 | K20: 普通千川 | L20: =(MAX(维护参数!$B$4,ROUNDUP(J20/10000,0)))*(维护参数!$B$2) -> 336 | M20: =ROUNDUP(D20*维护参数!$B$16/维护参数!$B$15/1000,0)*1000 -> 12000 | N20: =ROUNDUP(D20*维护参数!$B$17/维护参数!$B$15/10,0)*10 -> 120 | O20: =ROUNDUP(D20*维护参数!$B$18/维护参数!$B$15/10,0)*10 -> 120 | P20: =ROUNDUP(D20*维护参数!$B$19/维护参数!$B$15/10,0)*10 -> 180 | Q20: =M20/1000*维护参数!$B$6+N20*维护参数!$B$7+O20*维护参数!$B$8+P20*维护参数!$B$9 -> 864 | R20: =SUM(L20,Q20) -> 1200 | S20: =R20/I20 -> 0.33333333 | T20: =I20-R20 -> 2400 | U20: =T20/(D20) -> 0.4 | V20: =T20*维护参数!$B$20 -> 1560 | W20: =V20/(D20) -> 0.26 | Y20: https://v.douyin.com/JmcXQpY/
H21: 平台单 | I21: =(D20)*(维护参数!$B$10) -> 4200 | K21: 千川无视版 | L21: =(MAX(维护参数!$B$5,ROUNDUP(J20/10000,0)))*(维护参数!$B$3) -> 880 | R21: =SUM(L21,Q20) -> 1744 | S21: =R21/I21 -> 0.4152381 | T21: =I21-R21 -> 2456 | U21: =T21/(D20) -> 0.40933333 | V21: =T21*维护参数!$B$20 -> 1596.4 | W21: =V21/(D20) -> 0.26606667
A22: 灵梦小师妹 | B22: 林宇辰 | C22: 王者 | D22: 6000 | E22: =D22*0.6 -> 3600 | F22: / | G22: / | H22: 私单 | I22: =(E22)*(1) -> 3600 | J22: =ROUNDUP(D22*维护参数!$B$11/维护参数!$B$12*1000,0) -> 160000 | K22: 普通千川 | L22: =(MAX(维护参数!$B$4,ROUNDUP(J22/10000,0)))*(维护参数!$B$2) -> 336 | M22: =ROUNDUP(D22*维护参数!$B$16/维护参数!$B$15/1000,0)*1000 -> 12000 | N22: =ROUNDUP(D22*维护参数!$B$17/维护参数!$B$15/10,0)*10 -> 120 | O22: =ROUNDUP(D22*维护参数!$B$18/维护参数!$B$15/10,0)*10 -> 120 | P22: =ROUNDUP(D22*维护参数!$B$19/维护参数!$B$15/10,0)*10 -> 180 | Q22: =M22/1000*维护参数!$B$6+N22*维护参数!$B$7+O22*维护参数!$B$8+P22*维护参数!$B$9 -> 864 | R22: =SUM(L22,Q22) -> 1200 | S22: =R22/I22 -> 0.33333333 | T22: =I22-R22 -> 2400 | U22: =T22/(D22) -> 0.4 | V22: =T22*维护参数!$B$20 -> 1560 | W22: =V22/(D22) -> 0.26 | X22: 王者 | Y22: https://www.douyin.com/user/MS4wLjABAAAAJfqON1LDmWBPlUXvQ-iwZ6AZLbLuIj72uGiFUuot89k
H23: 平台单 | I23: =(D22)*(维护参数!$B$10) -> 4200 | K23: 千川无视版 | L23: =(MAX(维护参数!$B$5,ROUNDUP(J22/10000,0)))*(维护参数!$B$3) -> 880 | R23: =SUM(L23,Q22) -> 1744 | S23: =R23/I23 -> 0.4152381 | T23: =I23-R23 -> 2456 | U23: =T23/(D22) -> 0.40933333 | V23: =T23*维护参数!$B$20 -> 1596.4 | W23: =V23/(D22) -> 0.26606667
A24: 超玩教授 | B24: 商光涵 | C24: 封面+隐藏 | D24: 6000 | E24: =D24*0.6 -> 3600 | F24: 8000 | G24: =F24*0.6 -> 4800 | H24: 私单 | I24: =(E24)*(1) -> 3600 | J24: =ROUNDUP(D24*维护参数!$B$11/维护参数!$B$12*1000,0) -> 160000 | K24: 普通千川 | L24: =(MAX(维护参数!$B$4,ROUNDUP(J24/10000,0)))*(维护参数!$B$2) -> 336 | M24: =ROUNDUP(D24*维护参数!$B$16/维护参数!$B$15/1000,0)*1000 -> 12000 | N24: =ROUNDUP(D24*维护参数!$B$17/维护参数!$B$15/10,0)*10 -> 120 | O24: =ROUNDUP(D24*维护参数!$B$18/维护参数!$B$15/10,0)*10 -> 120 | P24: =ROUNDUP(D24*维护参数!$B$19/维护参数!$B$15/10,0)*10 -> 180 | Q24: =M24/1000*维护参数!$B$6+N24*维护参数!$B$7+O24*维护参数!$B$8+P24*维护参数!$B$9 -> 864 | R24: =SUM(L24,Q24) -> 1200 | S24: =R24/I24 -> 0.33333333 | T24: =I24-R24 -> 2400 | U24: =T24/(D24) -> 0.4 | V24: =T24*维护参数!$B$20 -> 1560 | W24: =V24/(D24) -> 0.26 | X24: 需改封面+隐藏 | Y24: https://v.douyin.com/JJ3p572/
H25: 平台单 | I25: =(D24)*(维护参数!$B$10) -> 4200 | K25: 千川无视版 | L25: =(MAX(维护参数!$B$5,ROUNDUP(J24/10000,0)))*(维护参数!$B$3) -> 880 | R25: =SUM(L25,Q24) -> 1744 | S25: =R25/I25 -> 0.4152381 | T25: =I25-R25 -> 2456 | U25: =T25/(D24) -> 0.40933333 | V25: =T25*维护参数!$B$20 -> 1596.4 | W25: =V25/(D24) -> 0.26606667
A26: lee小强 | B26: 商光涵 | D26: 4800 | E26: =D26*0.6 -> 2880 | F26: 6000 | G26: =F26*0.6 -> 3600 | H26: 私单 | I26: =(E26)*(1) -> 2880 | J26: =ROUNDUP(D26*维护参数!$B$11/维护参数!$B$12*1000,0) -> 128000 | K26: 普通千川 | L26: =(MAX(维护参数!$B$4,ROUNDUP(J26/10000,0)))*(维护参数!$B$2) -> 273 | M26: =ROUNDUP(D26*维护参数!$B$16/维护参数!$B$15/1000,0)*1000 -> 10000 | N26: =ROUNDUP(D26*维护参数!$B$17/维护参数!$B$15/10,0)*10 -> 100 | O26: =ROUNDUP(D26*维护参数!$B$18/维护参数!$B$15/10,0)*10 -> 100 | P26: =ROUNDUP(D26*维护参数!$B$19/维护参数!$B$15/10,0)*10 -> 150 | Q26: =M26/1000*维护参数!$B$6+N26*维护参数!$B$7+O26*维护参数!$B$8+P26*维护参数!$B$9 -> 720 | R26: =SUM(L26,Q26) -> 993 | S26: =R26/I26 -> 0.34479167 | T26: =I26-R26 -> 1887 | U26: =T26/(D26) -> 0.393125 | V26: =T26*维护参数!$B$20 -> 1226.55 | W26: =V26/(D26) -> 0.25553125 | Y26: https://v.douyin.com/ihb6eF8j/
H27: 平台单 | I27: =(D26)*(维护参数!$B$10) -> 3360 | K27: 千川无视版 | L27: =(MAX(维护参数!$B$5,ROUNDUP(J26/10000,0)))*(维护参数!$B$3) -> 715 | R27: =SUM(L27,Q26) -> 1435 | S27: =R27/I27 -> 0.42708333 | T27: =I27-R27 -> 1925 | U27: =T27/(D26) -> 0.40104167 | V27: =T27*维护参数!$B$20 -> 1251.25 | W27: =V27/(D26) -> 0.26067708
A28: 不玩就分手 | B28: 刘登魁 | C28: 王者 | D28: 3500 | E28: =D28*0.6 -> 2100 | F28: 4500 | G28: =F28*0.6 -> 2700 | H28: 私单 | I28: =(E28)*(1) -> 2100 | J28: =ROUNDUP(D28*维护参数!$B$11/维护参数!$B$12*1000,0) -> 93334 | K28: 普通千川 | L28: =(MAX(维护参数!$B$4,ROUNDUP(J28/10000,0)))*(维护参数!$B$2) -> 210 | M28: =ROUNDUP(D28*维护参数!$B$16/维护参数!$B$15/1000,0)*1000 -> 7000 | N28: =ROUNDUP(D28*维护参数!$B$17/维护参数!$B$15/10,0)*10 -> 70 | O28: =ROUNDUP(D28*维护参数!$B$18/维护参数!$B$15/10,0)*10 -> 70 | P28: =ROUNDUP(D28*维护参数!$B$19/维护参数!$B$15/10,0)*10 -> 110 | Q28: =M28/1000*维护参数!$B$6+N28*维护参数!$B$7+O28*维护参数!$B$8+P28*维护参数!$B$9 -> 505 | R28: =SUM(L28,Q28) -> 715 | S28: =R28/I28 -> 0.34047619 | T28: =I28-R28 -> 1385 | U28: =T28/(D28) -> 0.39571429 | V28: =T28*维护参数!$B$20 -> 900.25 | W28: =V28/(D28) -> 0.25721429 | X28: 王者 | Y28: https://v.douyin.com/jTKED_9fV4A/
H29: 平台单 | I29: =(D28)*(维护参数!$B$10) -> 2450 | K29: 千川无视版 | L29: =(MAX(维护参数!$B$5,ROUNDUP(J28/10000,0)))*(维护参数!$B$3) -> 550 | R29: =SUM(L29,Q28) -> 1055 | S29: =R29/I29 -> 0.43061224 | T29: =I29-R29 -> 1395 | U29: =T29/(D28) -> 0.39857143 | V29: =T29*维护参数!$B$20 -> 906.75 | W29: =V29/(D28) -> 0.25907143
A30: 游梗要说 | B30: 罗晓棋 | D30: 7800 | E30: =D30*0.6 -> 4680 | F30: / | G30: / | H30: 私单 | I30: =(E30)*(1) -> 4680 | J30: =ROUNDUP(D30*维护参数!$B$11/维护参数!$B$12*1000,0) -> 208000 | K30: 普通千川 | L30: =(MAX(维护参数!$B$4,ROUNDUP(J30/10000,0)))*(维护参数!$B$2) -> 441 | M30: =ROUNDUP(D30*维护参数!$B$16/维护参数!$B$15/1000,0)*1000 -> 16000 | N30: =ROUNDUP(D30*维护参数!$B$17/维护参数!$B$15/10,0)*10 -> 160 | O30: =ROUNDUP(D30*维护参数!$B$18/维护参数!$B$15/10,0)*10 -> 160 | P30: =ROUNDUP(D30*维护参数!$B$19/维护参数!$B$15/10,0)*10 -> 240 | Q30: =M30/1000*维护参数!$B$6+N30*维护参数!$B$7+O30*维护参数!$B$8+P30*维护参数!$B$9 -> 1152 | R30: =SUM(L30,Q30) -> 1593 | S30: =R30/I30 -> 0.34038462 | T30: =I30-R30 -> 3087 | U30: =T30/(D30) -> 0.39576923 | V30: =T30*维护参数!$B$20 -> 2006.55 | W30: =V30/(D30) -> 0.25725 | Y30: https://www.douyin.com/user/MS4wLjABAAAAbRgpD5qO5M7mlI-ALMWDbsqjwiSeFC1WxNPKVgjsSCbFam1N0thGyVDw-PfRjICt
H31: 平台单 | I31: =(D30)*(维护参数!$B$10) -> 5460 | K31: 千川无视版 | L31: =(MAX(维护参数!$B$5,ROUNDUP(J30/10000,0)))*(维护参数!$B$3) -> 1155 | R31: =SUM(L31,Q30) -> 2307 | S31: =R31/I31 -> 0.42252747 | T31: =I31-R31 -> 3153 | U31: =T31/(D30) -> 0.40423077 | V31: =T31*维护参数!$B$20 -> 2049.45 | W31: =V31/(D30) -> 0.26275
A32: 中二探长 | B32: 陈泓睿 | C32: 王者 | D32: 3750 | E32: =D32*0.6 -> 2250 | F32: 5000 | G32: =F32*0.6 -> 3000 | H32: 私单 | I32: =(E32)*(1) -> 2250 | J32: =ROUNDUP(D32*维护参数!$B$11/维护参数!$B$12*1000,0) -> 100000 | K32: 普通千川 | L32: =(MAX(维护参数!$B$4,ROUNDUP(J32/10000,0)))*(维护参数!$B$2) -> 210 | M32: =ROUNDUP(D32*维护参数!$B$16/维护参数!$B$15/1000,0)*1000 -> 8000 | N32: =ROUNDUP(D32*维护参数!$B$17/维护参数!$B$15/10,0)*10 -> 80 | O32: =ROUNDUP(D32*维护参数!$B$18/维护参数!$B$15/10,0)*10 -> 80 | P32: =ROUNDUP(D32*维护参数!$B$19/维护参数!$B$15/10,0)*10 -> 120 | Q32: =M32/1000*维护参数!$B$6+N32*维护参数!$B$7+O32*维护参数!$B$8+P32*维护参数!$B$9 -> 576 | R32: =SUM(L32,Q32) -> 786 | S32: =R32/I32 -> 0.34933333 | T32: =I32-R32 -> 1464 | U32: =T32/(D32) -> 0.3904 | V32: =T32*维护参数!$B$20 -> 951.6 | W32: =V32/(D32) -> 0.25376 | X32: 王者 | Y32: https://v.douyin.com/mFA-j2xaAJY/
H33: 平台单 | I33: =(D32)*(维护参数!$B$10) -> 2625 | K33: 千川无视版 | L33: =(MAX(维护参数!$B$5,ROUNDUP(J32/10000,0)))*(维护参数!$B$3) -> 550 | R33: =SUM(L33,Q32) -> 1126 | S33: =R33/I33 -> 0.42895238 | T33: =I33-R33 -> 1499 | U33: =T33/(D32) -> 0.39973333 | V33: =T33*维护参数!$B$20 -> 974.35 | W33: =V33/(D32) -> 0.25982667
A34: 嘿小虎 | B34: 陈泓睿 | C34: 逆水寒-之前 | D34: 3000 | E34: =D34*0.6 -> 1800 | F34: 5000 | G34: =F34*0.6 -> 3000 | H34: 私单 | I34: =(E34)*(1) -> 1800 | J34: =ROUNDUP(D34*维护参数!$B$11/维护参数!$B$12*1000,0) -> 80000 | K34: 普通千川 | L34: =(MAX(维护参数!$B$4,ROUNDUP(J34/10000,0)))*(维护参数!$B$2) -> 210 | M34: =ROUNDUP(D34*维护参数!$B$16/维护参数!$B$15/1000,0)*1000 -> 6000 | N34: =ROUNDUP(D34*维护参数!$B$17/维护参数!$B$15/10,0)*10 -> 60 | O34: =ROUNDUP(D34*维护参数!$B$18/维护参数!$B$15/10,0)*10 -> 60 | P34: =ROUNDUP(D34*维护参数!$B$19/维护参数!$B$15/10,0)*10 -> 90 | Q34: =M34/1000*维护参数!$B$6+N34*维护参数!$B$7+O34*维护参数!$B$8+P34*维护参数!$B$9 -> 432 | R34: =SUM(L34,Q34) -> 642 | S34: =R34/I34 -> 0.35666667 | T34: =I34-R34 -> 1158 | U34: =T34/(D34) -> 0.386 | V34: =T34*维护参数!$B$20 -> 752.7 | W34: =V34/(D34) -> 0.2509 | X34: 逆水寒-之前 需改封面+隐藏 | Y34: https://v.douyin.com/lIhi6TchbPw/
H35: 平台单 | I35: =(D34)*(维护参数!$B$10) -> 2100 | K35: 千川无视版 | L35: =(MAX(维护参数!$B$5,ROUNDUP(J34/10000,0)))*(维护参数!$B$3) -> 440 | R35: =SUM(L35,Q34) -> 872 | S35: =R35/I35 -> 0.4152381 | T35: =I35-R35 -> 1228 | U35: =T35/(D34) -> 0.40933333 | V35: =T35*维护参数!$B$20 -> 798.2 | W35: =V35/(D34) -> 0.26606667
A36: 有事找学姐 | B36: 林宇辰 | C36: 王者 | D36: 7150 | E36: =D36*0.6 -> 4290 | F36: / | G36: / | H36: 私单 | I36: =(E36)*(1) -> 4290 | J36: =ROUNDUP(D36*维护参数!$B$11/维护参数!$B$12*1000,0) -> 190667 | K36: 普通千川 | L36: =(MAX(维护参数!$B$4,ROUNDUP(J36/10000,0)))*(维护参数!$B$2) -> 420 | M36: =ROUNDUP(D36*维护参数!$B$16/维护参数!$B$15/1000,0)*1000 -> 15000 | N36: =ROUNDUP(D36*维护参数!$B$17/维护参数!$B$15/10,0)*10 -> 150 | O36: =ROUNDUP(D36*维护参数!$B$18/维护参数!$B$15/10,0)*10 -> 150 | P36: =ROUNDUP(D36*维护参数!$B$19/维护参数!$B$15/10,0)*10 -> 220 | Q36: =M36/1000*维护参数!$B$6+N36*维护参数!$B$7+O36*维护参数!$B$8+P36*维护参数!$B$9 -> 1079 | R36: =SUM(L36,Q36) -> 1499 | S36: =R36/I36 -> 0.34941725 | T36: =I36-R36 -> 2791 | U36: =T36/(D36) -> 0.39034965 | V36: =T36*维护参数!$B$20 -> 1814.15 | W36: =V36/(D36) -> 0.25372727 | X36: 王者 | Y36: https://v.douyin.com/ettSTTldPIc/
H37: 平台单 | I37: =(D36)*(维护参数!$B$10) -> 5005 | K37: 千川无视版 | L37: =(MAX(维护参数!$B$5,ROUNDUP(J36/10000,0)))*(维护参数!$B$3) -> 1100 | R37: =SUM(L37,Q36) -> 2179 | S37: =R37/I37 -> 0.43536464 | T37: =I37-R37 -> 2826 | U37: =T37/(D36) -> 0.39524476 | V37: =T37*维护参数!$B$20 -> 1836.9 | W37: =V37/(D36) -> 0.25690909
A38: 跑腿的包子 | B38: 陈泓睿 | D38: 7000 | E38: =D38*0.6 -> 4200 | F38: / | G38: / | H38: 私单 | I38: =(E38)*(1) -> 4200 | J38: =ROUNDUP(D38*维护参数!$B$11/维护参数!$B$12*1000,0) -> 186667 | K38: 普通千川 | L38: =(MAX(维护参数!$B$4,ROUNDUP(J38/10000,0)))*(维护参数!$B$2) -> 399 | M38: =ROUNDUP(D38*维护参数!$B$16/维护参数!$B$15/1000,0)*1000 -> 14000 | N38: =ROUNDUP(D38*维护参数!$B$17/维护参数!$B$15/10,0)*10 -> 140 | O38: =ROUNDUP(D38*维护参数!$B$18/维护参数!$B$15/10,0)*10 -> 140 | P38: =ROUNDUP(D38*维护参数!$B$19/维护参数!$B$15/10,0)*10 -> 210 | Q38: =M38/1000*维护参数!$B$6+N38*维护参数!$B$7+O38*维护参数!$B$8+P38*维护参数!$B$9 -> 1008 | R38: =SUM(L38,Q38) -> 1407 | S38: =R38/I38 -> 0.335 | T38: =I38-R38 -> 2793 | U38: =T38/(D38) -> 0.399 | V38: =T38*维护参数!$B$20 -> 1815.45 | W38: =V38/(D38) -> 0.25935 | X38: 分发-精选激励 | Y38: https://v.douyin.com/Vva749Cn4Fk/
H39: 平台单 | I39: =(D38)*(维护参数!$B$10) -> 4900 | K39: 千川无视版 | L39: =(MAX(维护参数!$B$5,ROUNDUP(J38/10000,0)))*(维护参数!$B$3) -> 1045 | R39: =SUM(L39,Q38) -> 2053 | S39: =R39/I39 -> 0.41897959 | T39: =I39-R39 -> 2847 | U39: =T39/(D38) -> 0.40671429 | V39: =T39*维护参数!$B$20 -> 1850.55 | W39: =V39/(D38) -> 0.26436429
A40: 皮皮说游戏 | B40: 陈泓睿 | C40: 星广 | D40: 5500 | E40: =D40*0.6 -> 3300 | F40: / | G40: / | H40: 私单 | I40: =(E40)*(1) -> 3300 | J40: =ROUNDUP(D40*维护参数!$B$11/维护参数!$B$12*1000,0) -> 146667 | K40: 普通千川 | L40: =(MAX(维护参数!$B$4,ROUNDUP(J40/10000,0)))*(维护参数!$B$2) -> 315 | M40: =ROUNDUP(D40*维护参数!$B$16/维护参数!$B$15/1000,0)*1000 -> 11000 | N40: =ROUNDUP(D40*维护参数!$B$17/维护参数!$B$15/10,0)*10 -> 110 | O40: =ROUNDUP(D40*维护参数!$B$18/维护参数!$B$15/10,0)*10 -> 110 | P40: =ROUNDUP(D40*维护参数!$B$19/维护参数!$B$15/10,0)*10 -> 170 | Q40: =M40/1000*维护参数!$B$6+N40*维护参数!$B$7+O40*维护参数!$B$8+P40*维护参数!$B$9 -> 793 | R40: =SUM(L40,Q40) -> 1108 | S40: =R40/I40 -> 0.33575758 | T40: =I40-R40 -> 2192 | U40: =T40/(D40) -> 0.39854545 | V40: =T40*维护参数!$B$20 -> 1424.8 | W40: =V40/(D40) -> 0.25905455 | X40: 星广 | Y40: https://v.douyin.com/iSUabqnS/
H41: 平台单 | I41: =(D40)*(维护参数!$B$10) -> 3850 | K41: 千川无视版 | L41: =(MAX(维护参数!$B$5,ROUNDUP(J40/10000,0)))*(维护参数!$B$3) -> 825 | R41: =SUM(L41,Q40) -> 1618 | S41: =R41/I41 -> 0.42025974 | T41: =I41-R41 -> 2232 | U41: =T41/(D40) -> 0.40581818 | V41: =T41*维护参数!$B$20 -> 1450.8 | W41: =V41/(D40) -> 0.26378182
A42: 夏洛 | B42: 刘登魁 | C42: 星广 | D42: 5000 | E42: =D42*0.6 -> 3000 | F42: / | G42: / | H42: 私单 | I42: =(E42)*(1) -> 3000 | J42: =ROUNDUP(D42*维护参数!$B$11/维护参数!$B$12*1000,0) -> 133334 | K42: 普通千川 | L42: =(MAX(维护参数!$B$4,ROUNDUP(J42/10000,0)))*(维护参数!$B$2) -> 294 | M42: =ROUNDUP(D42*维护参数!$B$16/维护参数!$B$15/1000,0)*1000 -> 10000 | N42: =ROUNDUP(D42*维护参数!$B$17/维护参数!$B$15/10,0)*10 -> 100 | O42: =ROUNDUP(D42*维护参数!$B$18/维护参数!$B$15/10,0)*10 -> 100 | P42: =ROUNDUP(D42*维护参数!$B$19/维护参数!$B$15/10,0)*10 -> 150 | Q42: =M42/1000*维护参数!$B$6+N42*维护参数!$B$7+O42*维护参数!$B$8+P42*维护参数!$B$9 -> 720 | R42: =SUM(L42,Q42) -> 1014 | S42: =R42/I42 -> 0.338 | T42: =I42-R42 -> 1986 | U42: =T42/(D42) -> 0.3972 | V42: =T42*维护参数!$B$20 -> 1290.9 | W42: =V42/(D42) -> 0.25818 | X42: 星广 | Y42: https://v.douyin.com/wq_9XvcbfS0/
H43: 平台单 | I43: =(D42)*(维护参数!$B$10) -> 3500 | K43: 千川无视版 | L43: =(MAX(维护参数!$B$5,ROUNDUP(J42/10000,0)))*(维护参数!$B$3) -> 770 | R43: =SUM(L43,Q42) -> 1490 | S43: =R43/I43 -> 0.42571429 | T43: =I43-R43 -> 2010 | U43: =T43/(D42) -> 0.402 | V43: =T43*维护参数!$B$20 -> 1306.5 | W43: =V43/(D42) -> 0.2613
A44: 畅玩百晓生 | B44: 刘登魁 | C44: 星广 | D44: 5000 | E44: =D44*0.6 -> 3000 | F44: / | G44: / | H44: 私单 | I44: =(E44)*(1) -> 3000 | J44: =ROUNDUP(D44*维护参数!$B$11/维护参数!$B$12*1000,0) -> 133334 | K44: 普通千川 | L44: =(MAX(维护参数!$B$4,ROUNDUP(J44/10000,0)))*(维护参数!$B$2) -> 294 | M44: =ROUNDUP(D44*维护参数!$B$16/维护参数!$B$15/1000,0)*1000 -> 10000 | N44: =ROUNDUP(D44*维护参数!$B$17/维护参数!$B$15/10,0)*10 -> 100 | O44: =ROUNDUP(D44*维护参数!$B$18/维护参数!$B$15/10,0)*10 -> 100 | P44: =ROUNDUP(D44*维护参数!$B$19/维护参数!$B$15/10,0)*10 -> 150 | Q44: =M44/1000*维护参数!$B$6+N44*维护参数!$B$7+O44*维护参数!$B$8+P44*维护参数!$B$9 -> 720 | R44: =SUM(L44,Q44) -> 1014 | S44: =R44/I44 -> 0.338 | T44: =I44-R44 -> 1986 | U44: =T44/(D44) -> 0.3972 | V44: =T44*维护参数!$B$20 -> 1290.9 | W44: =V44/(D44) -> 0.25818 | X44: 星广 | Y44: https://v.douyin.com/jTTVNutNIRQ/
H45: 平台单 | I45: =(D44)*(维护参数!$B$10) -> 3500 | K45: 千川无视版 | L45: =(MAX(维护参数!$B$5,ROUNDUP(J44/10000,0)))*(维护参数!$B$3) -> 770 | R45: =SUM(L45,Q44) -> 1490 | S45: =R45/I45 -> 0.42571429 | T45: =I45-R45 -> 2010 | U45: =T45/(D44) -> 0.402 | V45: =T45*维护参数!$B$20 -> 1306.5 | W45: =V45/(D44) -> 0.2613
A46: 游戏永动机 | B46: 刘登魁 | C46: 星广 | D46: 5000 | E46: =D46*0.6 -> 3000 | F46: / | G46: / | H46: 私单 | I46: =(E46)*(1) -> 3000 | J46: =ROUNDUP(D46*维护参数!$B$11/维护参数!$B$12*1000,0) -> 133334 | K46: 普通千川 | L46: =(MAX(维护参数!$B$4,ROUNDUP(J46/10000,0)))*(维护参数!$B$2) -> 294 | M46: =ROUNDUP(D46*维护参数!$B$16/维护参数!$B$15/1000,0)*1000 -> 10000 | N46: =ROUNDUP(D46*维护参数!$B$17/维护参数!$B$15/10,0)*10 -> 100 | O46: =ROUNDUP(D46*维护参数!$B$18/维护参数!$B$15/10,0)*10 -> 100 | P46: =ROUNDUP(D46*维护参数!$B$19/维护参数!$B$15/10,0)*10 -> 150 | Q46: =M46/1000*维护参数!$B$6+N46*维护参数!$B$7+O46*维护参数!$B$8+P46*维护参数!$B$9 -> 720 | R46: =SUM(L46,Q46) -> 1014 | S46: =R46/I46 -> 0.338 | T46: =I46-R46 -> 1986 | U46: =T46/(D46) -> 0.3972 | V46: =T46*维护参数!$B$20 -> 1290.9 | W46: =V46/(D46) -> 0.25818 | X46: 星广 | Y46: https://v.douyin.com/c2M4VXTdIvM/
...

Sheet 维护参数
A1: 参数 | B1: 数值 | C1: 单位 / 来源
A2: 私单千川 | B2: 21 | C2: 元/万；
A3: 平台千川无视版 | B3: 55 | C3: 元/万；
A4: 私单千川起量 | B4: 10 | C4: 万
A5: 平台千川起量 | B5: 5 | C5: 万
A6: 点赞（科技） | B6: 60 | C6: 元/千次；
A7: 自定义评论 | B7: 0.8 | C7: 元/个；
A8: 收藏 | B8: 0.1 | C8: 元/个；
A9: 转发 | B9: 0.2 | C9: 元/个；
A10: 定制对客折扣 | B10: 0.7
A11: 折扣换算 | B11: 0.8
A12: 目标播放CPM | B12: 30 | C12: 元/千次；
A13: 星图观察CPM | B13: 200
A14: 星图观察系数 | B14: 1.5
A15: 互动档基准报价 | B15: 10000 | C15: 元；
A16: 点赞基准 | B16: 20000 | C16: 个；
A17: 评论基准 | B17: 200 | C17: 个；
A18: 收藏基准 | B18: 200 | C18: 个；
A19: 转发基准 | B19: 300 | C19: 个；
A20: 部门分成比例 | B20: 0.65 | C20: 沿用大号模板T列
A23: 来源与口径
A24: 账号与报价：【内容事业部】自孵化账号询单信息.xlsx，抖音页A/D/I/L/M/P列；原表更新2026-09-11。
A25: 价格：style-library/gross-margin/douyin.json，采用启用项unitPrice；未采用旧note中的价格。
A26: 模板：自孵化维护标准.xlsx，维护标准页J/K/P/R—U列。互动量按定制刊例价缩放为本次建议。
A27: 5个星广联投账号仍纳入，但本次仅按用户指定的私单/平台七折两种规则，不采用原表可谈深折条款。
A28: 毛利计算沿用工作台：成交价－维护成本；集团毛利率以折前下单基准为分母，部门毛利为集团毛利×65%。
A29: 维护费按完整目标预算，实际执行先减自然数据再核算；中位数未作为可购买或已实现数量。
A30: 空缺实际数据不填零。当前表用于逐账号制定预算，不代表历史表现、平台验收承诺或已完成维护。
