Workbook

Sheet 抖音大号维护标准
A1: 【MCN事业部】抖音大号维护标准
A2: 目标星图播放中位数 = 下阶段报价 ÷ 目标CPM 200 × 1000 × 1.5 维护顺序： 1、冲榜项目/发布后急需上量/抖加无法过审，优先采用千川无视版进行维护 2、除以上情况外，应当优先采用抖加维护，正常情况下仅适用抖加采买播放量，互动量通过HKJ补齐 达到目标中位数并形成至少3条满30天样本后，下月执行涨价；平台预期CPM暂时没变化也不立即降价。
A3: 账号
A4: 花无缺
A6: 最游话说
A8: 报告砖家
A10: 策划克星阿强
A12: 天机妹
A14: 木游话说
A16: 麦冬冬
A22: 【MCN事业部】抖音小号维护标准
A23: 私单按询单表私单价格，不额外折扣；平台单按各账号定制刊例报价×70% 播放目标沿用大号模板：定制基准×80%÷30×1000。按完整目标预留千川费用，不将星图中位数当成已实现播放扣减。
A24: 账号 | B24: 负责人 | C24: 定制 刊例价 | D24: 私单 报价 | E24: 涨价定制 刊例价 | F24: 涨价私单 报价 | G24: 订单 类型 | H24: 成交价 | I24: 目标播放量 （次） | J24: 千川版本 | K24: 千川 费用 | L24: 点赞 | M24: 评论 | N24: 收藏 | O24: 转发 | P24: 互动 费用 | Q24: 总维护 成本 | R24: 维护费 占成交价 | S24: 集团 毛利 | T24: 集团毛利率 （占折前报价） | U24: 部门 毛利 | V24: 部门毛利率 （占折前报价） | W24: 备注 | X24: 主页链接
A25: 薛定谔的机 | B25: 薛荐轩 | C25: 10500 | D25: =C25*0.6 -> 6300 | E25: / | F25: / | G25: 私单 | H25: =(D25)*(1) -> 6300 | I25: =ROUNDUP(C25*维护参数!$B$11/维护参数!$B$12*1000,0) -> 280000 | J25: 普通千川 | K25: =(MAX(维护参数!$B$4,ROUNDUP(I25/10000,0)))*(维护参数!$B$2) -> 588 | L25: =ROUNDUP(C25*维护参数!$B$16/维护参数!$B$15/1000,0)*1000 -> 21000 | M25: =ROUNDUP(C25*维护参数!$B$17/维护参数!$B$15/10,0)*10 -> 210 | N25: =ROUNDUP(C25*维护参数!$B$18/维护参数!$B$15/10,0)*10 -> 210 | O25: =ROUNDUP(C25*维护参数!$B$19/维护参数!$B$15/10,0)*10 -> 320 | P25: =L25/1000*维护参数!$B$6+M25*维护参数!$B$7+N25*维护参数!$B$8+O25*维护参数!$B$9 -> 1513 | Q25: =SUM(K25,P25) -> 2101 | R25: =Q25/H25 -> 0.33349206 | S25: =H25-Q25 -> 4199 | T25: =S25/(C25) -> 0.39990476 | U25: =S25*维护参数!$B$20 -> 2729.35 | V25: =U25/(C25) -> 0.2599381 | W25: 真人 | X25: https://v.douyin.com/dcP3cOC30h4/
G26: 平台单 | H26: =(C25)*(维护参数!$B$10) -> 7350 | J26: 千川无视版 | K26: =(MAX(维护参数!$B$5,ROUNDUP(I25/10000,0)))*(维护参数!$B$3) -> 1540 | Q26: =SUM(K26,P25) -> 3053 | R26: =Q26/H26 -> 0.41537415 | S26: =H26-Q26 -> 4297 | T26: =S26/(C25) -> 0.4092381 | U26: =S26*维护参数!$B$20 -> 2793.05 | V26: =U26/(C25) -> 0.26600476
A27: 花满楼 | B27: 陈健伊 | C27: 11700 | D27: =C27*0.6 -> 7020 | E27: / | F27: / | G27: 私单 | H27: =(D27)*(1) -> 7020 | I27: =ROUNDUP(C27*维护参数!$B$11/维护参数!$B$12*1000,0) -> 312000 | J27: 普通千川 | K27: =(MAX(维护参数!$B$4,ROUNDUP(I27/10000,0)))*(维护参数!$B$2) -> 672 | L27: =ROUNDUP(C27*维护参数!$B$16/维护参数!$B$15/1000,0)*1000 -> 24000 | M27: =ROUNDUP(C27*维护参数!$B$17/维护参数!$B$15/10,0)*10 -> 240 | N27: =ROUNDUP(C27*维护参数!$B$18/维护参数!$B$15/10,0)*10 -> 240 | O27: =ROUNDUP(C27*维护参数!$B$19/维护参数!$B$15/10,0)*10 -> 360 | P27: =L27/1000*维护参数!$B$6+M27*维护参数!$B$7+N27*维护参数!$B$8+O27*维护参数!$B$9 -> 1728 | Q27: =SUM(K27,P27) -> 2400 | R27: =Q27/H27 -> 0.34188034 | S27: =H27-Q27 -> 4620 | T27: =S27/(C27) -> 0.39487179 | U27: =S27*维护参数!$B$20 -> 3003 | V27: =U27/(C27) -> 0.25666667 | W27: 建议降价 | X27: https://v.douyin.com/SAEJqgoPkrY/
G28: 平台单 | H28: =(C27)*(维护参数!$B$10) -> 8190 | J28: 千川无视版 | K28: =(MAX(维护参数!$B$5,ROUNDUP(I27/10000,0)))*(维护参数!$B$3) -> 1760 | Q28: =SUM(K28,P27) -> 3488 | R28: =Q28/H28 -> 0.42588523 | S28: =H28-Q28 -> 4702 | T28: =S28/(C27) -> 0.40188034 | U28: =S28*维护参数!$B$20 -> 3056.3 | V28: =U28/(C27) -> 0.26122222
A29: 麦小雯 | B29: 陈健伊 | C29: 6000 | D29: =C29*0.6 -> 3600 | E29: 9000 | F29: =E29*0.6 -> 5400 | G29: 私单 | H29: =(D29)*(1) -> 3600 | I29: =ROUNDUP(C29*维护参数!$B$11/维护参数!$B$12*1000,0) -> 160000 | J29: 普通千川 | K29: =(MAX(维护参数!$B$4,ROUNDUP(I29/10000,0)))*(维护参数!$B$2) -> 336 | L29: =ROUNDUP(C29*维护参数!$B$16/维护参数!$B$15/1000,0)*1000 -> 12000 | M29: =ROUNDUP(C29*维护参数!$B$17/维护参数!$B$15/10,0)*10 -> 120 | N29: =ROUNDUP(C29*维护参数!$B$18/维护参数!$B$15/10,0)*10 -> 120 | O29: =ROUNDUP(C29*维护参数!$B$19/维护参数!$B$15/10,0)*10 -> 180 | P29: =L29/1000*维护参数!$B$6+M29*维护参数!$B$7+N29*维护参数!$B$8+O29*维护参数!$B$9 -> 864 | Q29: =SUM(K29,P29) -> 1200 | R29: =Q29/H29 -> 0.33333333 | S29: =H29-Q29 -> 2400 | T29: =S29/(C29) -> 0.4 | U29: =S29*维护参数!$B$20 -> 1560 | V29: =U29/(C29) -> 0.26 | X29: https://v.douyin.com/DcH2brXPgvc/
G30: 平台单 | H30: =(C29)*(维护参数!$B$10) -> 4200 | J30: 千川无视版 | K30: =(MAX(维护参数!$B$5,ROUNDUP(I29/10000,0)))*(维护参数!$B$3) -> 880 | Q30: =SUM(K30,P29) -> 1744 | R30: =Q30/H30 -> 0.4152381 | S30: =H30-Q30 -> 2456 | T30: =S30/(C29) -> 0.40933333 | U30: =S30*维护参数!$B$20 -> 1596.4 | V30: =U30/(C29) -> 0.26606667
A31: 葵仔不想肝 | B31: 刘登魁 | C31: 6250 | D31: =C31*0.6 -> 3750 | E31: 7000 | F31: =E31*0.6 -> 4200 | G31: 私单 | H31: =(D31)*(1) -> 3750 | I31: =ROUNDUP(C31*维护参数!$B$11/维护参数!$B$12*1000,0) -> 166667 | J31: 普通千川 | K31: =(MAX(维护参数!$B$4,ROUNDUP(I31/10000,0)))*(维护参数!$B$2) -> 357 | L31: =ROUNDUP(C31*维护参数!$B$16/维护参数!$B$15/1000,0)*1000 -> 13000 | M31: =ROUNDUP(C31*维护参数!$B$17/维护参数!$B$15/10,0)*10 -> 130 | N31: =ROUNDUP(C31*维护参数!$B$18/维护参数!$B$15/10,0)*10 -> 130 | O31: =ROUNDUP(C31*维护参数!$B$19/维护参数!$B$15/10,0)*10 -> 190 | P31: =L31/1000*维护参数!$B$6+M31*维护参数!$B$7+N31*维护参数!$B$8+O31*维护参数!$B$9 -> 935 | Q31: =SUM(K31,P31) -> 1292 | R31: =Q31/H31 -> 0.34453333 | S31: =H31-Q31 -> 2458 | T31: =S31/(C31) -> 0.39328 | U31: =S31*维护参数!$B$20 -> 1597.7 | V31: =U31/(C31) -> 0.255632 | X31: https://v.douyin.com/38Scd6JrG_s/
G32: 平台单 | H32: =(C31)*(维护参数!$B$10) -> 4375 | J32: 千川无视版 | K32: =(MAX(维护参数!$B$5,ROUNDUP(I31/10000,0)))*(维护参数!$B$3) -> 935 | Q32: =SUM(K32,P31) -> 1870 | R32: =Q32/H32 -> 0.42742857 | S32: =H32-Q32 -> 2505 | T32: =S32/(C31) -> 0.4008 | U32: =S32*维护参数!$B$20 -> 1628.25 | V32: =U32/(C31) -> 0.26052
A33: 游热娃子 | B33: 杨鸿霆 | C33: 8750 | D33: =C33*0.6 -> 5250 | E33: 10000 | F33: =E33*0.6 -> 6000 | G33: 私单 | H33: =(D33)*(1) -> 5250 | I33: =ROUNDUP(C33*维护参数!$B$11/维护参数!$B$12*1000,0) -> 233334 | J33: 普通千川 | K33: =(MAX(维护参数!$B$4,ROUNDUP(I33/10000,0)))*(维护参数!$B$2) -> 504 | L33: =ROUNDUP(C33*维护参数!$B$16/维护参数!$B$15/1000,0)*1000 -> 18000 | M33: =ROUNDUP(C33*维护参数!$B$17/维护参数!$B$15/10,0)*10 -> 180 | N33: =ROUNDUP(C33*维护参数!$B$18/维护参数!$B$15/10,0)*10 -> 180 | O33: =ROUNDUP(C33*维护参数!$B$19/维护参数!$B$15/10,0)*10 -> 270 | P33: =L33/1000*维护参数!$B$6+M33*维护参数!$B$7+N33*维护参数!$B$8+O33*维护参数!$B$9 -> 1296 | Q33: =SUM(K33,P33) -> 1800 | R33: =Q33/H33 -> 0.34285714 | S33: =H33-Q33 -> 3450 | T33: =S33/(C33) -> 0.39428571 | U33: =S33*维护参数!$B$20 -> 2242.5 | V33: =U33/(C33) -> 0.25628571 | W33: 数据好 | X33: https://v.douyin.com/JmcvjVd/
G34: 平台单 | H34: =(C33)*(维护参数!$B$10) -> 6125 | J34: 千川无视版 | K34: =(MAX(维护参数!$B$5,ROUNDUP(I33/10000,0)))*(维护参数!$B$3) -> 1320 | Q34: =SUM(K34,P33) -> 2616 | R34: =Q34/H34 -> 0.42710204 | S34: =H34-Q34 -> 3509 | T34: =S34/(C33) -> 0.40102857 | U34: =S34*维护参数!$B$20 -> 2280.85 | V34: =U34/(C33) -> 0.26066857
A35: 游小妹 | B35: 杨鸿霆 | C35: 6000 | D35: =C35*0.6 -> 3600 | E35: 8000 | F35: =E35*0.6 -> 4800 | G35: 私单 | H35: =(D35)*(1) -> 3600 | I35: =ROUNDUP(C35*维护参数!$B$11/维护参数!$B$12*1000,0) -> 160000 | J35: 普通千川 | K35: =(MAX(维护参数!$B$4,ROUNDUP(I35/10000,0)))*(维护参数!$B$2) -> 336 | L35: =ROUNDUP(C35*维护参数!$B$16/维护参数!$B$15/1000,0)*1000 -> 12000 | M35: =ROUNDUP(C35*维护参数!$B$17/维护参数!$B$15/10,0)*10 -> 120 | N35: =ROUNDUP(C35*维护参数!$B$18/维护参数!$B$15/10,0)*10 -> 120 | O35: =ROUNDUP(C35*维护参数!$B$19/维护参数!$B$15/10,0)*10 -> 180 | P35: =L35/1000*维护参数!$B$6+M35*维护参数!$B$7+N35*维护参数!$B$8+O35*维护参数!$B$9 -> 864 | Q35: =SUM(K35,P35) -> 1200 | R35: =Q35/H35 -> 0.33333333 | S35: =H35-Q35 -> 2400 | T35: =S35/(C35) -> 0.4 | U35: =S35*维护参数!$B$20 -> 1560 | V35: =U35/(C35) -> 0.26 | X35: https://v.douyin.com/JmcXQpY/
G36: 平台单 | H36: =(C35)*(维护参数!$B$10) -> 4200 | J36: 千川无视版 | K36: =(MAX(维护参数!$B$5,ROUNDUP(I35/10000,0)))*(维护参数!$B$3) -> 880 | Q36: =SUM(K36,P35) -> 1744 | R36: =Q36/H36 -> 0.4152381 | S36: =H36-Q36 -> 2456 | T36: =S36/(C35) -> 0.40933333 | U36: =S36*维护参数!$B$20 -> 1596.4 | V36: =U36/(C35) -> 0.26606667
A37: 灵梦小师妹 | B37: 林宇辰 | C37: 6000 | D37: =C37*0.6 -> 3600 | E37: / | F37: / | G37: 私单 | H37: =(D37)*(1) -> 3600 | I37: =ROUNDUP(C37*维护参数!$B$11/维护参数!$B$12*1000,0) -> 160000 | J37: 普通千川 | K37: =(MAX(维护参数!$B$4,ROUNDUP(I37/10000,0)))*(维护参数!$B$2) -> 336 | L37: =ROUNDUP(C37*维护参数!$B$16/维护参数!$B$15/1000,0)*1000 -> 12000 | M37: =ROUNDUP(C37*维护参数!$B$17/维护参数!$B$15/10,0)*10 -> 120 | N37: =ROUNDUP(C37*维护参数!$B$18/维护参数!$B$15/10,0)*10 -> 120 | O37: =ROUNDUP(C37*维护参数!$B$19/维护参数!$B$15/10,0)*10 -> 180 | P37: =L37/1000*维护参数!$B$6+M37*维护参数!$B$7+N37*维护参数!$B$8+O37*维护参数!$B$9 -> 864 | Q37: =SUM(K37,P37) -> 1200 | R37: =Q37/H37 -> 0.33333333 | S37: =H37-Q37 -> 2400 | T37: =S37/(C37) -> 0.4 | U37: =S37*维护参数!$B$20 -> 1560 | V37: =U37/(C37) -> 0.26 | W37: 王者 | X37: https://www.douyin.com/user/MS4wLjABAAAAJfqON1LDmWBPlUXvQ-iwZ6AZLbLuIj72uGiFUuot89k
G38: 平台单 | H38: =(C37)*(维护参数!$B$10) -> 4200 | J38: 千川无视版 | K38: =(MAX(维护参数!$B$5,ROUNDUP(I37/10000,0)))*(维护参数!$B$3) -> 880 | Q38: =SUM(K38,P37) -> 1744 | R38: =Q38/H38 -> 0.4152381 | S38: =H38-Q38 -> 2456 | T38: =S38/(C37) -> 0.40933333 | U38: =S38*维护参数!$B$20 -> 1596.4 | V38: =U38/(C37) -> 0.26606667
A39: 超玩教授 | B39: 商光涵 | C39: 6000 | D39: =C39*0.6 -> 3600 | E39: 8000 | F39: =E39*0.6 -> 4800 | G39: 私单 | H39: =(D39)*(1) -> 3600 | I39: =ROUNDUP(C39*维护参数!$B$11/维护参数!$B$12*1000,0) -> 160000 | J39: 普通千川 | K39: =(MAX(维护参数!$B$4,ROUNDUP(I39/10000,0)))*(维护参数!$B$2) -> 336 | L39: =ROUNDUP(C39*维护参数!$B$16/维护参数!$B$15/1000,0)*1000 -> 12000 | M39: =ROUNDUP(C39*维护参数!$B$17/维护参数!$B$15/10,0)*10 -> 120 | N39: =ROUNDUP(C39*维护参数!$B$18/维护参数!$B$15/10,0)*10 -> 120 | O39: =ROUNDUP(C39*维护参数!$B$19/维护参数!$B$15/10,0)*10 -> 180 | P39: =L39/1000*维护参数!$B$6+M39*维护参数!$B$7+N39*维护参数!$B$8+O39*维护参数!$B$9 -> 864 | Q39: =SUM(K39,P39) -> 1200 | R39: =Q39/H39 -> 0.33333333 | S39: =H39-Q39 -> 2400 | T39: =S39/(C39) -> 0.4 | U39: =S39*维护参数!$B$20 -> 1560 | V39: =U39/(C39) -> 0.26 | W39: 需改封面+隐藏 | X39: https://v.douyin.com/JJ3p572/
G40: 平台单 | H40: =(C39)*(维护参数!$B$10) -> 4200 | J40: 千川无视版 | K40: =(MAX(维护参数!$B$5,ROUNDUP(I39/10000,0)))*(维护参数!$B$3) -> 880 | Q40: =SUM(K40,P39) -> 1744 | R40: =Q40/H40 -> 0.4152381 | S40: =H40-Q40 -> 2456 | T40: =S40/(C39) -> 0.40933333 | U40: =S40*维护参数!$B$20 -> 1596.4 | V40: =U40/(C39) -> 0.26606667
A41: lee小强 | B41: 商光涵 | C41: 4800 | D41: =C41*0.6 -> 2880 | E41: 6000 | F41: =E41*0.6 -> 3600 | G41: 私单 | H41: =(D41)*(1) -> 2880 | I41: =ROUNDUP(C41*维护参数!$B$11/维护参数!$B$12*1000,0) -> 128000 | J41: 普通千川 | K41: =(MAX(维护参数!$B$4,ROUNDUP(I41/10000,0)))*(维护参数!$B$2) -> 273 | L41: =ROUNDUP(C41*维护参数!$B$16/维护参数!$B$15/1000,0)*1000 -> 10000 | M41: =ROUNDUP(C41*维护参数!$B$17/维护参数!$B$15/10,0)*10 -> 100 | N41: =ROUNDUP(C41*维护参数!$B$18/维护参数!$B$15/10,0)*10 -> 100 | O41: =ROUNDUP(C41*维护参数!$B$19/维护参数!$B$15/10,0)*10 -> 150 | P41: =L41/1000*维护参数!$B$6+M41*维护参数!$B$7+N41*维护参数!$B$8+O41*维护参数!$B$9 -> 720 | Q41: =SUM(K41,P41) -> 993 | R41: =Q41/H41 -> 0.34479167 | S41: =H41-Q41 -> 1887 | T41: =S41/(C41) -> 0.393125 | U41: =S41*维护参数!$B$20 -> 1226.55 | V41: =U41/(C41) -> 0.25553125 | X41: https://v.douyin.com/ihb6eF8j/
G42: 平台单 | H42: =(C41)*(维护参数!$B$10) -> 3360 | J42: 千川无视版 | K42: =(MAX(维护参数!$B$5,ROUNDUP(I41/10000,0)))*(维护参数!$B$3) -> 715 | Q42: =SUM(K42,P41) -> 1435 | R42: =Q42/H42 -> 0.42708333 | S42: =H42-Q42 -> 1925 | T42: =S42/(C41) -> 0.40104167 | U42: =S42*维护参数!$B$20 -> 1251.25 | V42: =U42/(C41) -> 0.26067708
A43: 不玩就分手 | B43: 刘登魁 | C43: 3500 | D43: =C43*0.6 -> 2100 | E43: 4500 | F43: =E43*0.6 -> 2700 | G43: 私单 | H43: =(D43)*(1) -> 2100 | I43: =ROUNDUP(C43*维护参数!$B$11/维护参数!$B$12*1000,0) -> 93334 | J43: 普通千川 | K43: =(MAX(维护参数!$B$4,ROUNDUP(I43/10000,0)))*(维护参数!$B$2) -> 210 | L43: =ROUNDUP(C43*维护参数!$B$16/维护参数!$B$15/1000,0)*1000 -> 7000 | M43: =ROUNDUP(C43*维护参数!$B$17/维护参数!$B$15/10,0)*10 -> 70 | N43: =ROUNDUP(C43*维护参数!$B$18/维护参数!$B$15/10,0)*10 -> 70 | O43: =ROUNDUP(C43*维护参数!$B$19/维护参数!$B$15/10,0)*10 -> 110 | P43: =L43/1000*维护参数!$B$6+M43*维护参数!$B$7+N43*维护参数!$B$8+O43*维护参数!$B$9 -> 505 | Q43: =SUM(K43,P43) -> 715 | R43: =Q43/H43 -> 0.34047619 | S43: =H43-Q43 -> 1385 | T43: =S43/(C43) -> 0.39571429 | U43: =S43*维护参数!$B$20 -> 900.25 | V43: =U43/(C43) -> 0.25721429 | W43: 王者 | X43: https://v.douyin.com/jTKED_9fV4A/
G44: 平台单 | H44: =(C43)*(维护参数!$B$10) -> 2450 | J44: 千川无视版 | K44: =(MAX(维护参数!$B$5,ROUNDUP(I43/10000,0)))*(维护参数!$B$3) -> 550 | Q44: =SUM(K44,P43) -> 1055 | R44: =Q44/H44 -> 0.43061224 | S44: =H44-Q44 -> 1395 | T44: =S44/(C43) -> 0.39857143 | U44: =S44*维护参数!$B$20 -> 906.75 | V44: =U44/(C43) -> 0.25907143
A45: 游梗要说 | B45: 罗晓棋 | C45: 7800 | D45: =C45*0.6 -> 4680 | E45: / | F45: / | G45: 私单 | H45: =(D45)*(1) -> 4680 | I45: =ROUNDUP(C45*维护参数!$B$11/维护参数!$B$12*1000,0) -> 208000 | J45: 普通千川 | K45: =(MAX(维护参数!$B$4,ROUNDUP(I45/10000,0)))*(维护参数!$B$2) -> 441 | L45: =ROUNDUP(C45*维护参数!$B$16/维护参数!$B$15/1000,0)*1000 -> 16000 | M45: =ROUNDUP(C45*维护参数!$B$17/维护参数!$B$15/10,0)*10 -> 160 | N45: =ROUNDUP(C45*维护参数!$B$18/维护参数!$B$15/10,0)*10 -> 160 | O45: =ROUNDUP(C45*维护参数!$B$19/维护参数!$B$15/10,0)*10 -> 240 | P45: =L45/1000*维护参数!$B$6+M45*维护参数!$B$7+N45*维护参数!$B$8+O45*维护参数!$B$9 -> 1152 | Q45: =SUM(K45,P45) -> 1593 | R45: =Q45/H45 -> 0.34038462 | S45: =H45-Q45 -> 3087 | T45: =S45/(C45) -> 0.39576923 | U45: =S45*维护参数!$B$20 -> 2006.55 | V45: =U45/(C45) -> 0.25725 | X45: https://www.douyin.com/user/MS4wLjABAAAAbRgpD5qO5M7mlI-ALMWDbsqjwiSeFC1WxNPKVgjsSCbFam1N0thGyVDw-PfRjICt
G46: 平台单 | H46: =(C45)*(维护参数!$B$10) -> 5460 | J46: 千川无视版 | K46: =(MAX(维护参数!$B$5,ROUNDUP(I45/10000,0)))*(维护参数!$B$3) -> 1155 | Q46: =SUM(K46,P45) -> 2307 | R46: =Q46/H46 -> 0.42252747 | S46: =H46-Q46 -> 3153 | T46: =S46/(C45) -> 0.40423077 | U46: =S46*维护参数!$B$20 -> 2049.45 | V46: =U46/(C45) -> 0.26275
A47: 中二探长 | B47: 陈泓睿 | C47: 3750 | D47: =C47*0.6 -> 2250 | E47: 5000 | F47: =E47*0.6 -> 3000 | G47: 私单 | H47: =(D47)*(1) -> 2250 | I47: =ROUNDUP(C47*维护参数!$B$11/维护参数!$B$12*1000,0) -> 100000 | J47: 普通千川 | K47: =(MAX(维护参数!$B$4,ROUNDUP(I47/10000,0)))*(维护参数!$B$2) -> 210 | L47: =ROUNDUP(C47*维护参数!$B$16/维护参数!$B$15/1000,0)*1000 -> 8000 | M47: =ROUNDUP(C47*维护参数!$B$17/维护参数!$B$15/10,0)*10 -> 80 | N47: =ROUNDUP(C47*维护参数!$B$18/维护参数!$B$15/10,0)*10 -> 80 | O47: =ROUNDUP(C47*维护参数!$B$19/维护参数!$B$15/10,0)*10 -> 120 | P47: =L47/1000*维护参数!$B$6+M47*维护参数!$B$7+N47*维护参数!$B$8+O47*维护参数!$B$9 -> 576 | Q47: =SUM(K47,P47) -> 786 | R47: =Q47/H47 -> 0.34933333 | S47: =H47-Q47 -> 1464 | T47: =S47/(C47) -> 0.3904 | U47: =S47*维护参数!$B$20 -> 951.6 | V47: =U47/(C47) -> 0.25376 | W47: 王者 | X47: https://v.douyin.com/mFA-j2xaAJY/
G48: 平台单 | H48: =(C47)*(维护参数!$B$10) -> 2625 | J48: 千川无视版 | K48: =(MAX(维护参数!$B$5,ROUNDUP(I47/10000,0)))*(维护参数!$B$3) -> 550 | Q48: =SUM(K48,P47) -> 1126 | R48: =Q48/H48 -> 0.42895238 | S48: =H48-Q48 -> 1499 | T48: =S48/(C47) -> 0.39973333 | U48: =S48*维护参数!$B$20 -> 974.35 | V48: =U48/(C47) -> 0.25982667
A49: 嘿小虎 | B49: 陈泓睿 | C49: 3000 | D49: =C49*0.6 -> 1800 | E49: 5000 | F49: =E49*0.6 -> 3000 | G49: 私单 | H49: =(D49)*(1) -> 1800 | I49: =ROUNDUP(C49*维护参数!$B$11/维护参数!$B$12*1000,0) -> 80000 | J49: 普通千川 | K49: =(MAX(维护参数!$B$4,ROUNDUP(I49/10000,0)))*(维护参数!$B$2) -> 210 | L49: =ROUNDUP(C49*维护参数!$B$16/维护参数!$B$15/1000,0)*1000 -> 6000 | M49: =ROUNDUP(C49*维护参数!$B$17/维护参数!$B$15/10,0)*10 -> 60 | N49: =ROUNDUP(C49*维护参数!$B$18/维护参数!$B$15/10,0)*10 -> 60 | O49: =ROUNDUP(C49*维护参数!$B$19/维护参数!$B$15/10,0)*10 -> 90 | P49: =L49/1000*维护参数!$B$6+M49*维护参数!$B$7+N49*维护参数!$B$8+O49*维护参数!$B$9 -> 432 | Q49: =SUM(K49,P49) -> 642 | R49: =Q49/H49 -> 0.35666667 | S49: =H49-Q49 -> 1158 | T49: =S49/(C49) -> 0.386 | U49: =S49*维护参数!$B$20 -> 752.7 | V49: =U49/(C49) -> 0.2509 | W49: 逆水寒-之前 需改封面+隐藏 | X49: https://v.douyin.com/lIhi6TchbPw/
G50: 平台单 | H50: =(C49)*(维护参数!$B$10) -> 2100 | J50: 千川无视版 | K50: =(MAX(维护参数!$B$5,ROUNDUP(I49/10000,0)))*(维护参数!$B$3) -> 440 | Q50: =SUM(K50,P49) -> 872 | R50: =Q50/H50 -> 0.4152381 | S50: =H50-Q50 -> 1228 | T50: =S50/(C49) -> 0.40933333 | U50: =S50*维护参数!$B$20 -> 798.2 | V50: =U50/(C49) -> 0.26606667
A51: 有事找学姐 | B51: 林宇辰 | C51: 7150 | D51: =C51*0.6 -> 4290 | E51: / | F51: / | G51: 私单 | H51: =(D51)*(1) -> 4290 | I51: =ROUNDUP(C51*维护参数!$B$11/维护参数!$B$12*1000,0) -> 190667 | J51: 普通千川 | K51: =(MAX(维护参数!$B$4,ROUNDUP(I51/10000,0)))*(维护参数!$B$2) -> 420 | L51: =ROUNDUP(C51*维护参数!$B$16/维护参数!$B$15/1000,0)*1000 -> 15000 | M51: =ROUNDUP(C51*维护参数!$B$17/维护参数!$B$15/10,0)*10 -> 150 | N51: =ROUNDUP(C51*维护参数!$B$18/维护参数!$B$15/10,0)*10 -> 150 | O51: =ROUNDUP(C51*维护参数!$B$19/维护参数!$B$15/10,0)*10 -> 220 | P51: =L51/1000*维护参数!$B$6+M51*维护参数!$B$7+N51*维护参数!$B$8+O51*维护参数!$B$9 -> 1079 | Q51: =SUM(K51,P51) -> 1499 | R51: =Q51/H51 -> 0.34941725 | S51: =H51-Q51 -> 2791 | T51: =S51/(C51) -> 0.39034965 | U51: =S51*维护参数!$B$20 -> 1814.15 | V51: =U51/(C51) -> 0.25372727 | W51: 王者 | X51: https://v.douyin.com/ettSTTldPIc/
...

Sheet 抖音小号维护标准
A1: 【内容事业部】抖音游戏类小号维护标准
A2: 私单按询单表私单价格，不额外折扣；平台单按各账号定制刊例报价×70% 播放目标沿用大号模板：定制基准×80%÷30×1000。按完整目标预留千川费用，不将星图中位数当成已实现播放扣减。
A9: 账号 | B9: 负责人 | C9: 备注 | D9: 定制 刊例价 | E9: 私单 报价 | F9: 涨价定制 刊例价 | G9: 涨价私单 报价 | H9: 订单 类型 | I9: 成交价 | J9: 目标播放量 （次） | K9: 千川版本 | L9: 千川 费用 | M9: 点赞 | N9: 评论 | O9: 收藏 | P9: 转发 | Q9: 互动 费用 | R9: 总维护 成本 | S9: 维护费 占成交价 | T9: 集团 毛利 | U9: 集团毛利率 （占折前报价） | V9: 部门 毛利 | W9: 部门毛利率 （占折前报价） | X9: 备注 | Y9: 主页链接
A10: 薛定谔的机 | B10: 薛荐轩 | D10: 10500 | E10: =D10*0.6 -> 6300 | F10: / | G10: / | H10: 私单 | I10: =(E10)*(1) -> 6300 | J10: =ROUNDUP(D10*维护参数!$B$11/维护参数!$B$12*1000,0) -> 280000 | K10: 普通千川 | L10: =(MAX(维护参数!$B$4,ROUNDUP(J10/10000,0)))*(维护参数!$B$2) -> 588 | M10: =ROUNDUP(D10*维护参数!$B$16/维护参数!$B$15/1000,0)*1000 -> 21000 | N10: =ROUNDUP(D10*维护参数!$B$17/维护参数!$B$15/10,0)*10 -> 210 | O10: =ROUNDUP(D10*维护参数!$B$18/维护参数!$B$15/10,0)*10 -> 210 | P10: =ROUNDUP(D10*维护参数!$B$19/维护参数!$B$15/10,0)*10 -> 320 | Q10: =M10/1000*维护参数!$B$6+N10*维护参数!$B$7+O10*维护参数!$B$8+P10*维护参数!$B$9 -> 1513 | R10: =SUM(L10,Q10) -> 2101 | S10: =R10/I10 -> 0.33349206 | T10: =I10-R10 -> 4199 | U10: =T10/(D10) -> 0.39990476 | V10: =T10*维护参数!$B$20 -> 2729.35 | W10: =V10/(D10) -> 0.2599381 | X10: 真人 | Y10: https://v.douyin.com/dcP3cOC30h4/
H11: 平台单 | I11: =(D10)*(维护参数!$B$10) -> 7350 | K11: 千川无视版 | L11: =(MAX(维护参数!$B$5,ROUNDUP(J10/10000,0)))*(维护参数!$B$3) -> 1540 | R11: =SUM(L11,Q10) -> 3053 | S11: =R11/I11 -> 0.41537415 | T11: =I11-R11 -> 4297 | U11: =T11/(D10) -> 0.4092381 | V11: =T11*维护参数!$B$20 -> 2793.05 | W11: =V11/(D10) -> 0.26600476
A12: 花满楼 | B12: 陈健伊 | D12: 11700 | E12: =D12*0.6 -> 7020 | F12: / | G12: / | H12: 私单 | I12: =(E12)*(1) -> 7020 | J12: =ROUNDUP(D12*维护参数!$B$11/维护参数!$B$12*1000,0) -> 312000 | K12: 普通千川 | L12: =(MAX(维护参数!$B$4,ROUNDUP(J12/10000,0)))*(维护参数!$B$2) -> 672 | M12: =ROUNDUP(D12*维护参数!$B$16/维护参数!$B$15/1000,0)*1000 -> 24000 | N12: =ROUNDUP(D12*维护参数!$B$17/维护参数!$B$15/10,0)*10 -> 240 | O12: =ROUNDUP(D12*维护参数!$B$18/维护参数!$B$15/10,0)*10 -> 240 | P12: =ROUNDUP(D12*维护参数!$B$19/维护参数!$B$15/10,0)*10 -> 360 | Q12: =M12/1000*维护参数!$B$6+N12*维护参数!$B$7+O12*维护参数!$B$8+P12*维护参数!$B$9 -> 1728 | R12: =SUM(L12,Q12) -> 2400 | S12: =R12/I12 -> 0.34188034 | T12: =I12-R12 -> 4620 | U12: =T12/(D12) -> 0.39487179 | V12: =T12*维护参数!$B$20 -> 3003 | W12: =V12/(D12) -> 0.25666667 | X12: 建议降价 | Y12: https://v.douyin.com/SAEJqgoPkrY/
H13: 平台单 | I13: =(D12)*(维护参数!$B$10) -> 8190 | K13: 千川无视版 | L13: =(MAX(维护参数!$B$5,ROUNDUP(J12/10000,0)))*(维护参数!$B$3) -> 1760 | R13: =SUM(L13,Q12) -> 3488 | S13: =R13/I13 -> 0.42588523 | T13: =I13-R13 -> 4702 | U13: =T13/(D12) -> 0.40188034 | V13: =T13*维护参数!$B$20 -> 3056.3 | W13: =V13/(D12) -> 0.26122222
A14: 麦小雯 | B14: 陈健伊 | D14: 6000 | E14: =D14*0.6 -> 3600 | F14: 9000 | G14: =F14*0.6 -> 5400 | H14: 私单 | I14: =(E14)*(1) -> 3600 | J14: =ROUNDUP(D14*维护参数!$B$11/维护参数!$B$12*1000,0) -> 160000 | K14: 普通千川 | L14: =(MAX(维护参数!$B$4,ROUNDUP(J14/10000,0)))*(维护参数!$B$2) -> 336 | M14: =ROUNDUP(D14*维护参数!$B$16/维护参数!$B$15/1000,0)*1000 -> 12000 | N14: =ROUNDUP(D14*维护参数!$B$17/维护参数!$B$15/10,0)*10 -> 120 | O14: =ROUNDUP(D14*维护参数!$B$18/维护参数!$B$15/10,0)*10 -> 120 | P14: =ROUNDUP(D14*维护参数!$B$19/维护参数!$B$15/10,0)*10 -> 180 | Q14: =M14/1000*维护参数!$B$6+N14*维护参数!$B$7+O14*维护参数!$B$8+P14*维护参数!$B$9 -> 864 | R14: =SUM(L14,Q14) -> 1200 | S14: =R14/I14 -> 0.33333333 | T14: =I14-R14 -> 2400 | U14: =T14/(D14) -> 0.4 | V14: =T14*维护参数!$B$20 -> 1560 | W14: =V14/(D14) -> 0.26 | Y14: https://v.douyin.com/DcH2brXPgvc/
H15: 平台单 | I15: =(D14)*(维护参数!$B$10) -> 4200 | K15: 千川无视版 | L15: =(MAX(维护参数!$B$5,ROUNDUP(J14/10000,0)))*(维护参数!$B$3) -> 880 | R15: =SUM(L15,Q14) -> 1744 | S15: =R15/I15 -> 0.4152381 | T15: =I15-R15 -> 2456 | U15: =T15/(D14) -> 0.40933333 | V15: =T15*维护参数!$B$20 -> 1596.4 | W15: =V15/(D14) -> 0.26606667
A16: 葵仔不想肝 | B16: 刘登魁 | D16: 6250 | E16: =D16*0.6 -> 3750 | F16: 7000 | G16: =F16*0.6 -> 4200 | H16: 私单 | I16: =(E16)*(1) -> 3750 | J16: =ROUNDUP(D16*维护参数!$B$11/维护参数!$B$12*1000,0) -> 166667 | K16: 普通千川 | L16: =(MAX(维护参数!$B$4,ROUNDUP(J16/10000,0)))*(维护参数!$B$2) -> 357 | M16: =ROUNDUP(D16*维护参数!$B$16/维护参数!$B$15/1000,0)*1000 -> 13000 | N16: =ROUNDUP(D16*维护参数!$B$17/维护参数!$B$15/10,0)*10 -> 130 | O16: =ROUNDUP(D16*维护参数!$B$18/维护参数!$B$15/10,0)*10 -> 130 | P16: =ROUNDUP(D16*维护参数!$B$19/维护参数!$B$15/10,0)*10 -> 190 | Q16: =M16/1000*维护参数!$B$6+N16*维护参数!$B$7+O16*维护参数!$B$8+P16*维护参数!$B$9 -> 935 | R16: =SUM(L16,Q16) -> 1292 | S16: =R16/I16 -> 0.34453333 | T16: =I16-R16 -> 2458 | U16: =T16/(D16) -> 0.39328 | V16: =T16*维护参数!$B$20 -> 1597.7 | W16: =V16/(D16) -> 0.255632 | Y16: https://v.douyin.com/38Scd6JrG_s/
H17: 平台单 | I17: =(D16)*(维护参数!$B$10) -> 4375 | K17: 千川无视版 | L17: =(MAX(维护参数!$B$5,ROUNDUP(J16/10000,0)))*(维护参数!$B$3) -> 935 | R17: =SUM(L17,Q16) -> 1870 | S17: =R17/I17 -> 0.42742857 | T17: =I17-R17 -> 2505 | U17: =T17/(D16) -> 0.4008 | V17: =T17*维护参数!$B$20 -> 1628.25 | W17: =V17/(D16) -> 0.26052
A18: 游热娃子 | B18: 杨鸿霆 | D18: 8750 | E18: =D18*0.6 -> 5250 | F18: 10000 | G18: =F18*0.6 -> 6000 | H18: 私单 | I18: =(E18)*(1) -> 5250 | J18: =ROUNDUP(D18*维护参数!$B$11/维护参数!$B$12*1000,0) -> 233334 | K18: 普通千川 | L18: =(MAX(维护参数!$B$4,ROUNDUP(J18/10000,0)))*(维护参数!$B$2) -> 504 | M18: =ROUNDUP(D18*维护参数!$B$16/维护参数!$B$15/1000,0)*1000 -> 18000 | N18: =ROUNDUP(D18*维护参数!$B$17/维护参数!$B$15/10,0)*10 -> 180 | O18: =ROUNDUP(D18*维护参数!$B$18/维护参数!$B$15/10,0)*10 -> 180 | P18: =ROUNDUP(D18*维护参数!$B$19/维护参数!$B$15/10,0)*10 -> 270 | Q18: =M18/1000*维护参数!$B$6+N18*维护参数!$B$7+O18*维护参数!$B$8+P18*维护参数!$B$9 -> 1296 | R18: =SUM(L18,Q18) -> 1800 | S18: =R18/I18 -> 0.34285714 | T18: =I18-R18 -> 3450 | U18: =T18/(D18) -> 0.39428571 | V18: =T18*维护参数!$B$20 -> 2242.5 | W18: =V18/(D18) -> 0.25628571 | X18: 数据好 | Y18: https://v.douyin.com/JmcvjVd/
H19: 平台单 | I19: =(D18)*(维护参数!$B$10) -> 6125 | K19: 千川无视版 | L19: =(MAX(维护参数!$B$5,ROUNDUP(J18/10000,0)))*(维护参数!$B$3) -> 1320 | R19: =SUM(L19,Q18) -> 2616 | S19: =R19/I19 -> 0.42710204 | T19: =I19-R19 -> 3509 | U19: =T19/(D18) -> 0.40102857 | V19: =T19*维护参数!$B$20 -> 2280.85 | W19: =V19/(D18) -> 0.26066857
A20: 游小妹 | B20: 杨鸿霆 | D20: 6000 | E20: =D20*0.6 -> 3600 | F20: 8000 | G20: =F20*0.6 -> 4800 | H20: 私单 | I20: =(E20)*(1) -> 3600 | J20: =ROUNDUP(D20*维护参数!$B$11/维护参数!$B$12*1000,0) -> 160000 | K20: 普通千川 | L20: =(MAX(维护参数!$B$4,ROUNDUP(J20/10000,0)))*(维护参数!$B$2) -> 336 | M20: =ROUNDUP(D20*维护参数!$B$16/维护参数!$B$15/1000,0)*1000 -> 12000 | N20: =ROUNDUP(D20*维护参数!$B$17/维护参数!$B$15/10,0)*10 -> 120 | O20: =ROUNDUP(D20*维护参数!$B$18/维护参数!$B$15/10,0)*10 -> 120 | P20: =ROUNDUP(D20*维护参数!$B$19/维护参数!$B$15/10,0)*10 -> 180 | Q20: =M20/1000*维护参数!$B$6+N20*维护参数!$B$7+O20*维护参数!$B$8+P20*维护参数!$B$9 -> 864 | R20: =SUM(L20,Q20) -> 1200 | S20: =R20/I20 -> 0.33333333 | T20: =I20-R20 -> 2400 | U20: =T20/(D20) -> 0.4 | V20: =T20*维护参数!$B$20 -> 1560 | W20: =V20/(D20) -> 0.26 | Y20: https://v.douyin.com/JmcXQpY/
H21: 平台单 | I21: =(D20)*(维护参数!$B$10) -> 4200 | K21: 千川无视版 | L21: =(MAX(维护参数!$B$5,ROUNDUP(J20/10000,0)))*(维护参数!$B$3) -> 880 | R21: =SUM(L21,Q20) -> 1744 | S21: =R21/I21 -> 0.4152381 | T21: =I21-R21 -> 2456 | U21: =T21/(D20) -> 0.40933333 | V21: =T21*维护参数!$B$20 -> 1596.4 | W21: =V21/(D20) -> 0.26606667
A22: 灵梦小师妹 | B22: 林宇辰 | C22: 王者 | D22: 6000 | E22: =D22*0.6 -> 3600 | F22: / | G22: / | H22: 私单 | I22: =(E22)*(1) -> 3600 | J22: =ROUNDUP(D22*维护参数!$B$11/维护参数!$B$12*1000,0) -> 160000 | K22: 普通千川 | L22: =(MAX(维护参数!$B$4,ROUNDUP(J22/10000,0)))*(维护参数!$B$2) -> 336 | M22: =ROUNDUP(D22*维护参数!$B$16/维护参数!$B$15/1000,0)*1000 -> 12000 | N22: =ROUNDUP(D22*维护参数!$B$17/维护参数!$B$15/10,0)*10 -> 120 | O22: =ROUNDUP(D22*维护参数!$B$18/维护参数!$B$15/10,0)*10 -> 120 | P22: =ROUNDUP(D22*维护参数!$B$19/维护参数!$B$15/10,0)*10 -> 180 | Q22: =M22/1000*维护参数!$B$6+N22*维护参数!$B$7+O22*维护参数!$B$8+P22*维护参数!$B$9 -> 864 | R22: =SUM(L22,Q22) -> 1200 | S22: =R22/I22 -> 0.33333333 | T22: =I22-R22 -> 2400 | U22: =T22/(D22) -> 0.4 | V22: =T22*维护参数!$B$20 -> 1560 | W22: =V22/(D22) -> 0.26 | X22: 王者 | Y22: https://www.douyin.com/user/MS4wLjABAAAAJfqON1LDmWBPlUXvQ-iwZ6AZLbLuIj72uGiFUuot89k
H23: 平台单 | I23: =(D22)*(维护参数!$B$10) -> 4200 | K23: 千川无视版 | L23: =(MAX(维护参数!$B$5,ROUNDUP(J22/10000,0)))*(维护参数!$B$3) -> 880 | R23: =SUM(L23,Q22) -> 1744 | S23: =R23/I23 -> 0.4152381 | T23: =I23-R23 -> 2456 | U23: =T23/(D22) -> 0.40933333 | V23: =T23*维护参数!$B$20 -> 1596.4 | W23: =V23/(D22) -> 0.26606667
A24: 超玩教授 | B24: 商光涵 | C24: 封面+隐藏 | D24: 6000 | E24: =D24*0.6 -> 3600 | F24: 8000 | G24: =F24*0.6 -> 4800 | H24: 私单 | I24: =(E24)*(1) -> 3600 | J24: =ROUNDUP(D24*维护参数!$B$11/维护参数!$B$12*1000,0) -> 160000 | K24: 普通千川 | L24: =(MAX(维护参数!$B$4,ROUNDUP(J24/10000,0)))*(维护参数!$B$2) -> 336 | M24: =ROUNDUP(D24*维护参数!$B$16/维护参数!$B$15/1000,0)*1000 -> 12000 | N24: =ROUNDUP(D24*维护参数!$B$17/维护参数!$B$15/10,0)*10 -> 120 | O24: =ROUNDUP(D24*维护参数!$B$18/维护参数!$B$15/10,0)*10 -> 120 | P24: =ROUNDUP(D24*维护参数!$B$19/维护参数!$B$15/10,0)*10 -> 180 | Q24: =M24/1000*维护参数!$B$6+N24*维护参数!$B$7+O24*维护参数!$B$8+P24*维护参数!$B$9 -> 864 | R24: =SUM(L24,Q24) -> 1200 | S24: =R24/I24 -> 0.33333333 | T24: =I24-R24 -> 2400 | U24: =T24/(D24) -> 0.4 | V24: =T24*维护参数!$B$20 -> 1560 | W24: =V24/(D24) -> 0.26 | X24: 需改封面+隐藏 | Y24: https://v.douyin.com/JJ3p572/
H25: 平台单 | I25: =(D24)*(维护参数!$B$10) -> 4200 | K25: 千川无视版 | L25: =(MAX(维护参数!$B$5,ROUNDUP(J24/10000,0)))*(维护参数!$B$3) -> 880 | R25: =SUM(L25,Q24) -> 1744 | S25: =R25/I25 -> 0.4152381 | T25: =I25-R25 -> 2456 | U25: =T25/(D24) -> 0.40933333 | V25: =T25*维护参数!$B$20 -> 1596.4 | W25: =V25/(D24) -> 0.26606667
A26: lee小强 | B26: 商光涵 | D26: 4800 | E26: =D26*0.6 -> 2880 | F26: 6000 | G26: =F26*0.6 -> 3600 | H26: 私单 | I26: =(E26)*(1) -> 2880 | J26: =ROUNDUP(D26*维护参数!$B$11/维护参数!$B$12*1000,0) -> 128000 | K26: 普通千川 | L26: =(MAX(维护参数!$B$4,ROUNDUP(J26/10000,0)))*(维护参数!$B$2) -> 273 | M26: =ROUNDUP(D26*维护参数!$B$16/维护参数!$B$15/1000,0)*1000 -> 10000 | N26: =ROUNDUP(D26*维护参数!$B$17/维护参数!$B$15/10,0)*10 -> 100 | O26: =ROUNDUP(D26*维护参数!$B$18/维护参数!$B$15/10,0)*10 -> 100 | P26: =ROUNDUP(D26*维护参数!$B$19/维护参数!$B$15/10,0)*10 -> 150 | Q26: =M26/1000*维护参数!$B$6+N26*维护参数!$B$7+O26*维护参数!$B$8+P26*维护参数!$B$9 -> 720 | R26: =SUM(L26,Q26) -> 993 | S26: =R26/I26 -> 0.34479167 | T26: =I26-R26 -> 1887 | U26: =T26/(D26) -> 0.393125 | V26: =T26*维护参数!$B$20 -> 1226.55 | W26: =V26/(D26) -> 0.25553125 | Y26: https://v.douyin.com/ihb6eF8j/
H27: 平台单 | I27: =(D26)*(维护参数!$B$10) -> 3360 | K27: 千川无视版 | L27: =(MAX(维护参数!$B$5,ROUNDUP(J26/10000,0)))*(维护参数!$B$3) -> 715 | R27: =SUM(L27,Q26) -> 1435 | S27: =R27/I27 -> 0.42708333 | T27: =I27-R27 -> 1925 | U27: =T27/(D26) -> 0.40104167 | V27: =T27*维护参数!$B$20 -> 1251.25 | W27: =V27/(D26) -> 0.26067708
A28: 不玩就分手 | B28: 刘登魁 | C28: 王者 | D28: 3500 | E28: =D28*0.6 -> 2100 | F28: 4500 | G28: =F28*0.6 -> 2700 | H28: 私单 | I28: =(E28)*(1) -> 2100 | J28: =ROUNDUP(D28*维护参数!$B$11/维护参数!$B$12*1000,0) -> 93334 | K28: 普通千川 | L28: =(MAX(维护参数!$B$4,ROUNDUP(J28/10000,0)))*(维护参数!$B$2) -> 210 | M28: =ROUNDUP(D28*维护参数!$B$16/维护参数!$B$15/1000,0)*1000 -> 7000 | N28: =ROUNDUP(D28*维护参数!$B$17/维护参数!$B$15/10,0)*10 -> 70 | O28: =ROUNDUP(D28*维护参数!$B$18/维护参数!$B$15/10,0)*10 -> 70 | P28: =ROUNDUP(D28*维护参数!$B$19/维护参数!$B$15/10,0)*10 -> 110 | Q28: =M28/1000*维护参数!$B$6+N28*维护参数!$B$7+O28*维护参数!$B$8+P28*维护参数!$B$9 -> 505 | R28: =SUM(L28,Q28) -> 715 | S28: =R28/I28 -> 0.34047619 | T28: =I28-R28 -> 1385 | U28: =T28/(D28) -> 0.39571429 | V28: =T28*维护参数!$B$20 -> 900.25 | W28: =V28/(D28) -> 0.25721429 | X28: 王者 | Y28: https://v.douyin.com/jTKED_9fV4A/
H29: 平台单 | I29: =(D28)*(维护参数!$B$10) -> 2450 | K29: 千川无视版 | L29: =(MAX(维护参数!$B$5,ROUNDUP(J28/10000,0)))*(维护参数!$B$3) -> 550 | R29: =SUM(L29,Q28) -> 1055 | S29: =R29/I29 -> 0.43061224 | T29: =I29-R29 -> 1395 | U29: =T29/(D28) -> 0.39857143 | V29: =T29*维护参数!$B$20 -> 906.75 | W29: =V29/(D28) -> 0.25907143
A30: 游梗要说 | B30: 罗晓棋 | D30: 7800 | E30: =D30*0.6 -> 4680 | F30: / | G30: / | H30: 私单 | I30: =(E30)*(1) -> 4680 | J30: =ROUNDUP(D30*维护参数!$B$11/维护参数!$B$12*1000,0) -> 208000 | K30: 普通千川 | L30: =(MAX(维护参数!$B$4,ROUNDUP(J30/10000,0)))*(维护参数!$B$2) -> 441 | M30: =ROUNDUP(D30*维护参数!$B$16/维护参数!$B$15/1000,0)*1000 -> 16000 | N30: =ROUNDUP(D30*维护参数!$B$17/维护参数!$B$15/10,0)*10 -> 160 | O30: =ROUNDUP(D30*维护参数!$B$18/维护参数!$B$15/10,0)*10 -> 160 | P30: =ROUNDUP(D30*维护参数!$B$19/维护参数!$B$15/10,0)*10 -> 240 | Q30: =M30/1000*维护参数!$B$6+N30*维护参数!$B$7+O30*维护参数!$B$8+P30*维护参数!$B$9 -> 1152 | R30: =SUM(L30,Q30) -> 1593 | S30: =R30/I30 -> 0.34038462 | T30: =I30-R30 -> 3087 | U30: =T30/(D30) -> 0.39576923 | V30: =T30*维护参数!$B$20 -> 2006.55 | W30: =V30/(D30) -> 0.25725 | Y30: https://www.douyin.com/user/MS4wLjABAAAAbRgpD5qO5M7mlI-ALMWDbsqjwiSeFC1WxNPKVgjsSCbFam1N0thGyVDw-PfRjICt
H31: 平台单 | I31: =(D30)*(维护参数!$B$10) -> 5460 | K31: 千川无视版 | L31: =(MAX(维护参数!$B$5,ROUNDUP(J30/10000,0)))*(维护参数!$B$3) -> 1155 | R31: =SUM(L31,Q30) -> 2307 | S31: =R31/I31 -> 0.42252747 | T31: =I31-R31 -> 3153 | U31: =T31/(D30) -> 0.40423077 | V31: =T31*维护参数!$B$20 -> 2049.45 | W31: =V31/(D30) -> 0.26275
A32: 中二探长 | B32: 陈泓睿 | C32: 王者 | D32: 3750 | E32: =D32*0.6 -> 2250 | F32: 5000 | G32: =F32*0.6 -> 3000 | H32: 私单 | I32: =(E32)*(1) -> 2250 | J32: =ROUNDUP(D32*维护参数!$B$11/维护参数!$B$12*1000,0) -> 100000 | K32: 普通千川 | L32: =(MAX(维护参数!$B$4,ROUNDUP(J32/10000,0)))*(维护参数!$B$2) -> 210 | M32: =ROUNDUP(D32*维护参数!$B$16/维护参数!$B$15/1000,0)*1000 -> 8000 | N32: =ROUNDUP(D32*维护参数!$B$17/维护参数!$B$15/10,0)*10 -> 80 | O32: =ROUNDUP(D32*维护参数!$B$18/维护参数!$B$15/10,0)*10 -> 80 | P32: =ROUNDUP(D32*维护参数!$B$19/维护参数!$B$15/10,0)*10 -> 120 | Q32: =M32/1000*维护参数!$B$6+N32*维护参数!$B$7+O32*维护参数!$B$8+P32*维护参数!$B$9 -> 576 | R32: =SUM(L32,Q32) -> 786 | S32: =R32/I32 -> 0.34933333 | T32: =I32-R32 -> 1464 | U32: =T32/(D32) -> 0.3904 | V32: =T32*维护参数!$B$20 -> 951.6 | W32: =V32/(D32) -> 0.25376 | X32: 王者 | Y32: https://v.douyin.com/mFA-j2xaAJY/
H33: 平台单 | I33: =(D32)*(维护参数!$B$10) -> 2625 | K33: 千川无视版 | L33: =(MAX(维护参数!$B$5,ROUNDUP(J32/10000,0)))*(维护参数!$B$3) -> 550 | R33: =SUM(L33,Q32) -> 1126 | S33: =R33/I33 -> 0.42895238 | T33: =I33-R33 -> 1499 | U33: =T33/(D32) -> 0.39973333 | V33: =T33*维护参数!$B$20 -> 974.35 | W33: =V33/(D32) -> 0.25982667
A34: 嘿小虎 | B34: 陈泓睿 | C34: 逆水寒-之前 | D34: 3000 | E34: =D34*0.6 -> 1800 | F34: 5000 | G34: =F34*0.6 -> 3000 | H34: 私单 | I34: =(E34)*(1) -> 1800 | J34: =ROUNDUP(D34*维护参数!$B$11/维护参数!$B$12*1000,0) -> 80000 | K34: 普通千川 | L34: =(MAX(维护参数!$B$4,ROUNDUP(J34/10000,0)))*(维护参数!$B$2) -> 210 | M34: =ROUNDUP(D34*维护参数!$B$16/维护参数!$B$15/1000,0)*1000 -> 6000 | N34: =ROUNDUP(D34*维护参数!$B$17/维护参数!$B$15/10,0)*10 -> 60 | O34: =ROUNDUP(D34*维护参数!$B$18/维护参数!$B$15/10,0)*10 -> 60 | P34: =ROUNDUP(D34*维护参数!$B$19/维护参数!$B$15/10,0)*10 -> 90 | Q34: =M34/1000*维护参数!$B$6+N34*维护参数!$B$7+O34*维护参数!$B$8+P34*维护参数!$B$9 -> 432 | R34: =SUM(L34,Q34) -> 642 | S34: =R34/I34 -> 0.35666667 | T34: =I34-R34 -> 1158 | U34: =T34/(D34) -> 0.386 | V34: =T34*维护参数!$B$20 -> 752.7 | W34: =V34/(D34) -> 0.2509 | X34: 逆水寒-之前 需改封面+隐藏 | Y34: https://v.douyin.com/lIhi6TchbPw/
H35: 平台单 | I35: =(D34)*(维护参数!$B$10) -> 2100 | K35: 千川无视版 | L35: =(MAX(维护参数!$B$5,ROUNDUP(J34/10000,0)))*(维护参数!$B$3) -> 440 | R35: =SUM(L35,Q34) -> 872 | S35: =R35/I35 -> 0.4152381 | T35: =I35-R35 -> 1228 | U35: =T35/(D34) -> 0.40933333 | V35: =T35*维护参数!$B$20 -> 798.2 | W35: =V35/(D34) -> 0.26606667
A36: 有事找学姐 | B36: 林宇辰 | C36: 王者 | D36: 7150 | E36: =D36*0.6 -> 4290 | F36: / | G36: / | H36: 私单 | I36: =(E36)*(1) -> 4290 | J36: =ROUNDUP(D36*维护参数!$B$11/维护参数!$B$12*1000,0) -> 190667 | K36: 普通千川 | L36: =(MAX(维护参数!$B$4,ROUNDUP(J36/10000,0)))*(维护参数!$B$2) -> 420 | M36: =ROUNDUP(D36*维护参数!$B$16/维护参数!$B$15/1000,0)*1000 -> 15000 | N36: =ROUNDUP(D36*维护参数!$B$17/维护参数!$B$15/10,0)*10 -> 150 | O36: =ROUNDUP(D36*维护参数!$B$18/维护参数!$B$15/10,0)*10 -> 150 | P36: =ROUNDUP(D36*维护参数!$B$19/维护参数!$B$15/10,0)*10 -> 220 | Q36: =M36/1000*维护参数!$B$6+N36*维护参数!$B$7+O36*维护参数!$B$8+P36*维护参数!$B$9 -> 1079 | R36: =SUM(L36,Q36) -> 1499 | S36: =R36/I36 -> 0.34941725 | T36: =I36-R36 -> 2791 | U36: =T36/(D36) -> 0.39034965 | V36: =T36*维护参数!$B$20 -> 1814.15 | W36: =V36/(D36) -> 0.25372727 | X36: 王者 | Y36: https://v.douyin.com/ettSTTldPIc/
H37: 平台单 | I37: =(D36)*(维护参数!$B$10) -> 5005 | K37: 千川无视版 | L37: =(MAX(维护参数!$B$5,ROUNDUP(J36/10000,0)))*(维护参数!$B$3) -> 1100 | R37: =SUM(L37,Q36) -> 2179 | S37: =R37/I37 -> 0.43536464 | T37: =I37-R37 -> 2826 | U37: =T37/(D36) -> 0.39524476 | V37: =T37*维护参数!$B$20 -> 1836.9 | W37: =V37/(D36) -> 0.25690909
A38: 跑腿的包子 | B38: 陈泓睿 | D38: 7000 | E38: =D38*0.6 -> 4200 | F38: / | G38: / | H38: 私单 | I38: =(E38)*(1) -> 4200 | J38: =ROUNDUP(D38*维护参数!$B$11/维护参数!$B$12*1000,0) -> 186667 | K38: 普通千川 | L38: =(MAX(维护参数!$B$4,ROUNDUP(J38/10000,0)))*(维护参数!$B$2) -> 399 | M38: =ROUNDUP(D38*维护参数!$B$16/维护参数!$B$15/1000,0)*1000 -> 14000 | N38: =ROUNDUP(D38*维护参数!$B$17/维护参数!$B$15/10,0)*10 -> 140 | O38: =ROUNDUP(D38*维护参数!$B$18/维护参数!$B$15/10,0)*10 -> 140 | P38: =ROUNDUP(D38*维护参数!$B$19/维护参数!$B$15/10,0)*10 -> 210 | Q38: =M38/1000*维护参数!$B$6+N38*维护参数!$B$7+O38*维护参数!$B$8+P38*维护参数!$B$9 -> 1008 | R38: =SUM(L38,Q38) -> 1407 | S38: =R38/I38 -> 0.335 | T38: =I38-R38 -> 2793 | U38: =T38/(D38) -> 0.399 | V38: =T38*维护参数!$B$20 -> 1815.45 | W38: =V38/(D38) -> 0.25935 | X38: 分发-精选激励 | Y38: https://v.douyin.com/Vva749Cn4Fk/
H39: 平台单 | I39: =(D38)*(维护参数!$B$10) -> 4900 | K39: 千川无视版 | L39: =(MAX(维护参数!$B$5,ROUNDUP(J38/10000,0)))*(维护参数!$B$3) -> 1045 | R39: =SUM(L39,Q38) -> 2053 | S39: =R39/I39 -> 0.41897959 | T39: =I39-R39 -> 2847 | U39: =T39/(D38) -> 0.40671429 | V39: =T39*维护参数!$B$20 -> 1850.55 | W39: =V39/(D38) -> 0.26436429
A40: 皮皮说游戏 | B40: 陈泓睿 | C40: 星广 | D40: 5500 | E40: =D40*0.6 -> 3300 | F40: / | G40: / | H40: 私单 | I40: =(E40)*(1) -> 3300 | J40: =ROUNDUP(D40*维护参数!$B$11/维护参数!$B$12*1000,0) -> 146667 | K40: 普通千川 | L40: =(MAX(维护参数!$B$4,ROUNDUP(J40/10000,0)))*(维护参数!$B$2) -> 315 | M40: =ROUNDUP(D40*维护参数!$B$16/维护参数!$B$15/1000,0)*1000 -> 11000 | N40: =ROUNDUP(D40*维护参数!$B$17/维护参数!$B$15/10,0)*10 -> 110 | O40: =ROUNDUP(D40*维护参数!$B$18/维护参数!$B$15/10,0)*10 -> 110 | P40: =ROUNDUP(D40*维护参数!$B$19/维护参数!$B$15/10,0)*10 -> 170 | Q40: =M40/1000*维护参数!$B$6+N40*维护参数!$B$7+O40*维护参数!$B$8+P40*维护参数!$B$9 -> 793 | R40: =SUM(L40,Q40) -> 1108 | S40: =R40/I40 -> 0.33575758 | T40: =I40-R40 -> 2192 | U40: =T40/(D40) -> 0.39854545 | V40: =T40*维护参数!$B$20 -> 1424.8 | W40: =V40/(D40) -> 0.25905455 | X40: 星广 | Y40: https://v.douyin.com/iSUabqnS/
H41: 平台单 | I41: =(D40)*(维护参数!$B$10) -> 3850 | K41: 千川无视版 | L41: =(MAX(维护参数!$B$5,ROUNDUP(J40/10000,0)))*(维护参数!$B$3) -> 825 | R41: =SUM(L41,Q40) -> 1618 | S41: =R41/I41 -> 0.42025974 | T41: =I41-R41 -> 2232 | U41: =T41/(D40) -> 0.40581818 | V41: =T41*维护参数!$B$20 -> 1450.8 | W41: =V41/(D40) -> 0.26378182
A42: 夏洛 | B42: 刘登魁 | C42: 星广 | D42: 5000 | E42: =D42*0.6 -> 3000 | F42: / | G42: / | H42: 私单 | I42: =(E42)*(1) -> 3000 | J42: =ROUNDUP(D42*维护参数!$B$11/维护参数!$B$12*1000,0) -> 133334 | K42: 普通千川 | L42: =(MAX(维护参数!$B$4,ROUNDUP(J42/10000,0)))*(维护参数!$B$2) -> 294 | M42: =ROUNDUP(D42*维护参数!$B$16/维护参数!$B$15/1000,0)*1000 -> 10000 | N42: =ROUNDUP(D42*维护参数!$B$17/维护参数!$B$15/10,0)*10 -> 100 | O42: =ROUNDUP(D42*维护参数!$B$18/维护参数!$B$15/10,0)*10 -> 100 | P42: =ROUNDUP(D42*维护参数!$B$19/维护参数!$B$15/10,0)*10 -> 150 | Q42: =M42/1000*维护参数!$B$6+N42*维护参数!$B$7+O42*维护参数!$B$8+P42*维护参数!$B$9 -> 720 | R42: =SUM(L42,Q42) -> 1014 | S42: =R42/I42 -> 0.338 | T42: =I42-R42 -> 1986 | U42: =T42/(D42) -> 0.3972 | V42: =T42*维护参数!$B$20 -> 1290.9 | W42: =V42/(D42) -> 0.25818 | X42: 星广 | Y42: https://v.douyin.com/wq_9XvcbfS0/
H43: 平台单 | I43: =(D42)*(维护参数!$B$10) -> 3500 | K43: 千川无视版 | L43: =(MAX(维护参数!$B$5,ROUNDUP(J42/10000,0)))*(维护参数!$B$3) -> 770 | R43: =SUM(L43,Q42) -> 1490 | S43: =R43/I43 -> 0.42571429 | T43: =I43-R43 -> 2010 | U43: =T43/(D42) -> 0.402 | V43: =T43*维护参数!$B$20 -> 1306.5 | W43: =V43/(D42) -> 0.2613
A44: 畅玩百晓生 | B44: 刘登魁 | C44: 星广 | D44: 5000 | E44: =D44*0.6 -> 3000 | F44: / | G44: / | H44: 私单 | I44: =(E44)*(1) -> 3000 | J44: =ROUNDUP(D44*维护参数!$B$11/维护参数!$B$12*1000,0) -> 133334 | K44: 普通千川 | L44: =(MAX(维护参数!$B$4,ROUNDUP(J44/10000,0)))*(维护参数!$B$2) -> 294 | M44: =ROUNDUP(D44*维护参数!$B$16/维护参数!$B$15/1000,0)*1000 -> 10000 | N44: =ROUNDUP(D44*维护参数!$B$17/维护参数!$B$15/10,0)*10 -> 100 | O44: =ROUNDUP(D44*维护参数!$B$18/维护参数!$B$15/10,0)*10 -> 100 | P44: =ROUNDUP(D44*维护参数!$B$19/维护参数!$B$15/10,0)*10 -> 150 | Q44: =M44/1000*维护参数!$B$6+N44*维护参数!$B$7+O44*维护参数!$B$8+P44*维护参数!$B$9 -> 720 | R44: =SUM(L44,Q44) -> 1014 | S44: =R44/I44 -> 0.338 | T44: =I44-R44 -> 1986 | U44: =T44/(D44) -> 0.3972 | V44: =T44*维护参数!$B$20 -> 1290.9 | W44: =V44/(D44) -> 0.25818 | X44: 星广 | Y44: https://v.douyin.com/jTTVNutNIRQ/
H45: 平台单 | I45: =(D44)*(维护参数!$B$10) -> 3500 | K45: 千川无视版 | L45: =(MAX(维护参数!$B$5,ROUNDUP(J44/10000,0)))*(维护参数!$B$3) -> 770 | R45: =SUM(L45,Q44) -> 1490 | S45: =R45/I45 -> 0.42571429 | T45: =I45-R45 -> 2010 | U45: =T45/(D44) -> 0.402 | V45: =T45*维护参数!$B$20 -> 1306.5 | W45: =V45/(D44) -> 0.2613
A46: 游戏永动机 | B46: 刘登魁 | C46: 星广 | D46: 5000 | E46: =D46*0.6 -> 3000 | F46: / | G46: / | H46: 私单 | I46: =(E46)*(1) -> 3000 | J46: =ROUNDUP(D46*维护参数!$B$11/维护参数!$B$12*1000,0) -> 133334 | K46: 普通千川 | L46: =(MAX(维护参数!$B$4,ROUNDUP(J46/10000,0)))*(维护参数!$B$2) -> 294 | M46: =ROUNDUP(D46*维护参数!$B$16/维护参数!$B$15/1000,0)*1000 -> 10000 | N46: =ROUNDUP(D46*维护参数!$B$17/维护参数!$B$15/10,0)*10 -> 100 | O46: =ROUNDUP(D46*维护参数!$B$18/维护参数!$B$15/10,0)*10 -> 100 | P46: =ROUNDUP(D46*维护参数!$B$19/维护参数!$B$15/10,0)*10 -> 150 | Q46: =M46/1000*维护参数!$B$6+N46*维护参数!$B$7+O46*维护参数!$B$8+P46*维护参数!$B$9 -> 720 | R46: =SUM(L46,Q46) -> 1014 | S46: =R46/I46 -> 0.338 | T46: =I46-R46 -> 1986 | U46: =T46/(D46) -> 0.3972 | V46: =T46*维护参数!$B$20 -> 1290.9 | W46: =V46/(D46) -> 0.25818 | X46: 星广 | Y46: https://v.douyin.com/c2M4VXTdIvM/
...

Sheet 维护参数
A1: 参数 | B1: 数值 | C1: 单位 / 来源
A2: 私单千川 | B2: 21 | C2: 元/万；
A3: 平台千川无视版 | B3: 55 | C3: 元/万；
A4: 私单千川起量 | B4: 10 | C4: 万
A5: 平台千川起量 | B5: 5 | C5: 万
A6: 点赞（科技） | B6: 60 | C6: 元/千次；
A7: 自定义评论 | B7: 0.8 | C7: 元/个；
A8: 收藏 | B8: 0.1 | C8: 元/个；
A9: 转发 | B9: 0.2 | C9: 元/个；
A10: 定制对客折扣 | B10: 0.7
A11: 折扣换算 | B11: 0.8
A12: 目标播放CPM | B12: 30 | C12: 元/千次；
A13: 星图观察CPM | B13: 200
A14: 星图观察系数 | B14: 1.5
A15: 互动档基准报价 | B15: 10000 | C15: 元；
A16: 点赞基准 | B16: 20000 | C16: 个；
A17: 评论基准 | B17: 200 | C17: 个；大号模板P列
A18: 收藏基准 | B18: 200 | C18: 个；大号模板P列
A19: 转发基准 | B19: 300 | C19: 个；大号模板P列
A20: 部门分成比例 | B20: 0.65 | C20: 沿用大号模板T列
A23: 来源与口径
A24: 账号与报价：【内容事业部】自孵化账号询单信息.xlsx，抖音页A/D/I/L/M/P列；原表更新2026-09-11。
A25: 价格：style-library/gross-margin/douyin.json，采用启用项unitPrice；未采用旧note中的价格。
A26: 模板：自孵化维护标准.xlsx，维护标准页J/K/P/R—U列。互动量按定制刊例价缩放为本次建议。
A27: 5个星广联投账号仍纳入，但本次仅按用户指定的私单/平台七折两种规则，不采用原表可谈深折条款。
A28: 毛利计算沿用工作台：成交价－维护成本；集团毛利率以折前下单基准为分母，部门毛利为集团毛利×65%。
A29: 维护费按完整目标预算，实际执行先减自然数据再核算；中位数未作为可购买或已实现数量。
A30: 空缺实际数据不填零。当前表用于逐账号制定预算，不代表历史表现、平台验收承诺或已完成维护。
