Workbook

Sheet 维护标准
A1: 【MCN事业部】自孵化账号维护标准
A2: 目标星图播放中位数 = 下阶段报价 ÷ 目标CPM 200 × 1000 × 1.5 维护顺序： 1、冲榜项目/发布后急需上量/抖加无法过审，优先采用千川无视版进行维护 2、除以上情况外，应当优先采用抖加维护，正常情况下仅适用抖加采买播放量，互动量通过HKJ补齐 达到目标中位数并形成至少3条满30天样本后，下月执行涨价；平台预期CPM暂时没变化也不立即降价。
A3: 账号 | B3: 8月植入报价 | C3: 8月定制报价 | D3: 预期播放量 | E3: 预期CPM | F3: 星图中位数 （30天） | G3: 9月植入报价 （定制价格*70%） | H3: 9月定制报价 | I3: 涨价比例 | J3: 目标 柱状图播放量 （定制CPM30） | K3: 目标 星图中位数 （30天） | L3: 抖加费用 （CPM17） | M3: 抖加费用 （CPM20） | N3: 柱状图播放量缺口 | O3: 千川费用 （CPM5.5） | P3: HKJ互动 | Q3: 总维护成本 | R3: 7折+数据维护后 集团毛利 | S3: 集团毛利率 | T3: 部门毛利 | U3: 部门毛利率 | V3: 外显CPM | W3: 播放中位数 | X3: 外显CPM（排营销） | Y3: 播放中位数（排营销）
A4: 花无缺 | B4: 14800 | C4: 16600 | D4: 57000 | E4: =B4/D4*1000 -> 259.64912 | F4: 69000 | G4: 14800 | H4: 16600 | I4: =(H4-C4)/C4 -> 0 | J4: =(H4*80%)*1000/30 -> 442666.67 | K4: =H4/200*1000*1.5 -> 124500 | L4: =K4*17/1000 -> 2116.5 | M4: =K4*20/1000 -> 2490 | N4: =J4-K4 -> 318166.67 | O4: =(N4/1000)*5.5 -> 1749.9167 | P4: =30*18+200*0.8+300*0.2+200*0.1 -> 780 | Q4: =M4+O4+P4 -> 5019.9167 | R4: =(H4*70%)-Q4 -> 6600.0833 | S4: =R4/H4 -> 0.39759538 | T4: =R4*0.65 -> 4290.0542 | U4: =T4/H4 -> 0.258437 | V4: 197.3 | W4: 7 | X4: 237.6 | Y4: 7
A5: 最游话说 | B5: 11900 | C5: 14300 | D5: 32000 | E5: =B5/D5*1000 -> 371.875 | F5: 54000 | G5: =H5*0.7 -> 12600 | H5: 18000 | I5: =(H5-C5)/C5 -> 0.25874126 | J5: =(H5*80%)*1000/30 -> 480000 | K5: =H5/200*1000*1.5 -> 135000 | L5: =K5*17/1000 -> 2295 | M5: =K5*20/1000 -> 2700 | N5: =J5-K5 -> 345000 | O5: =(N5/1000)*5.5 -> 1897.5 | P5: =20*18+200*0.8+300*0.2+200*0.1 -> 600 | Q5: =M5+O5+P5 -> 5197.5 | R5: =(H5*70%)-Q5 -> 7402.5 | S5: =R5/H5 -> 0.41125 | T5: =R5*0.65 -> 4811.625 | U5: =T5/H5 -> 0.2673125 | V5: 257.1 | W5: 5.6 | X5: 257.1 | Y5: 5.6
A6: 报告砖家 | B6: 14250 | C6: 17100 | D6: 261000 | E6: =B6/D6*1000 -> 54.597701 | F6: 189000 | G6: =H6*0.7 -> 14000 | H6: 20000 | I6: =(H6-C6)/C6 -> 0.16959064 | J6: =(H6*80%)*1000/30 -> 533333.33 | K6: =H6/200*1000*1.5 -> 150000 | L6: =K6*17/1000 -> 2550 | M6: =K6*20/1000 -> 3000 | N6: =J6-K6 -> 383333.33 | O6: =(N6/1000)*5.5 -> 2108.3333 | P6: =30*18+200*0.8+300*0.2+200*0.1 -> 780 | Q6: =M6+O6+P6 -> 5888.3333 | R6: =(H6*70%)-Q6 -> 8111.6667 | S6: =R6/H6 -> 0.40558333 | T6: =R6*0.65 -> 5272.5833 | U6: =T6/H6 -> 0.26362917 | V6: 53.7 | W6: 19.1 | X6: 53.9 | Y6: 19.1
A7: 策划克星阿强 | B7: 8000 | C7: 10000 | D7: 35000 | E7: =B7/D7*1000 -> 228.57143 | F7: 84000 | G7: =H7*0.7 -> 8400 | H7: 12000 | I7: =(H7-C7)/C7 -> 0.2 | J7: =(H7*80%)*1000/30 -> 320000 | K7: =H7/200*1000*1.5 -> 90000 | L7: =K7*17/1000 -> 1530 | M7: =K7*20/1000 -> 1800 | N7: =J7-K7 -> 230000 | O7: =(N7/1000)*5.5 -> 1265 | P7: =15*18+200*0.8+300*0.2+200*0.1 -> 510 | Q7: =M7+O7+P7 -> 3575 | R7: =(H7*70%)-Q7 -> 4825 | S7: =R7/H7 -> 0.40208333 | T7: =R7*0.65 -> 3136.25 | U7: =T7/H7 -> 0.26135417 | V7: 169.2 | W7: 95 | X7: 203.8 | Y7: 8.4
A8: 天机妹 | B8: 15000 | C8: 18000 | D8: 13000 | E8: =B8/D8*1000 -> 1153.8462 | F8: 84000 | G8: =H8*0.7 -> 14000 | H8: 20000 | I8: =(H8-C8)/C8 -> 0.11111111 | J8: =(H8*80%)*1000/30 -> 533333.33 | K8: =H8/200*1000*1.5 -> 150000 | L8: =K8*17/1000 -> 2550 | M8: =K8*20/1000 -> 3000 | N8: =J8-K8 -> 383333.33 | O8: =(N8/1000)*5.5 -> 2108.3333 | P8: =30*18+200*0.8+300*0.2+200*0.1 -> 780 | Q8: =M8+O8+P8 -> 5888.3333 | R8: =(H8*70%)-Q8 -> 8111.6667 | S8: =R8/H8 -> 0.40558333 | T8: =R8*0.65 -> 5272.5833 | U8: =T8/H8 -> 0.26362917 | V8: 1210.6 | W8: 10.9 | X8: 1281 | Y8: 10.9
A9: 木游话说 | B9: 10000 | C9: 12000 | D9: 26000 | E9: =B9/D9*1000 -> 384.61538 | F9: 70000 | G9: =H9*0.7 -> 10500 | H9: 15000 | I9: =(H9-C9)/C9 -> 0.25 | J9: =(H9*80%)*1000/30 -> 400000 | K9: =H9/200*1000*1.5 -> 112500 | L9: =K9*17/1000 -> 1912.5 | M9: =K9*20/1000 -> 2250 | N9: =J9-K9 -> 287500 | O9: =(N9/1000)*5.5 -> 1581.25 | P9: =20*18+200*0.8+300*0.2+200*0.1 -> 600 | Q9: =M9+O9+P9 -> 4431.25 | R9: =(H9*70%)-Q9 -> 6068.75 | S9: =R9/H9 -> 0.40458333 | T9: =R9*0.65 -> 3944.6875 | U9: =T9/H9 -> 0.26297917 | V9: 138.7 | W9: 30.7 | X9: 199 | Y9: 30.7
A10: 麦冬冬 | B10: 8000 | C10: 10000 | D10: 26000 | E10: =B10/D10*1000 -> 307.69231 | F10: 97000 | G10: 8000 | H10: 10000 | I10: =(H10-C10)/C10 -> 0 | J10: =(H10*80%)*1000/30 -> 266666.67 | K10: =H10/200*1000*1.5 -> 75000 | L10: =K10*17/1000 -> 1275 | M10: =K10*20/1000 -> 1500 | N10: =J10-K10 -> 191666.67 | O10: =(N10/1000)*5.5 -> 1054.1667 | P10: =15*18+200*0.8+300*0.2+200*0.1 -> 510 | Q10: =M10+O10+P10 -> 3064.1667 | R10: =(H10*70%)-Q10 -> 3935.8333 | S10: =R10/H10 -> 0.39358333 | T10: =R10*0.65 -> 2558.2917 | U10: =T10/H10 -> 0.25582917 | V10: 224.8 | W10: 13.7 | X10: 228.5 | Y10: 13.6
G13: s

Sheet 需补DOU+
A1: 序号 | B1: 账号 | C1: 商单 | D1: 发布链接 | E1: 是否为星图单 | F1: 已投成本 | I1: 播放量 （只算自然量加doui+） | J1: 需补dou+ | K1: 发起申请 | L1: 投放 | N1: 昵称 | O1: 条数 | P1: 金额 | Q1: 营销标的 | R1: 星图播放量中位数 维护前 | S1: 星图播放量中位数 维护后预估 | T1: 预期播放量 维护前 | U1: 预期播放量 维护后预估（一个月后） | V1: 预期播Cpm 维护后预估（一个月后）
F2: 千川 | G2: dou+ | H2: 合计
B3: 最游话说 | C3: 穿越火线 | D3: https://v.douyin.com/O_y6EZe7Pxc/ | E3: 否 | F3: 2164 | G3: 0 | H3: =F3+G3 -> 2164 | I3: 16000 | J3: / | N3: 最游话说 | O3: 6 | P3: 3700 | Q3: 新天龙八部、三国火凤燎原 | R3: 57000 | S3: 110000 | T3: 27000 | U3: 130000 | V3: =R14/U3*1000 -> 138.46154
B4: 最游话说 | C4: 仙遇 | D4: https://v.douyin.com/bBaFptMb0cI/ | E4: 否 | F4: 1574 | G4: 0 | H4: =F4+G4 -> 1574 | I4: 10000 | J4: / | N4: 木游话说 | O4: 3 | P4: 3100 | Q4: 三国志王道天下、新天龙八部 | R4: 35000 | S4: 110000 | T4: 32000 | U4: 140000 | V4: =R15/U4*1000 -> 128.57143
B5: 最游话说 | C5: 雾海之下 | D5: https://v.douyin.com/_YVsx0qkLhY/ | E5: 否 | F5: 1576 | G5: 500 | H5: =F5+G5 -> 2076 | I5: 29100 | J5: / | N5: 策划克星阿强 | O5: 2 | P5: 2000 | Q5: 仙遇、应用宝 | R5: 46000 | S5: 100000 | T5: 43000 | U5: 130000 | V5: =R16/U5*1000 -> 115.38462
B6: 最游话说 | C6: 疯狂水世界 | D6: https://v.douyin.com/PXOEqRrTTWE/ | E6: 是 | F6: 1650 | G6: 500 | H6: =F6+G6 -> 2150 | I6: 25700 | J6: / | N6: 花无缺 | O6: 3 | P6: 3000 | Q6: 三角洲行动、三国火凤燎原 | R6: 65000 | S6: 130000 | T6: 41000 | U6: 180000 | V6: =R17/U6*1000 -> 111.11111
B7: 最游话说 | C7: 天龙八部 | D7: https://v.douyin.com/QBFbHgS_qzs/ | E7: 是 | F7: 2085 | G7: 0 | H7: =F7+G7 -> 2085 | I7: 20000 | J7: 500 | K7: 1 | L7: 1 | M7: =SUM(J7:J12) -> 3700 | N7: 天机妹 | O7: 4 | P7: 5000 | Q7: 向末日开炮、新天龙八部 | R7: 29000 | S7: 125000 | T7: 16000 | U7: 150000 | V7: =R18/U7*1000 -> 133.33333
B8: 最游话说 | C8: 三国火凤燎原 | D8: https://v.douyin.com/Qpj1irNXt2o/ | E8: 是 | F8: 1140 | G8: 1000 | H8: =F8+G8 -> 2140 | I8: 55000 | J8: 800 | K8: 1 | L8: 1 | N8: 报告砖家 | O8: 1 | P8: 1000 | Q8: ROG | R8: 458000 | S8: / | T8: 257000 | U8: / | V8: /
B9: 最游话说 | C9: 雅迪x绝区零 | D9: https://v.douyin.com/balqG0MdVto/ | E9: 是 | F9: 1595 | G9: 1000 | H9: =F9+G9 -> 2595 | I9: 59000 | J9: 800 | K9: 1 | L9: 1 | N9: 麦冬冬 | O9: 2 | P9: 1500 | Q9: 三国志王道天下 | R9: 38000 | S9: 90000 | T9: 26000 | U9: 100000 | V9: =R20/U9*1000 -> 150
B10: 最游话说 | C10: 新大话西游 | D10: https://v.douyin.com/sddgZUvHCH8/ | E10: 是 | F10: 1090 | G10: 1000 | H10: =F10+G10 -> 2090 | I10: 56000 | J10: 800 | K10: 1 | L10: 1 | N10: 合计 | P10: =SUM(P3:P9) -> 19300
B11: 最游话说 | C11: IQOO | D11: https://v.douyin.com/QU_a6-qEFSc/ | E11: 是 | F11: 1219 | G11: 1500 | H11: =F11+G11 -> 2719 | I11: 93200 | J11: / | P11: =9800+23600 -> 33400
B12: 最游话说 | C12: 率土之滨 | D12: https://v.douyin.com/sJElyt9DQsk/ | E12: 是 | F12: 1411 | G12: 1000 | H12: =F12+G12 -> 2411 | I12: 54000 | J12: 800 | K12: 1 | L12: 1 | P12: =SUM(P10:P11) -> 52700 | Q12: =P12/0.6 -> 87833.333
B13: 最游话说 | C13: 新大话西游 | D13: 未发 | E13: 是 | F13: / | G13: / | H13: / | I13: 90000 | J13: 0 | Q13: 账号 | R13: 下阶段报价 | S13: 目标星图中位数
B14: 麦冬冬 | C14: 天龙八部 | D14: https://v.douyin.com/Ypf3z8VOGM4/ | E14: 是 | F14: 1765 | G14: 1000 | H14: =F14+G14 -> 2765 | I14: 64000 | J14: 500 | K14: 1 | L14: 1 | Q14: 最游话说 | R14: 18000 | S14: 120000
B15: 麦冬冬 | C15: 三国志：王道天下 | D15: https://v.douyin.com/QHOABaZ8XpY/ | E15: 是 | F15: 2035 | G15: 500 | H15: =F15+G15 -> 2535 | I15: 30000 | J15: 1000 | K15: 1 | L15: 1 | Q15: 木游话说 | R15: 18000 | S15: 120000
B16: 木游话说 | C16: 三国志：王道天下 | D16: https://v.douyin.com/0K55vTkPf80/ | E16: 是 | F16: 1670 | G16: 500 | H16: =F16+G16 -> 2170 | I16: 9000 | J16: 800 | K16: 1 | L16: 1 | M16: 3100 | Q16: 策划克星阿强 | R16: 15000 | S16: 100000
B17: 木游话说 | C17: 新天龙八部 | D17: https://v.douyin.com/o3WY-D0i2SU | E17: 是 | F17: 1670 | G17: 0 | H17: =F17+G17 -> 1670 | I17: 45000 | J17: 1500 | K17: 1 | L17: 1 | Q17: 花无缺 | R17: 20000 | S17: 150000
B18: 木游话说 | C18: 雾海之下 | D18: https://v.douyin.com/LMBUS2mv5nQ/ | E18: 否 | F18: 1110 | G18: 0 | H18: =F18+G18 -> 1110 | I18: 2000 | J18: / | M18: 违规不投流 | Q18: 天机妹 | R18: 20000 | S18: 150000
B19: 木游话说 | C19: 仙遇 | D19: https://v.douyin.com/nWTl7vI_tXs/ | E19: 否 | F19: 1110 | G19: 0 | H19: =F19+G19 -> 1110 | I19: 21000 | J19: / | M19: 违规不投流 | Q19: 报告砖家 | R19: 20000 | S19: 150000
B20: 木游话说 | C20: appstore | D20: https://v.douyin.com/tT8IDZkGMz0/ | E20: 是 | F20: 0 | G20: 1000 | H20: 1000 | I20: 55000 | J20: 800 | K20: 1 | L20: 1 | Q20: 麦冬冬 | R20: 15000 | S20: 100000
B21: 木游话说 | C21: 时空猎人:觉醒 | D21: 未发 | E21: 否 | F21: / | G21: / | H21: / | I21: / | J21: /
B22: 策划克星阿强 | C22: 仙遇 | D22: https://v.douyin.com/OMuv4vkQCnM/ | E22: 否 | F22: 1230 | G22: 0 | H22: =F22+G22 -> 1230 | I22: 5000 | J22: /
B23: 策划克星阿强 | C23: 鸿蒙CJ | D23: https://v.douyin.com/PkAgFU-6NMY/ | E23: 是 | F23: 1269 | G23: 0 | H23: =F23+G23 -> 1269 | I23: 5000 | J23: 1000 | K23: 1 | L23: 1 | M23: 2000
B24: 策划克星阿强 | C24: dnf应用宝 | D24: https://v.douyin.com/CKkb6Tnx8kY/ | E24: 是 | F24: 1506 | G24: 0 | H24: =F24+G24 -> 1506 | I24: 5000 | J24: 1000 | K24: 1 | L24: 1
B25: 策划克星阿强 | C25: 雾海之下 | D25: https://v.douyin.com/1_t7DAMMbt0/ | E25: 否 | F25: 1180 | G25: 0 | H25: =F25+G25 -> 1180 | I25: 2000 | J25: 0 | M25: 违规不投流
B26: 策划克星阿强 | C26: IQOO抖音电商开学季 | D26: https://v.douyin.com/-l8PolKZPYw/ | E26: 是 | F26: 876 | G26: 1000 | H26: =F26+G26 -> 1876 | I26: 60000 | J26: 0
B27: 报告砖家 | C27: 仙遇 | D27: https://v.douyin.com/xWO7974UPpc/ | E27: 否 | F27: 2298 | G27: / | H27: =SUM(F27:G27) -> 2298 | I27: 24000 | J27: / | M27: 违规不投流
B28: 报告砖家 | C28: rog | D28: https://v.douyin.com/thvS9L2IReA/ | E28: 是 | F28: 2194 | G28: 1000 | H28: =SUM(F28:G28) -> 3194 | I28: 4000 | J28: 1000 | K28: 1 | L28: 1
B29: 报告砖家 | C29: 穿越火线 | D29: https://v.douyin.com/aanjCgBObrI/ | E29: 否 | F29: 796 | G29: / | H29: =SUM(F29:G29) -> 796 | I29: 255000 | J29: /
B30: 报告砖家 | C30: 三角洲行动安全专项（保密项目） | D30: https://v.douyin.com/DNbu9Uasf6o/ | E30: 否 | F30: 1236 | G30: / | H30: =SUM(F30:G30) -> 1236 | I30: 352000 | J30: /
B31: 报告砖家 | C31: 金铲铲之战 | D31: https://v.douyin.com/KJaISoIxLbU/ | E31: 否 | F31: 2082 | G31: 1000 | H31: =SUM(F31:G31) -> 3082 | I31: 62000 | J31: /
B32: 报告砖家 | C32: 三角洲行动PC | D32: https://v.douyin.com/Ct9hnyrL9Uc/ | E32: 是 | F32: 3274 | G32: 1000 | H32: =SUM(F32:G32) -> 4274 | I32: 64000 | J32: /
B33: 报告砖家 | C33: 三角洲行动 | D33: https://v.douyin.com/3hiHS1_T408/ | E33: 是 | F33: 1595 | G33: 2500 | H33: =SUM(F33:G33) -> 4095 | I33: 127000 | J33: /
B34: 花无缺 | C34: 三国火凤燎原 | D34: https://v.douyin.com/XbgCixFkm3o/ | E34: 是 | F34: 1140 | G34: 1000 | H34: 2140 | I34: 5.8w | J34: 1500 | K34: 1 | L34: 1 | M34: 3000
B35: 花无缺 | C35: IQOO抖音电商开学季 | D35: https://v.douyin.com/16ZUpOdgoAs/ | E35: 是 | F35: 2608 | G35: 1000 | H35: 3608 | I35: 17.2w | J35: 0
B36: 花无缺 | C36: 三角洲行动PC | D36: https://v.douyin.com/EzilU_chRrE/ | E36: 是 | F36: 3121 | G36: 1000 | H36: 4121 | I36: 5.2w | J36: 1500 | K36: 1 | L36: 1
B37: 花无缺 | C37: 王者万象棋 | D37: https://v.douyin.com/v4bqWZel5Qc/ | E37: 否 | F37: 2461 | G37: 1000 | H37: 3461 | I37: 5w | J37: /
B38: 天机妹 | C38: 仙遇cj | D38: https://v.douyin.com/yACJcyK96A4/ | E38: 否 | F38: 2215 | G38: / | H38: 2215 | I38: 5000 | J38: / | M38: 违规不投流
B39: 天机妹 | C39: 穿越火线 | D39: https://v.douyin.com/ngKT1OYusH4/ | E39: 是 | F39: 2495 | G39: / | H39: 2495 | I39: 5000 | J39: 1000 | K39: 1 | L39: 1 | M39: 7000
B40: 天机妹 | C40: 向末日开炮 | D40: https://v.douyin.com/ZnWPfsIG9XU/ | E40: 是 | F40: 2264 | G40: 0 | H40: 2264 | I40: 5000 | J40: 2000 | K40: 1 | L40: 1
...

Sheet 抖音小号维护标准
A1: 【内容事业部】抖音游戏类小号维护标准
A2: 私单按询单表私单价格，不额外折扣；平台单按各账号定制刊例报价×70% 播放目标沿用大号模板：定制基准×80%÷30×1000。按完整目标预留千川费用，不将星图中位数当成已实现播放扣减。
A9: 账号 | B9: 定制 刊例价 | C9: 私单 报价 | D9: 订单 类型 | E9: 成交价 | F9: 目标播放量 （次） | G9: 千川版本 | H9: 千川 费用 | I9: 点赞 | J9: 评论 | K9: 收藏 | L9: 转发 | M9: 互动 费用 | N9: 总维护 成本 | O9: 维护费 占成交价 | P9: 集团 毛利 | Q9: 集团毛利率 （占折前报价） | R9: 部门 毛利 | S9: 部门毛利率 （占折前报价） | T9: 负责人 | U9: 主页链接
A10: 麦小雯 | B10: 6000 | C10: 3600 | D10: 私单 | E10: =(C10)*(1) -> 3600 | F10: =ROUNDUP(B10*维护参数!$B$11/维护参数!$B$12*1000,0) -> 220000 | G10: 普通千川 | H10: =(MAX(维护参数!$B$4,ROUNDUP(F10/10000,0)))*(维护参数!$B$2) -> 462 | I10: =ROUNDUP(B10*维护参数!$B$16/维护参数!$B$15/1000,0)*1000 -> 12000 | J10: =ROUNDUP(B10*维护参数!$B$17/维护参数!$B$15/10,0)*10 -> 120 | K10: =ROUNDUP(B10*维护参数!$B$18/维护参数!$B$15/10,0)*10 -> 120 | L10: =ROUNDUP(B10*维护参数!$B$19/维护参数!$B$15/10,0)*10 -> 180 | M10: =I10/1000*维护参数!$B$6+J10*维护参数!$B$7+K10*维护参数!$B$8+L10*维护参数!$B$9 -> 864 | N10: =SUM(H10,M10) -> 1326 | O10: =N10/E10 -> 0.36833333 | P10: =E10-N10 -> 2274 | Q10: =P10/(E10) -> 0.63166667 | R10: =P10*维护参数!$B$20 -> 1478.1 | S10: =R10/(C10) -> 0.41058333 | T10: 陈健伊 | U10: https://v.douyin.com/DcH2brXPgvc/
D11: 平台单 | E11: =(B10)*(维护参数!$B$10) -> 4200 | G11: 千川无视版 | H11: =(MAX(维护参数!$B$5,ROUNDUP(F10/10000,0)))*(维护参数!$B$3) -> 1210 | N11: =SUM(H11,M10) -> 2074 | O11: =N11/E11 -> 0.49380952 | P11: =E11-N11 -> 2126 | Q11: =P11/(E11) -> 0.50619048 | R11: =P11*维护参数!$B$20 -> 1381.9 | S11: =R11/(B10) -> 0.23031667
A12: 葵仔不想肝 | B12: 6250 | C12: 3750 | D12: 私单 | E12: =(C12)*(1) -> 3750 | F12: =ROUNDUP(B12*维护参数!$B$11/维护参数!$B$12*1000,0) -> 229167 | G12: 普通千川 | H12: =(MAX(维护参数!$B$4,ROUNDUP(F12/10000,0)))*(维护参数!$B$2) -> 483 | I12: =ROUNDUP(B12*维护参数!$B$16/维护参数!$B$15/1000,0)*1000 -> 13000 | J12: =ROUNDUP(B12*维护参数!$B$17/维护参数!$B$15/10,0)*10 -> 130 | K12: =ROUNDUP(B12*维护参数!$B$18/维护参数!$B$15/10,0)*10 -> 130 | L12: =ROUNDUP(B12*维护参数!$B$19/维护参数!$B$15/10,0)*10 -> 190 | M12: =I12/1000*维护参数!$B$6+J12*维护参数!$B$7+K12*维护参数!$B$8+L12*维护参数!$B$9 -> 935 | N12: =SUM(H12,M12) -> 1418 | O12: =N12/E12 -> 0.37813333 | P12: =E12-N12 -> 2332 | Q12: =P12/(E12) -> 0.62186667 | R12: =P12*维护参数!$B$20 -> 1515.8 | S12: =R12/(C12) -> 0.40421333 | T12: 刘登魁 | U12: https://v.douyin.com/38Scd6JrG_s/
D13: 平台单 | E13: =(B12)*(维护参数!$B$10) -> 4375 | G13: 千川无视版 | H13: =(MAX(维护参数!$B$5,ROUNDUP(F12/10000,0)))*(维护参数!$B$3) -> 1265 | N13: =SUM(H13,M12) -> 2200 | O13: =N13/E13 -> 0.50285714 | P13: =E13-N13 -> 2175 | Q13: =P13/(E13) -> 0.49714286 | R13: =P13*维护参数!$B$20 -> 1413.75 | S13: =R13/(B12) -> 0.2262
A14: 游热娃子 | B14: 8750 | C14: 5250 | D14: 私单 | E14: =(C14)*(1) -> 5250 | F14: =ROUNDUP(B14*维护参数!$B$11/维护参数!$B$12*1000,0) -> 320834 | G14: 普通千川 | H14: =(MAX(维护参数!$B$4,ROUNDUP(F14/10000,0)))*(维护参数!$B$2) -> 693 | I14: =ROUNDUP(B14*维护参数!$B$16/维护参数!$B$15/1000,0)*1000 -> 18000 | J14: =ROUNDUP(B14*维护参数!$B$17/维护参数!$B$15/10,0)*10 -> 180 | K14: =ROUNDUP(B14*维护参数!$B$18/维护参数!$B$15/10,0)*10 -> 180 | L14: =ROUNDUP(B14*维护参数!$B$19/维护参数!$B$15/10,0)*10 -> 270 | M14: =I14/1000*维护参数!$B$6+J14*维护参数!$B$7+K14*维护参数!$B$8+L14*维护参数!$B$9 -> 1296 | N14: =SUM(H14,M14) -> 1989 | O14: =N14/E14 -> 0.37885714 | P14: =E14-N14 -> 3261 | Q14: =P14/(C14) -> 0.62114286 | R14: =P14*维护参数!$B$20 -> 2119.65 | S14: =R14/(C14) -> 0.40374286 | T14: 杨鸿霆 | U14: https://v.douyin.com/JmcvjVd/
D15: 平台单 | E15: =(B14)*(维护参数!$B$10) -> 6125 | G15: 千川无视版 | H15: =(MAX(维护参数!$B$5,ROUNDUP(F14/10000,0)))*(维护参数!$B$3) -> 1815 | N15: =SUM(H15,M14) -> 3111 | O15: =N15/E15 -> 0.50791837 | P15: =E15-N15 -> 3014 | Q15: =P15/(B14) -> 0.34445714 | R15: =P15*维护参数!$B$20 -> 1959.1 | S15: =R15/(B14) -> 0.22389714
A16: 游小妹 | B16: 6000 | C16: 3600 | D16: 私单 | E16: =(C16)*(1) -> 3600 | F16: =ROUNDUP(B16*维护参数!$B$11/维护参数!$B$12*1000,0) -> 220000 | G16: 普通千川 | H16: =(MAX(维护参数!$B$4,ROUNDUP(F16/10000,0)))*(维护参数!$B$2) -> 462 | I16: =ROUNDUP(B16*维护参数!$B$16/维护参数!$B$15/1000,0)*1000 -> 12000 | J16: =ROUNDUP(B16*维护参数!$B$17/维护参数!$B$15/10,0)*10 -> 120 | K16: =ROUNDUP(B16*维护参数!$B$18/维护参数!$B$15/10,0)*10 -> 120 | L16: =ROUNDUP(B16*维护参数!$B$19/维护参数!$B$15/10,0)*10 -> 180 | M16: =I16/1000*维护参数!$B$6+J16*维护参数!$B$7+K16*维护参数!$B$8+L16*维护参数!$B$9 -> 864 | N16: =SUM(H16,M16) -> 1326 | O16: =N16/E16 -> 0.36833333 | P16: =E16-N16 -> 2274 | Q16: =P16/(C16) -> 0.63166667 | R16: =P16*维护参数!$B$20 -> 1478.1 | S16: =R16/(C16) -> 0.41058333 | T16: 杨鸿霆 | U16: https://v.douyin.com/JmcXQpY/
D17: 平台单 | E17: =(B16)*(维护参数!$B$10) -> 4200 | G17: 千川无视版 | H17: =(MAX(维护参数!$B$5,ROUNDUP(F16/10000,0)))*(维护参数!$B$3) -> 1210 | N17: =SUM(H17,M16) -> 2074 | O17: =N17/E17 -> 0.49380952 | P17: =E17-N17 -> 2126 | Q17: =P17/(B16) -> 0.35433333 | R17: =P17*维护参数!$B$20 -> 1381.9 | S17: =R17/(B16) -> 0.23031667
A18: 灵梦小师妹 | B18: 6000 | C18: 3600 | D18: 私单 | E18: =(C18)*(1) -> 3600 | F18: =ROUNDUP(B18*维护参数!$B$11/维护参数!$B$12*1000,0) -> 220000 | G18: 普通千川 | H18: =(MAX(维护参数!$B$4,ROUNDUP(F18/10000,0)))*(维护参数!$B$2) -> 462 | I18: =ROUNDUP(B18*维护参数!$B$16/维护参数!$B$15/1000,0)*1000 -> 12000 | J18: =ROUNDUP(B18*维护参数!$B$17/维护参数!$B$15/10,0)*10 -> 120 | K18: =ROUNDUP(B18*维护参数!$B$18/维护参数!$B$15/10,0)*10 -> 120 | L18: =ROUNDUP(B18*维护参数!$B$19/维护参数!$B$15/10,0)*10 -> 180 | M18: =I18/1000*维护参数!$B$6+J18*维护参数!$B$7+K18*维护参数!$B$8+L18*维护参数!$B$9 -> 864 | N18: =SUM(H18,M18) -> 1326 | O18: =N18/E18 -> 0.36833333 | P18: =E18-N18 -> 2274 | Q18: =P18/(C18) -> 0.63166667 | R18: =P18*维护参数!$B$20 -> 1478.1 | S18: =R18/(C18) -> 0.41058333 | T18: 林宇辰 | U18: https://www.douyin.com/user/MS4wLjABAAAAJfqON1LDmWBPlUXvQ-iwZ6AZLbLuIj72uGiFUuot89k
D19: 平台单 | E19: =(B18)*(维护参数!$B$10) -> 4200 | G19: 千川无视版 | H19: =(MAX(维护参数!$B$5,ROUNDUP(F18/10000,0)))*(维护参数!$B$3) -> 1210 | N19: =SUM(H19,M18) -> 2074 | O19: =N19/E19 -> 0.49380952 | P19: =E19-N19 -> 2126 | Q19: =P19/(B18) -> 0.35433333 | R19: =P19*维护参数!$B$20 -> 1381.9 | S19: =R19/(B18) -> 0.23031667
A20: 超玩教授 | B20: 6000 | C20: 3600 | D20: 私单 | E20: =(C20)*(1) -> 3600 | F20: =ROUNDUP(B20*维护参数!$B$11/维护参数!$B$12*1000,0) -> 220000 | G20: 普通千川 | H20: =(MAX(维护参数!$B$4,ROUNDUP(F20/10000,0)))*(维护参数!$B$2) -> 462 | I20: =ROUNDUP(B20*维护参数!$B$16/维护参数!$B$15/1000,0)*1000 -> 12000 | J20: =ROUNDUP(B20*维护参数!$B$17/维护参数!$B$15/10,0)*10 -> 120 | K20: =ROUNDUP(B20*维护参数!$B$18/维护参数!$B$15/10,0)*10 -> 120 | L20: =ROUNDUP(B20*维护参数!$B$19/维护参数!$B$15/10,0)*10 -> 180 | M20: =I20/1000*维护参数!$B$6+J20*维护参数!$B$7+K20*维护参数!$B$8+L20*维护参数!$B$9 -> 864 | N20: =SUM(H20,M20) -> 1326 | O20: =N20/E20 -> 0.36833333 | P20: =E20-N20 -> 2274 | Q20: =P20/(C20) -> 0.63166667 | R20: =P20*维护参数!$B$20 -> 1478.1 | S20: =R20/(C20) -> 0.41058333 | T20: 商光涵 | U20: https://v.douyin.com/JJ3p572/
D21: 平台单 | E21: =(B20)*(维护参数!$B$10) -> 4200 | G21: 千川无视版 | H21: =(MAX(维护参数!$B$5,ROUNDUP(F20/10000,0)))*(维护参数!$B$3) -> 1210 | N21: =SUM(H21,M20) -> 2074 | O21: =N21/E21 -> 0.49380952 | P21: =E21-N21 -> 2126 | Q21: =P21/(B20) -> 0.35433333 | R21: =P21*维护参数!$B$20 -> 1381.9 | S21: =R21/(B20) -> 0.23031667
A22: lee小强 | B22: 4800 | C22: 2880 | D22: 私单 | E22: =(C22)*(1) -> 2880 | F22: =ROUNDUP(B22*维护参数!$B$11/维护参数!$B$12*1000,0) -> 176000 | G22: 普通千川 | H22: =(MAX(维护参数!$B$4,ROUNDUP(F22/10000,0)))*(维护参数!$B$2) -> 378 | I22: =ROUNDUP(B22*维护参数!$B$16/维护参数!$B$15/1000,0)*1000 -> 10000 | J22: =ROUNDUP(B22*维护参数!$B$17/维护参数!$B$15/10,0)*10 -> 100 | K22: =ROUNDUP(B22*维护参数!$B$18/维护参数!$B$15/10,0)*10 -> 100 | L22: =ROUNDUP(B22*维护参数!$B$19/维护参数!$B$15/10,0)*10 -> 150 | M22: =I22/1000*维护参数!$B$6+J22*维护参数!$B$7+K22*维护参数!$B$8+L22*维护参数!$B$9 -> 720 | N22: =SUM(H22,M22) -> 1098 | O22: =N22/E22 -> 0.38125 | P22: =E22-N22 -> 1782 | Q22: =P22/(C22) -> 0.61875 | R22: =P22*维护参数!$B$20 -> 1158.3 | S22: =R22/(C22) -> 0.4021875 | T22: 商光涵 | U22: https://v.douyin.com/ihb6eF8j/
D23: 平台单 | E23: =(B22)*(维护参数!$B$10) -> 3360 | G23: 千川无视版 | H23: =(MAX(维护参数!$B$5,ROUNDUP(F22/10000,0)))*(维护参数!$B$3) -> 990 | N23: =SUM(H23,M22) -> 1710 | O23: =N23/E23 -> 0.50892857 | P23: =E23-N23 -> 1650 | Q23: =P23/(B22) -> 0.34375 | R23: =P23*维护参数!$B$20 -> 1072.5 | S23: =R23/(B22) -> 0.2234375
A24: 不玩就分手 | B24: 3500 | C24: 2100 | D24: 私单 | E24: =(C24)*(1) -> 2100 | F24: =ROUNDUP(B24*维护参数!$B$11/维护参数!$B$12*1000,0) -> 128334 | G24: 普通千川 | H24: =(MAX(维护参数!$B$4,ROUNDUP(F24/10000,0)))*(维护参数!$B$2) -> 273 | I24: =ROUNDUP(B24*维护参数!$B$16/维护参数!$B$15/1000,0)*1000 -> 7000 | J24: =ROUNDUP(B24*维护参数!$B$17/维护参数!$B$15/10,0)*10 -> 70 | K24: =ROUNDUP(B24*维护参数!$B$18/维护参数!$B$15/10,0)*10 -> 70 | L24: =ROUNDUP(B24*维护参数!$B$19/维护参数!$B$15/10,0)*10 -> 110 | M24: =I24/1000*维护参数!$B$6+J24*维护参数!$B$7+K24*维护参数!$B$8+L24*维护参数!$B$9 -> 505 | N24: =SUM(H24,M24) -> 778 | O24: =N24/E24 -> 0.37047619 | P24: =E24-N24 -> 1322 | Q24: =P24/(C24) -> 0.62952381 | R24: =P24*维护参数!$B$20 -> 859.3 | S24: =R24/(C24) -> 0.40919048 | T24: 刘登魁 | U24: https://v.douyin.com/jTKED_9fV4A/
D25: 平台单 | E25: =(B24)*(维护参数!$B$10) -> 2450 | G25: 千川无视版 | H25: =(MAX(维护参数!$B$5,ROUNDUP(F24/10000,0)))*(维护参数!$B$3) -> 715 | N25: =SUM(H25,M24) -> 1220 | O25: =N25/E25 -> 0.49795918 | P25: =E25-N25 -> 1230 | Q25: =P25/(B24) -> 0.35142857 | R25: =P25*维护参数!$B$20 -> 799.5 | S25: =R25/(B24) -> 0.22842857
A26: 游梗要说 | B26: 7800 | C26: 4680 | D26: 私单 | E26: =(C26)*(1) -> 4680 | F26: =ROUNDUP(B26*维护参数!$B$11/维护参数!$B$12*1000,0) -> 286000 | G26: 普通千川 | H26: =(MAX(维护参数!$B$4,ROUNDUP(F26/10000,0)))*(维护参数!$B$2) -> 609 | I26: =ROUNDUP(B26*维护参数!$B$16/维护参数!$B$15/1000,0)*1000 -> 16000 | J26: =ROUNDUP(B26*维护参数!$B$17/维护参数!$B$15/10,0)*10 -> 160 | K26: =ROUNDUP(B26*维护参数!$B$18/维护参数!$B$15/10,0)*10 -> 160 | L26: =ROUNDUP(B26*维护参数!$B$19/维护参数!$B$15/10,0)*10 -> 240 | M26: =I26/1000*维护参数!$B$6+J26*维护参数!$B$7+K26*维护参数!$B$8+L26*维护参数!$B$9 -> 1152 | N26: =SUM(H26,M26) -> 1761 | O26: =N26/E26 -> 0.37628205 | P26: =E26-N26 -> 2919 | Q26: =P26/(C26) -> 0.62371795 | R26: =P26*维护参数!$B$20 -> 1897.35 | S26: =R26/(C26) -> 0.40541667 | T26: 罗晓棋 | U26: https://www.douyin.com/user/MS4wLjABAAAAbRgpD5qO5M7mlI-ALMWDbsqjwiSeFC1WxNPKVgjsSCbFam1N0thGyVDw-PfRjICt
D27: 平台单 | E27: =(B26)*(维护参数!$B$10) -> 5460 | G27: 千川无视版 | H27: =(MAX(维护参数!$B$5,ROUNDUP(F26/10000,0)))*(维护参数!$B$3) -> 1595 | N27: =SUM(H27,M26) -> 2747 | O27: =N27/E27 -> 0.50311355 | P27: =E27-N27 -> 2713 | Q27: =P27/(B26) -> 0.34782051 | R27: =P27*维护参数!$B$20 -> 1763.45 | S27: =R27/(B26) -> 0.22608333
A28: 中二探长 | B28: 3750 | C28: 2250 | D28: 私单 | E28: =(C28)*(1) -> 2250 | F28: =ROUNDUP(B28*维护参数!$B$11/维护参数!$B$12*1000,0) -> 137500 | G28: 普通千川 | H28: =(MAX(维护参数!$B$4,ROUNDUP(F28/10000,0)))*(维护参数!$B$2) -> 294 | I28: =ROUNDUP(B28*维护参数!$B$16/维护参数!$B$15/1000,0)*1000 -> 8000 | J28: =ROUNDUP(B28*维护参数!$B$17/维护参数!$B$15/10,0)*10 -> 80 | K28: =ROUNDUP(B28*维护参数!$B$18/维护参数!$B$15/10,0)*10 -> 80 | L28: =ROUNDUP(B28*维护参数!$B$19/维护参数!$B$15/10,0)*10 -> 120 | M28: =I28/1000*维护参数!$B$6+J28*维护参数!$B$7+K28*维护参数!$B$8+L28*维护参数!$B$9 -> 576 | N28: =SUM(H28,M28) -> 870 | O28: =N28/E28 -> 0.38666667 | P28: =E28-N28 -> 1380 | Q28: =P28/(C28) -> 0.61333333 | R28: =P28*维护参数!$B$20 -> 897 | S28: =R28/(C28) -> 0.39866667 | T28: 陈泓睿 | U28: https://v.douyin.com/mFA-j2xaAJY/
D29: 平台单 | E29: =(B28)*(维护参数!$B$10) -> 2625 | G29: 千川无视版 | H29: =(MAX(维护参数!$B$5,ROUNDUP(F28/10000,0)))*(维护参数!$B$3) -> 770 | N29: =SUM(H29,M28) -> 1346 | O29: =N29/E29 -> 0.5127619 | P29: =E29-N29 -> 1279 | Q29: =P29/(B28) -> 0.34106667 | R29: =P29*维护参数!$B$20 -> 831.35 | S29: =R29/(B28) -> 0.22169333
A30: 嘿小虎 | B30: 3000 | C30: 1800 | D30: 私单 | E30: =(C30)*(1) -> 1800 | F30: =ROUNDUP(B30*维护参数!$B$11/维护参数!$B$12*1000,0) -> 110000 | G30: 普通千川 | H30: =(MAX(维护参数!$B$4,ROUNDUP(F30/10000,0)))*(维护参数!$B$2) -> 231 | I30: =ROUNDUP(B30*维护参数!$B$16/维护参数!$B$15/1000,0)*1000 -> 6000 | J30: =ROUNDUP(B30*维护参数!$B$17/维护参数!$B$15/10,0)*10 -> 60 | K30: =ROUNDUP(B30*维护参数!$B$18/维护参数!$B$15/10,0)*10 -> 60 | L30: =ROUNDUP(B30*维护参数!$B$19/维护参数!$B$15/10,0)*10 -> 90 | M30: =I30/1000*维护参数!$B$6+J30*维护参数!$B$7+K30*维护参数!$B$8+L30*维护参数!$B$9 -> 432 | N30: =SUM(H30,M30) -> 663 | O30: =N30/E30 -> 0.36833333 | P30: =E30-N30 -> 1137 | Q30: =P30/(C30) -> 0.63166667 | R30: =P30*维护参数!$B$20 -> 739.05 | S30: =R30/(C30) -> 0.41058333 | T30: 陈泓睿 | U30: https://v.douyin.com/lIhi6TchbPw/
D31: 平台单 | E31: =(B30)*(维护参数!$B$10) -> 2100 | G31: 千川无视版 | H31: =(MAX(维护参数!$B$5,ROUNDUP(F30/10000,0)))*(维护参数!$B$3) -> 605 | N31: =SUM(H31,M30) -> 1037 | O31: =N31/E31 -> 0.49380952 | P31: =E31-N31 -> 1063 | Q31: =P31/(B30) -> 0.35433333 | R31: =P31*维护参数!$B$20 -> 690.95 | S31: =R31/(B30) -> 0.23031667
A32: 有事找学姐 | B32: 7150 | C32: 4290 | D32: 私单 | E32: =(C32)*(1) -> 4290 | F32: =ROUNDUP(B32*维护参数!$B$11/维护参数!$B$12*1000,0) -> 262167 | G32: 普通千川 | H32: =(MAX(维护参数!$B$4,ROUNDUP(F32/10000,0)))*(维护参数!$B$2) -> 567 | I32: =ROUNDUP(B32*维护参数!$B$16/维护参数!$B$15/1000,0)*1000 -> 15000 | J32: =ROUNDUP(B32*维护参数!$B$17/维护参数!$B$15/10,0)*10 -> 150 | K32: =ROUNDUP(B32*维护参数!$B$18/维护参数!$B$15/10,0)*10 -> 150 | L32: =ROUNDUP(B32*维护参数!$B$19/维护参数!$B$15/10,0)*10 -> 220 | M32: =I32/1000*维护参数!$B$6+J32*维护参数!$B$7+K32*维护参数!$B$8+L32*维护参数!$B$9 -> 1079 | N32: =SUM(H32,M32) -> 1646 | O32: =N32/E32 -> 0.38368298 | P32: =E32-N32 -> 2644 | Q32: =P32/(C32) -> 0.61631702 | R32: =P32*维护参数!$B$20 -> 1718.6 | S32: =R32/(C32) -> 0.40060606 | T32: 林宇辰 | U32: https://v.douyin.com/ettSTTldPIc/
D33: 平台单 | E33: =(B32)*(维护参数!$B$10) -> 5005 | G33: 千川无视版 | H33: =(MAX(维护参数!$B$5,ROUNDUP(F32/10000,0)))*(维护参数!$B$3) -> 1485 | N33: =SUM(H33,M32) -> 2564 | O33: =N33/E33 -> 0.51228771 | P33: =E33-N33 -> 2441 | Q33: =P33/(B32) -> 0.3413986 | R33: =P33*维护参数!$B$20 -> 1586.65 | S33: =R33/(B32) -> 0.22190909
A34: 游点慌 | B34: 7800 | C34: 4680 | D34: 私单 | E34: =(C34)*(1) -> 4680 | F34: =ROUNDUP(B34*维护参数!$B$11/维护参数!$B$12*1000,0) -> 286000 | G34: 普通千川 | H34: =(MAX(维护参数!$B$4,ROUNDUP(F34/10000,0)))*(维护参数!$B$2) -> 609 | I34: =ROUNDUP(B34*维护参数!$B$16/维护参数!$B$15/1000,0)*1000 -> 16000 | J34: =ROUNDUP(B34*维护参数!$B$17/维护参数!$B$15/10,0)*10 -> 160 | K34: =ROUNDUP(B34*维护参数!$B$18/维护参数!$B$15/10,0)*10 -> 160 | L34: =ROUNDUP(B34*维护参数!$B$19/维护参数!$B$15/10,0)*10 -> 240 | M34: =I34/1000*维护参数!$B$6+J34*维护参数!$B$7+K34*维护参数!$B$8+L34*维护参数!$B$9 -> 1152 | N34: =SUM(H34,M34) -> 1761 | O34: =N34/E34 -> 0.37628205 | P34: =E34-N34 -> 2919 | Q34: =P34/(C34) -> 0.62371795 | R34: =P34*维护参数!$B$20 -> 1897.35 | S34: =R34/(C34) -> 0.40541667 | T34: 刘登魁 | U34: https://v.douyin.com/2hO1tem8Xhg/
D35: 平台单 | E35: =(B34)*(维护参数!$B$10) -> 5460 | G35: 千川无视版 | H35: =(MAX(维护参数!$B$5,ROUNDUP(F34/10000,0)))*(维护参数!$B$3) -> 1595 | N35: =SUM(H35,M34) -> 2747 | O35: =N35/E35 -> 0.50311355 | P35: =E35-N35 -> 2713 | Q35: =P35/(B34) -> 0.34782051 | R35: =P35*维护参数!$B$20 -> 1763.45 | S35: =R35/(B34) -> 0.22608333
A36: 饭十七 | B36: 7400 | C36: 4440 | D36: 私单 | E36: =(C36)*(1) -> 4440 | F36: =ROUNDUP(B36*维护参数!$B$11/维护参数!$B$12*1000,0) -> 271334 | G36: 普通千川 | H36: =(MAX(维护参数!$B$4,ROUNDUP(F36/10000,0)))*(维护参数!$B$2) -> 588 | I36: =ROUNDUP(B36*维护参数!$B$16/维护参数!$B$15/1000,0)*1000 -> 15000 | J36: =ROUNDUP(B36*维护参数!$B$17/维护参数!$B$15/10,0)*10 -> 150 | K36: =ROUNDUP(B36*维护参数!$B$18/维护参数!$B$15/10,0)*10 -> 150 | L36: =ROUNDUP(B36*维护参数!$B$19/维护参数!$B$15/10,0)*10 -> 230 | M36: =I36/1000*维护参数!$B$6+J36*维护参数!$B$7+K36*维护参数!$B$8+L36*维护参数!$B$9 -> 1081 | N36: =SUM(H36,M36) -> 1669 | O36: =N36/E36 -> 0.3759009 | P36: =E36-N36 -> 2771 | Q36: =P36/(C36) -> 0.6240991 | R36: =P36*维护参数!$B$20 -> 1801.15 | S36: =R36/(C36) -> 0.40566441 | T36: 陈泓睿 | U36: https://v.douyin.com/m8vFSRuq1co/
D37: 平台单 | E37: =(B36)*(维护参数!$B$10) -> 5180 | G37: 千川无视版 | H37: =(MAX(维护参数!$B$5,ROUNDUP(F36/10000,0)))*(维护参数!$B$3) -> 1540 | N37: =SUM(H37,M36) -> 2621 | O37: =N37/E37 -> 0.50598456 | P37: =E37-N37 -> 2559 | Q37: =P37/(B36) -> 0.34581081 | R37: =P37*维护参数!$B$20 -> 1663.35 | S37: =R37/(B36) -> 0.22477703
A38: 跑腿的包子 | B38: 7000 | C38: 4200 | D38: 私单 | E38: =(C38)*(1) -> 4200 | F38: =ROUNDUP(B38*维护参数!$B$11/维护参数!$B$12*1000,0) -> 256667 | G38: 普通千川 | H38: =(MAX(维护参数!$B$4,ROUNDUP(F38/10000,0)))*(维护参数!$B$2) -> 546 | I38: =ROUNDUP(B38*维护参数!$B$16/维护参数!$B$15/1000,0)*1000 -> 14000 | J38: =ROUNDUP(B38*维护参数!$B$17/维护参数!$B$15/10,0)*10 -> 140 | K38: =ROUNDUP(B38*维护参数!$B$18/维护参数!$B$15/10,0)*10 -> 140 | L38: =ROUNDUP(B38*维护参数!$B$19/维护参数!$B$15/10,0)*10 -> 210 | M38: =I38/1000*维护参数!$B$6+J38*维护参数!$B$7+K38*维护参数!$B$8+L38*维护参数!$B$9 -> 1008 | N38: =SUM(H38,M38) -> 1554 | O38: =N38/E38 -> 0.37 | P38: =E38-N38 -> 2646 | Q38: =P38/(C38) -> 0.63 | R38: =P38*维护参数!$B$20 -> 1719.9 | S38: =R38/(C38) -> 0.4095 | T38: 陈泓睿 | U38: https://v.douyin.com/Vva749Cn4Fk/
D39: 平台单 | E39: =(B38)*(维护参数!$B$10) -> 4900 | G39: 千川无视版 | H39: =(MAX(维护参数!$B$5,ROUNDUP(F38/10000,0)))*(维护参数!$B$3) -> 1430 | N39: =SUM(H39,M38) -> 2438 | O39: =N39/E39 -> 0.49755102 | P39: =E39-N39 -> 2462 | Q39: =P39/(B38) -> 0.35171429 | R39: =P39*维护参数!$B$20 -> 1600.3 | S39: =R39/(B38) -> 0.22861429
A40: 游侠蹦蹦 | B40: 5000 | C40: 3000 | D40: 私单 | E40: =(C40)*(1) -> 3000 | F40: =ROUNDUP(B40*维护参数!$B$11/维护参数!$B$12*1000,0) -> 183334 | G40: 普通千川 | H40: =(MAX(维护参数!$B$4,ROUNDUP(F40/10000,0)))*(维护参数!$B$2) -> 399 | I40: =ROUNDUP(B40*维护参数!$B$16/维护参数!$B$15/1000,0)*1000 -> 10000 | J40: =ROUNDUP(B40*维护参数!$B$17/维护参数!$B$15/10,0)*10 -> 100 | K40: =ROUNDUP(B40*维护参数!$B$18/维护参数!$B$15/10,0)*10 -> 100 | L40: =ROUNDUP(B40*维护参数!$B$19/维护参数!$B$15/10,0)*10 -> 150 | M40: =I40/1000*维护参数!$B$6+J40*维护参数!$B$7+K40*维护参数!$B$8+L40*维护参数!$B$9 -> 720 | N40: =SUM(H40,M40) -> 1119 | O40: =N40/E40 -> 0.373 | P40: =E40-N40 -> 1881 | Q40: =P40/(C40) -> 0.627 | R40: =P40*维护参数!$B$20 -> 1222.65 | S40: =R40/(C40) -> 0.40755 | T40: 刘登魁 | U40: https://v.douyin.com/dO7_tPj7Mgo/
D41: 平台单 | E41: =(B40)*(维护参数!$B$10) -> 3500 | G41: 千川无视版 | H41: =(MAX(维护参数!$B$5,ROUNDUP(F40/10000,0)))*(维护参数!$B$3) -> 1045 | N41: =SUM(H41,M40) -> 1765 | O41: =N41/E41 -> 0.50428571 | P41: =E41-N41 -> 1735 | Q41: =P41/(B40) -> 0.347 | R41: =P41*维护参数!$B$20 -> 1127.75 | S41: =R41/(B40) -> 0.22555
A42: 夏洛 | B42: 5000 | C42: 3000 | D42: 私单 | E42: =(C42)*(1) -> 3000 | F42: =ROUNDUP(B42*维护参数!$B$11/维护参数!$B$12*1000,0) -> 183334 | G42: 普通千川 | H42: =(MAX(维护参数!$B$4,ROUNDUP(F42/10000,0)))*(维护参数!$B$2) -> 399 | I42: =ROUNDUP(B42*维护参数!$B$16/维护参数!$B$15/1000,0)*1000 -> 10000 | J42: =ROUNDUP(B42*维护参数!$B$17/维护参数!$B$15/10,0)*10 -> 100 | K42: =ROUNDUP(B42*维护参数!$B$18/维护参数!$B$15/10,0)*10 -> 100 | L42: =ROUNDUP(B42*维护参数!$B$19/维护参数!$B$15/10,0)*10 -> 150 | M42: =I42/1000*维护参数!$B$6+J42*维护参数!$B$7+K42*维护参数!$B$8+L42*维护参数!$B$9 -> 720 | N42: =SUM(H42,M42) -> 1119 | O42: =N42/E42 -> 0.373 | P42: =E42-N42 -> 1881 | Q42: =P42/(C42) -> 0.627 | R42: =P42*维护参数!$B$20 -> 1222.65 | S42: =R42/(C42) -> 0.40755 | T42: 刘登魁 | U42: https://v.douyin.com/wq_9XvcbfS0/
D43: 平台单 | E43: =(B42)*(维护参数!$B$10) -> 3500 | G43: 千川无视版 | H43: =(MAX(维护参数!$B$5,ROUNDUP(F42/10000,0)))*(维护参数!$B$3) -> 1045 | N43: =SUM(H43,M42) -> 1765 | O43: =N43/E43 -> 0.50428571 | P43: =E43-N43 -> 1735 | Q43: =P43/(B42) -> 0.347 | R43: =P43*维护参数!$B$20 -> 1127.75 | S43: =R43/(B42) -> 0.22555
A44: 畅玩百晓生 | B44: 5000 | C44: 3000 | D44: 私单 | E44: =(C44)*(1) -> 3000 | F44: =ROUNDUP(B44*维护参数!$B$11/维护参数!$B$12*1000,0) -> 183334 | G44: 普通千川 | H44: =(MAX(维护参数!$B$4,ROUNDUP(F44/10000,0)))*(维护参数!$B$2) -> 399 | I44: =ROUNDUP(B44*维护参数!$B$16/维护参数!$B$15/1000,0)*1000 -> 10000 | J44: =ROUNDUP(B44*维护参数!$B$17/维护参数!$B$15/10,0)*10 -> 100 | K44: =ROUNDUP(B44*维护参数!$B$18/维护参数!$B$15/10,0)*10 -> 100 | L44: =ROUNDUP(B44*维护参数!$B$19/维护参数!$B$15/10,0)*10 -> 150 | M44: =I44/1000*维护参数!$B$6+J44*维护参数!$B$7+K44*维护参数!$B$8+L44*维护参数!$B$9 -> 720 | N44: =SUM(H44,M44) -> 1119 | O44: =N44/E44 -> 0.373 | P44: =E44-N44 -> 1881 | Q44: =P44/(C44) -> 0.627 | R44: =P44*维护参数!$B$20 -> 1222.65 | S44: =R44/(C44) -> 0.40755 | T44: 刘登魁 | U44: https://v.douyin.com/jTTVNutNIRQ/
D45: 平台单 | E45: =(B44)*(维护参数!$B$10) -> 3500 | G45: 千川无视版 | H45: =(MAX(维护参数!$B$5,ROUNDUP(F44/10000,0)))*(维护参数!$B$3) -> 1045 | N45: =SUM(H45,M44) -> 1765 | O45: =N45/E45 -> 0.50428571 | P45: =E45-N45 -> 1735 | Q45: =P45/(B44) -> 0.347 | R45: =P45*维护参数!$B$20 -> 1127.75 | S45: =R45/(B44) -> 0.22555
A46: 游戏永动机 | B46: 5000 | C46: 3000 | D46: 私单 | E46: =(C46)*(1) -> 3000 | F46: =ROUNDUP(B46*维护参数!$B$11/维护参数!$B$12*1000,0) -> 183334 | G46: 普通千川 | H46: =(MAX(维护参数!$B$4,ROUNDUP(F46/10000,0)))*(维护参数!$B$2) -> 399 | I46: =ROUNDUP(B46*维护参数!$B$16/维护参数!$B$15/1000,0)*1000 -> 10000 | J46: =ROUNDUP(B46*维护参数!$B$17/维护参数!$B$15/10,0)*10 -> 100 | K46: =ROUNDUP(B46*维护参数!$B$18/维护参数!$B$15/10,0)*10 -> 100 | L46: =ROUNDUP(B46*维护参数!$B$19/维护参数!$B$15/10,0)*10 -> 150 | M46: =I46/1000*维护参数!$B$6+J46*维护参数!$B$7+K46*维护参数!$B$8+L46*维护参数!$B$9 -> 720 | N46: =SUM(H46,M46) -> 1119 | O46: =N46/E46 -> 0.373 | P46: =E46-N46 -> 1881 | Q46: =P46/(C46) -> 0.627 | R46: =P46*维护参数!$B$20 -> 1222.65 | S46: =R46/(C46) -> 0.40755 | T46: 刘登魁 | U46: https://v.douyin.com/c2M4VXTdIvM/
...

Sheet 维护参数
A1: 参数 | B1: 数值 | C1: 单位 / 来源
A2: 私单千川 | B2: 21 | C2: 元/万；工作台，2026-09-14
A3: 平台千川无视版 | B3: 55 | C3: 元/万；工作台，2026-09-14
A4: 私单千川起量 | B4: 10 | C4: 万；工作台
A5: 平台千川起量 | B5: 5 | C5: 万；工作台
A6: 点赞（科技） | B6: 60 | C6: 元/千；工作台unitPrice
A7: 自定义评论 | B7: 0.8 | C7: 元/个；工作台unitPrice
A8: 收藏 | B8: 0.1 | C8: 元/个；工作台unitPrice
A9: 转发 | B9: 0.2 | C9: 元/个；工作台unitPrice
A10: 平台结算折扣 | B10: 0.7 | C10: 用户要求
A11: 播放系数 | B11: 1.1 | C11: 大号模板J列
A12: 目标播放CPM | B12: 30 | C12: 元/千次；大号模板J列
A13: 星图观察CPM | B13: 200 | C13: 大号模板K列
... A20: 部门分成比例 | B20: 0.65 | C20: 沿用大号模板T列
A23: 来源与口径
A24: 账号与报价：【内容事业部】自孵化账号询单信息.xlsx，抖音页A/D/I/L/M/P列；原表更新2026-09-11。
A25: 价格：style-library/gross-margin/douyin.json，采用启用项unitPrice；未采用旧note中的价格。
A26: 模板：自孵化维护标准.xlsx，维护标准页J/K/P/R—U列。互动量按定制刊例价缩放为本次建议。
A27: 5个星广联投账号仍纳入，但本次仅按用户指定的私单/平台七折两种规则，不采用原表可谈深折条款。
A28: 毛利计算沿用工作台：成交价－维护成本；集团毛利率以折前下单基准为分母，部门毛利为集团毛利×65%。
A29: 维护费按完整目标预算，实际执行先减自然数据再核算；中位数未作为可购买或已实现数量。
A30: 空缺实际数据不填零。当前表用于逐账号制定预算，不代表历史表现、平台验收承诺或已完成维护。
